Workbook

Sheet Como usar
A1: Calendário editorial · Fair Health · Instagram e LinkedIn
A2: Versão de 08/10/2026. Públicos e territórios são provisórios até chegar o material estratégico complementar.
A4: Como trabalhamos nesta planilha
A5: 1. Revisão mensal (conjunta): antes de cada mês começar, revisamos juntos temas, títulos, públicos, linhas e datas do mês seguinte. Pauta aprovada muda de "Pauta proposta" para "Pauta aprovada".
A6: 2. Detalhamento semanal: a cada semana, detalhamos texto, roteiro e criativo das peças da semana seguinte (colunas R a T) e passamos pela validação.
A7: 3. Comentários: use a coluna "Comentários da revisão" (V) ou comentários de célula. Não apague pautas descartadas: mude o status para "Descartada".
A8: 4. Datas: a data de início (célula amarela na aba Calendário) recalcula todas as datas sugeridas. Para mudar uma data só, digite a nova data por cima.
A10: Cadência proposta (a validar)
A11: 4 publicações por semana no feed, alternando vídeo e estático/carrossel (2 vídeos por semana). Os vídeos circulam entre as três linhas editoriais.
A12: As três linhas entram em rodízio: duas peças seguidas nunca são da mesma linha. A aba Visão mensal conta o equilíbrio de cada mês.
A13: Os dias da semana NÃO estão definidos: as datas são só uma distribuição sugerida (evitando feriados nacionais) e devem ser ajustadas na revisão mensal.
A14: Stories ficam fora da contagem e servem de apoio: repost, caixa de perguntas e bastidores.
... A32: Documentos de apoio no repositório: instagram/estrategia.md (estratégia), instagram/voice.md (voz), instagram/diretrizes-criativas.md (visual e formatos).

Sheet Visão mensal
A1: Visão mensal: temas e títulos
A2: Primeiro nível do planejamento. Os títulos de cada mês estão na aba Calendário. As contagens são automáticas e servem para a checagem de equilíbrio na revisão mensal.
A4: Mês | B4: Período | C4: Foco do mês | D4: Institucional | E4: Produto | F4: Projetos, eventos e entregas | G4: Séries em andamento | H4: Datas do calendário a avaliar | I4: Total | J4: Institucional (nº) | K4: Produto (nº) | L4: Projetos (nº) | M4: Vídeos | N4: Estáticos e carrosséis | O4: Pautas com validação médica
A5: Mês 1 | B5: =TEXT(Calendário!$D$2+0,"DD/MM")&" a "&TEXT(Calendário!$D$2+27,"DD/MM") -> 19/10 a 15/11 | C5: Apresentar quem somos e como o cuidado funciona, com acolhimento (sem argumento de retorno). | D5: Boas-vindas; time (Marília, Nina, Ronald, Floriana); origem: do Escritório do Paciente ao Escritório do Cuidado. | E5: Como funciona o Escritório do Cuidado; MEV e os 7 pilares; Plano Individualizado de Cuidado; pilar sono; wearables. | F5: Um dia no Escritório; workshops nos pilares; relatório para o RH; como o Escritório chega a uma empresa; registro do mês. | G5: Como funciona o cuidado (1 a 3); Quem cuida (1 a 4); Pilares da MEV (abertura e sono); Como chega a uma empresa (1). | H5: 02/11 feriado (Finados). 14/11 Dia Mundial do Diabetes: avaliar com a responsável médica um conteúdo de alimentação e atividade física, sem promessa clínica. | I5: =COUNTIFS(Calendário!$B$5:$B$400,$A5) -> 16 | J5: =COUNTIFS(Calendário!$B$5:$B$400,$A5,Calendário!$E$5:$E$400,"Institucional") -> 6 | K5: =COUNTIFS(Calendário!$B$5:$B$400,$A5,Calendário!$E$5:$E$400,"Produto") -> 5 | L5: =COUNTIFS(Calendário!$B$5:$B$400,$A5,Calendário!$E$5:$E$400,"Projetos, eventos e entregas") -> 5 | M5: =COUNTIFS(Calendário!$B$5:$B$400,$A5,Calendário!$L$5:$L$400,"Vídeo") -> 8 | N5: =I5-M5 -> 8 | O5: =SUMPRODUCT((Calendário!$B$5:$B$400=$A5)*ISNUMBER(SEARCH("responsável médica",Calendário!$P$5:$P$400))) -> 4
A6: Mês 2 | B6: =TEXT(Calendário!$D$2+28,"DD/MM")&" a "&TEXT(Calendário!$D$2+55,"DD/MM") -> 16/11 a 13/12 | C6: Aprofundar: NR-1 em série, saúde mental, privacidade dos dados e a primeira prova (Chemitec). | D6: Time (Renata, Liliane, Fernando, Charles); ecossistema FairJob. | E6: NR-1 (1 a 3) e versão para colaboradores; pilares saúde mental e relações sociais; seus dados, seu cuidado. | F6: Bastidores de uma implantação; Chemitec 1º semestre de 2026; depoimento B1; workshop nos pilares (registro do mês). | G6: NR-1 (1 a 3); Quem cuida (5 a 8); Pilares da MEV (2 e 3); Da intenção à evidência (1 e 2); Como chega a uma empresa (2). | H6: Novembro Azul: avaliar se há conexão real antes de usar. 20/11 feriado (Consciência Negra). | I6: =COUNTIFS(Calendário!$B$5:$B$400,$A6) -> 16 | J6: =COUNTIFS(Calendário!$B$5:$B$400,$A6,Calendário!$E$5:$E$400,"Institucional") -> 5 | K6: =COUNTIFS(Calendário!$B$5:$B$400,$A6,Calendário!$E$5:$E$400,"Produto") -> 7 | L6: =COUNTIFS(Calendário!$B$5:$B$400,$A6,Calendário!$E$5:$E$400,"Projetos, eventos e entregas") -> 4 | M6: =COUNTIFS(Calendário!$B$5:$B$400,$A6,Calendário!$L$5:$L$400,"Vídeo") -> 8 | N6: =I6-M6 -> 8 | O6: =SUMPRODUCT((Calendário!$B$5:$B$400=$A6)*ISNUMBER(SEARCH("responsável médica",Calendário!$P$5:$P$400))) -> 7
A7: Mês 3 | B7: =TEXT(Calendário!$D$2+56,"DD/MM")&" a "&TEXT(Calendário!$D$2+83,"DD/MM") -> 14/12 a 10/01 | C7: Evidência e convite: indicadores um a um, case HDSA, por que existimos e o diagnóstico gratuito. | D7: Time junto; quem cuida de quem cuida; o que é importante para você em 2027; por que existimos; fazemos o certo pelos motivos certos. | E7: NR-1 (4); indicadores para o RH; sinistralidade (opinião); pilares alimentação e propósito; diagnóstico gratuito. | F7: Depoimento em vídeo de cards; HDSA; 2026 em entregas; TEDx; registro do mês. | G7: NR-1 (4); Pilares da MEV (4 e 5); Da intenção à evidência (3, 4 e conjunto). | H7: Festas de fim de ano (25/12 e 01/01 feriados): reduzir a cadência se a produção apertar. | I7: =COUNTIFS(Calendário!$B$5:$B$400,$A7) -> 16 | J7: =COUNTIFS(Calendário!$B$5:$B$400,$A7,Calendário!$E$5:$E$400,"Institucional") -> 5 | K7: =COUNTIFS(Calendário!$B$5:$B$400,$A7,Calendário!$E$5:$E$400,"Produto") -> 6 | L7: =COUNTIFS(Calendário!$B$5:$B$400,$A7,Calendário!$E$5:$E$400,"Projetos, eventos e entregas") -> 5 | M7: =COUNTIFS(Calendário!$B$5:$B$400,$A7,Calendário!$L$5:$L$400,"Vídeo") -> 8 | N7: =I7-M7 -> 8 | O7: =SUMPRODUCT((Calendário!$B$5:$B$400=$A7)*ISNUMBER(SEARCH("responsável médica",Calendário!$P$5:$P$400))) -> 4

Sheet Linhas e públicos
A1: Linhas editoriais
A2: Linha | B2: O que entra | C2: Objetivos típicos | D2: Formatos que funcionam | E2: Peso no mês
A3: Institucional | B3: O que é a Fair Health, por que existe, de onde veio (Escritório do Paciente → Escritório do Cuidado, ecossistema FairJob), em que acredita e quem compõe o time, com a apresentação individual de cada integrante. | C3: Apresentar, humanizar, gerar confiança. | D3: Vídeo com o time, retratos, carrossel de origem. | E3: Cerca de 1/3
A4: Produto | B4: Escritório do Cuidado (espaço, percurso, sigilo), Medicina do Estilo de Vida e os 7 pilares, Plano Individualizado de Cuidado e tecnologia (smartband, bioimpedância, plataforma, relatórios anonimizados). Temas do entorno (NR-1, bem-estar, saúde mental) entram aqui quando a ligação com a oferta é clara. | C4: Explicar, educar com rigor, tirar dúvidas, levar à conversa comercial. | D4: Carrossel explicativo, vídeo de profissional para a câmera. | E4: Cerca de 1/3 a 2/5
A5: Projetos, eventos e entregas | B5: O que a Fair Health está fazendo e entregando: operação nas empresas (bastidores), workshops e letramento, cases e números liberados, eventos e participações, entregas para o RH. | C5: Provar, mostrar movimento, gerar prova social. | D5: Vídeo de bastidor, carrossel de case, registro de evento. | E5: Cerca de 1/4 a 1/3
A7: Públicos (PROVISÓRIO: confirmar com o material estratégico complementar)
A8: Público | B8: Quem é (como está documentado) | C8: Perguntas e necessidades | D8: Como falar | E8: Cuidados
A9: RH e liderança | B9: Público principal: CHROs, gerentes de pessoas e business partners de empresas de médio e grande porte, principalmente indústria. | C9: Como atender à NR-1 de um jeito que mude algo? Meu programa de saúde tem adesão? O que eu recebo e o que não posso ver? Como começar? | D9: Direto, com processo e evidência, sem jargão clínico. | E9: Números só liberados e com fonte.
A10: Colaboradores | B10: Quem é ou pode ser atendido pelo Escritório do Cuidado (público dos primeiros posts de acolhimento). | C10: Como funciona? Vou ser julgado? O que eu contar fica entre nós? Cabe na minha rotina? | D10: Acolhedor, em segunda pessoa, prático, sem números de negócio. | E10: Nunca expor quem é atendido.
A11: SESMT e medicina do trabalho | B11: Público secundário: médicos do trabalho e equipes de SST. | C11: Isso substitui ou complementa o que já fazemos? Como conversa com o SST e com a NR-1? | D11: Técnico, com fontes e precisão. | E11: Validação da responsável médica em tudo o que for clínico ou normativo.
A12: Diretoria financeira | B12: Público secundário: diretoria financeira. | C12: Qual o retorno? Como medir? O que muda na sinistralidade? | D12: Indicadores com fonte, sem promessa. | E12: Argumento de retorno só a partir do Mês 2, um indicador por vez.
A14: Territórios temáticos (PROVISÓRIO)
A15: Território | B15: Ligação real com a Fair Health | C15: Como adaptar ao público | D15: Validação | E15: Onde aparece
A16: NR-1 e riscos psicossociais | B16: O Executive Summary posiciona a oferta como aderente à NR-1 (programa de prevenção de riscos psicossociais e plataforma de indicadores). | C16: RH: o que muda na gestão. SESMT: como complementa o SST. Colaboradores: seu bem-estar no trabalho também é assunto da empresa. | D16: Texto da norma com fonte oficial; responsável médica; não prometer conformidade. | E16: Série NR-1 (Meses 2 e 3)
A17: Bem-estar e saúde no trabalho | B17: Cuidado preventivo dentro da empresa; adesão como primeiro resultado. | C17: RH: adesão e experiência. Colaboradores: cuidado perto, sem fila. | D17: Não chamar de "app de bem-estar" nem de "benefício" como mimo. | E17: Meses 1 a 3
A18: Os 7 pilares da MEV | B18: Base do Plano Individualizado de Cuidado (cartilha do Escritório do Cuidado). | C18: Colaboradores: hábito possível. RH: o que o ambiente da empresa pode facilitar. | D18: Responsável médica; números da cartilha sem fonte ficam de fora. | E18: Série Pilares, um pilar por vez ao longo dos meses
A19: Saúde mental | B19: Psicólogos no Escritório; guia "Saúde mental: o cuidado no dia a dia" (OMS, APA, IPq-USP). | C19: Colaboradores: acolher e dizer onde pedir ajuda. RH: liderança e clima. | D19: Sempre fechar com CVV 188; responsável médica. | E19: Meses 2 e 3
A20: Tecnologia e dados | B20: Smartband, bioimpedância, plataforma, relatórios anonimizados integrados ao fairdata. | C20: Colaboradores: privacidade. RH: o que recebe e o que não vê. | D20: Nunca dado individual; confirmar fluxo de dados. | E20: Série Tecnologia a favor da pessoa
A21: Experiência do colaborador e cuidado centrado na pessoa | B21: Origem no Escritório do Paciente e nos Aims da saúde (IHI). | C21: RH e SESMT: modelo com história e método. | D21: Datas e conceitos com fonte; [PENDENTE] quem idealizou. | E21: Origem (Mês 1), Quem cuida de quem cuida (Mês 3)
A22: Indicadores e retorno | B22: Provas liberadas: HDSA, Chemitec, HBR 2022, SHRM 2023. | C22: RH e diretoria financeira: um indicador por vez. | D22: Só números liberados, sempre com fonte. | E22: Série Da intenção à evidência (Meses 2 e 3)
A23: Datas e temas do entorno | B23: Só quando a data conversa com um pilar ou com o serviço. | C23: Escolher o público que a data realmente envolve. | D23: Responsável médica; evitar oportunismo. | E23: Coluna "Datas do calendário a avaliar" da Visão mensal

Sheet Séries
A1: Séries: assuntos amplos em peças curtas e complementares
A2: Série | B2: Lógica da sequência | C2: Partes (ID no Calendário) | D2: Meses | E2: Observações
A3: Como funciona o cuidado | B3: Contexto e percurso → cuidado individualizado → acompanhamento. | C3: M1-02 O percurso · M1-08 O Plano Individualizado de Cuidado · M1-14 O acompanhamento (wearables) | D3: Mês 1 | E3: Detalhes técnicos validados pela responsável médica.
A4: NR-1 | B4: Contexto → diagnóstico → cuidado individualizado → acompanhamento, com uma versão para colaboradores. | C4: M2-02 Contexto · M2-07 Versão para colaboradores · M2-09 Diagnóstico · M2-14 Cuidado individualizado · M3-05 Acompanhamento | D4: Meses 2 e 3 | E4: Fonte oficial para o texto da norma. Não prometer conformidade.
A5: Pilares da MEV | B5: Um pilar por vez, espalhado pelo calendário. Cada pilar pode ter até 3 peças em momentos diferentes: por que importa (colaboradores) → como entra no plano (produto) → o que a empresa pode facilitar (RH). | C5: M1-05 Abertura (7 pilares) · M1-11 Sono · M2-04 Saúde mental e estresse · M2-16 Relações sociais · M3-02 Alimentação · M3-14 Propósito · Atividade física e evitar substâncias no Mês 4 | D5: Meses 1 a 4 | E5: Um post não precisa esgotar o pilar. Retomar os pilares com outros ângulos depois.
A6: Quem cuida | B6: Uma pessoa do time por semana, sem cargo, com a resposta a "O que é importante para você?". Fecha com o time junto. | C6: M1-04 Marília · M1-07 Nina · M1-13 Ronald · M1-16 Floriana · M2-03 Renata · M2-05 Liliane · M2-11 Fernando · M2-15 Charles · M3-01 Time junto | D6: Meses 1 a 3 | E6: Ordem a confirmar com o time. Formato (vídeo ou retrato) conforme a preferência de cada pessoa.
A7: Tecnologia a favor da pessoa | B7: O que a tecnologia mede → o que fica no atendimento → o que o RH recebe. | C7: M1-14 Wearables · M1-09 Relatório para o RH · M2-12 Seus dados, seu cuidado | D7: Meses 1 e 2 | E7: Nunca dado individual.
A8: Da intenção à evidência | B8: Um indicador por vez, depois o conjunto (decisão de 01/10: o argumento de retorno começa depois da estreia). | C8: M2-06 Adesão e retorno (Chemitec) · M2-10 Experiência (depoimento B1) · M3-03 Adesão entre colegas · M3-06 HDSA · M3-08 Indicadores · M3-10 Afastamento | D8: Meses 2 e 3 | E8: Só números liberados, sempre com fonte.
A9: Como chega a uma empresa | B9: Explicação das etapas → bastidor de uma implantação real. | C9: M1-12 Diagnóstico, proposta e implantação · M2-01 Bastidores de uma implantação | D9: Meses 1 e 2 | E9: Deixa clara a oferta comercial. Não citar prazos sem confirmação.
A10: Registro do mês | B10: Uma peça por mês sobre um projeto, evento ou entrega real. | C10: M1-15 · M2-13 (workshop) · M3-09 (2026 em entregas) · M3-15 | D10: Todos os meses | E10: Depende da agenda de eventos e entregas, que ainda não está documentada.

Sheet Pendências
A1: Pendências e validações
A2: # | B2: Pendência | C2: Quem confirma | D2: Pautas afetadas | E2: Situação
A3: 1 | B3: Material estratégico complementar: confirmar públicos e aprofundar os territórios temáticos. | C3: Time Fair Health | D3: Colunas Público e Necessidade de todas as pautas | E3: Aberta
A4: 2 | B4: Nome da responsável médica que valida o conteúdo clínico (o material anterior citava o Dr. Ronald). | C4: Time Fair Health | D4: Todas as pautas com "responsável médica" na validação | E4: Aberta
A5: 3 | B5: Assistentes sociais fazem parte do atendimento? (o Executive Summary cita médicos e psicólogos) | C5: Time Fair Health | D5: M1-01 e textos que citam o time | E5: Aberta
A6: 4 | B6: Etapas e prazos clínicos: bioimpedância, smartband por 48 h, retorno, programa de 12 meses. | C6: Responsável médica | D6: M1-02, M1-08, M1-14 | E6: Aberta
A7: 5 | B7: Nomes dos 7 pilares: usar a lista da cartilha? (a apresentação institucional traz 6) | C7: Responsável médica | D7: Série Pilares da MEV | E7: Aberta
A8: 6 | B8: Texto, prazos e obrigações da NR-1 com fonte oficial. | C8: Responsável médica + fonte oficial | D8: Série NR-1 | E8: Aberta
A9: 7 | B9: Collab no Instagram: perfil da FairJob, quem envia e quem aceita o convite, se todos os posts vão em collab, perfis dos integrantes, limite de colaboradores por post. | C9: Comunicação + FairJob | D9: Todas as pautas (coluna Collab) | E9: Aberta
A10: 8 | B10: LinkedIn pela página da FairJob: quem publica, frequência, se a Fair Health terá página própria, se os integrantes compartilham, adaptação das legendas. | C10: Comunicação + FairJob | D10: Todas as pautas com canal LinkedIn | E10: Aberta
A11: 9 | B11: Fotos e vídeos reais do espaço (as imagens atuais parecem renders) e autorização da empresa para gravar. | C11: Time Fair Health | D11: M1-01, M1-03, M2-01 | E11: Aberta
A12: 10 | B12: Material de cada integrante: vídeo curto ou retrato, descrição sem cargo e resposta à pergunta. Ordem da série. | C12: Time Fair Health | D12: Série Quem cuida | E12: Aberta
A13: 11 | B13: Workshops e letramento: formato, frequência, temas e próximas datas. | C13: Time Fair Health | D13: M1-06, M2-13 | E13: Aberta
A14: 12 | B14: Agenda de eventos, projetos e entregas para o Registro do mês. | C14: Time Fair Health | D14: M1-15, M2-13, M3-09, M3-15 | E14: Aberta
... A21: 19 | B21: Quem idealizou o Escritório do Paciente. | C21: Time Fair Health | D21: M1-10 | E21: Aberta

Sheet Calendário
A1: Calendário editorial · Fair Health
A2: Início do Mês 1 (segunda-feira): | D2: 46314 | E2: Mude a data amarela para reposicionar todo o calendário. Os dias da semana são só sugestão.
A4: ID | B4: Mês | C4: Semana | D4: Data sugerida | E4: Linha editorial | F4: Tema | G4: Série (parte) | H4: Título provisório | I4: Público | J4: Necessidade ou pergunta do público | K4: Objetivo | L4: Formato | M4: Canal | N4: Collab / perfis | O4: Mensagem principal | P4: Validação necessária | Q4: Status | R4: Texto / legenda | S4: Roteiro / estrutura | T4: Criativo (modelo e arte) | U4: Responsável | V4: Comentários da revisão
A5: M1-01 | B5: Mês 1 | C5: 1 | D5: =$D$2+(C5-1)*7+0 -> 46314 | E5: Institucional | F5: Apresentação da Fair Health | H5: Antes de qualquer exame, uma conversa | I5: Colaboradores; RH e liderança | J5: O que é a Fair Health e o que ela faz dentro da empresa? | K5: Apresentar a marca e o jeito de cuidar | L5: Vídeo | M5: Instagram + LinkedIn | N5: FairJob | O5: A Fair Health leva o cuidado para dentro da empresa, e todo cuidado começa com uma pergunta: o que é importante para você? | P5: Roteiro e legenda citam assistentes sociais: confirmar se fazem parte do atendimento antes de publicar (o Executive Summary cita médicos e psicólogos). | Q5: Roteiro pronto | R5: Antes de qualquer exame, uma conversa. Esse é o Escritório do Cuidado: um espaço dentro da empresa, com médicos, psicólogos e assistentes sociais, perto de quem trabalha. Aqui, todo cuidado começa com a mesma pergunta: o que é importante para você? A partir da resposta, montamos juntos um plano que cabe na sua rotina e seguimos acompanhando. Seja bem-vindo. Nos próximos dias, você vai conhecer quem cuida por aqui. #fairhealth #saudecorporativa #cuidadocentradonapessoa #medicinadoestilodevida #saudedotrabalhador | S5: Reel de 30 a 34 s (instagram/primeiros-posts-acolhimento.md, ID 1). 0–3 s: "Antes de qualquer exame, a gente começa com uma conversa." Porta do Escritório se abrindo. 3–9 s: o espaço dentro da empresa (recepção, copa, sala). 9–16 s: quem chega é recebido por gente, sem pressa e sem julgamento. 16–23 s: cada integrante diz um pedaço da pergunta "O que é importante para você?". 23–30 s: a partir da resposta, um cuidado que cabe na rotina. 30–34 s: logo e assinatura. | T5: Vídeo 1080x1920 gravado no espaço real e com o time. Texto na tela dentro da área segura. Capa no modelo M1 (Tiffany, pergunta), conferindo o recorte da grade. LinkedIn: mesmo vídeo, legenda adaptada para RH.
A6: M1-02 | B6: Mês 1 | C6: 1 | D6: =$D$2+(C6-1)*7+1 -> 46315 | E6: Produto | F6: Escritório do Cuidado | G6: Como funciona o cuidado (1/3): o percurso | H6: Aqui, o cuidado começa com uma pergunta | I6: Colaboradores | J6: O que acontece quando eu vou ao Escritório do Cuidado? Vou ser julgado? O que eu contar fica entre nós? | K6: Explicar o percurso do atendimento e reduzir a barreira de ir | L6: Carrossel | M6: Instagram + LinkedIn | N6: FairJob | O6: Primeiro a gente te ouve e entende sua rotina; depois monta o plano com você e acompanha. O que você conta fica entre você e quem cuida. | P6: Responsável médica confere as etapas citadas (anamnese, bioimpedância, smartband por 48 horas, retorno). | Q6: Em revisão | R6: Aqui, o cuidado começa com uma pergunta: o que é importante para você? Antes de exame, antes de número, a gente quer saber da sua rotina, do seu trabalho, do que anda pesando e do que você gostaria de mudar. O Escritório do Cuidado fica dentro da empresa, perto de onde você já está. Lá, médicos e psicólogos se revezam para montar com você um cuidado que caiba na sua vida, com base na Medicina do Estilo de Vida. O objetivo da fairhealth é melhorar a qualidade de vida de quem trabalha, com um cuidado feito para cada pessoa e acompanhado de perto. E o que você conta fica entre você e quem cuida. Arrasta para o lado para ver como funciona. #fairhealth #saudecorporativa #cuidadocentradonapessoa #medicinadoestilodevida #saudedotrabalhador | S6: 10 slides: 1 capa (pergunta) · 2 fica dentro da empresa · 3 gente que cuida de gente · 4 Passo 1: a gente te conhece · 5 Passo 2: o que é importante para você? · 6 Passo 3: entender antes de propor (bioimpedância e smartband por 48 h) · 7 Passo 4: o plano é seu · 8 Passo 5: retorno e acompanhamento · 9 sigilo · 10 convite para comentar. | T6: Arte no Canva (design DAHW6JfDldU, 11 páginas): escolher entre as versões originais e as novas dos slides 1, 5, 7, 9 e 10. Modelos M1, M2 e M3. LinkedIn: exportar em PDF.
A7: M1-03 | B7: Mês 1 | C7: 1 | D7: =$D$2+(C7-1)*7+3 -> 46317 | E7: Projetos, eventos e entregas | F7: Escritório em funcionamento | H7: Um dia no Escritório do Cuidado | I7: RH e liderança; Colaboradores | J7: Como isso funciona na prática, dentro de uma empresa? | K7: Mostrar o serviço em operação e dar concretude à oferta | L7: Vídeo | M7: Instagram + LinkedIn | N7: FairJob; empresa-cliente (só se autorizar) | O7: O cuidado acontece dentro da empresa, em plantões de médicos e psicólogos, perto de quem trabalha. | P7: Gravar no espaço real (as imagens atuais parecem renders). Autorização da empresa para gravar. Nenhum colaborador atendido em cena. | Q7: Aguardando material | R7: [Rascunho] Como é um dia no Escritório do Cuidado? Antes do primeiro atendimento, a sala é preparada, a agenda é revisada e as smartbands ficam prontas para quem vai começar o acompanhamento. Depois, é conversa. Médicos e psicólogos se revezam em plantões dentro da empresa, perto de quem trabalha. #fairhealth #saudecorporativa #cuidadocentradonapessoa #medicinadoestilodevida #saudedotrabalhador | S7: Reel de 30 a 40 s, sem pacientes. 0–3 s: porta se abrindo. Tela: UM DIA NO ESCRITÓRIO DO CUIDADO 3–10 s: profissional preparando a sala (cena C3 da sessão de fotos). 10–18 s: agenda e smartbands sobre a mesa (A7). 18–28 s: profissional recebendo alguém, de costas. Tela: PLANTÕES DE MÉDICOS E PSICÓLOGOS 28–35 s: copa e pausa (B4). Fechamento com a pergunta e o logo. | T7: Vídeo 1080x1920. Cenas B1, B2, B4, C3 e A7 de instagram/sessao-de-fotos.md. Capa no modelo M7.
A8: M1-04 | B8: Mês 1 | C8: 1 | D8: =$D$2+(C8-1)*7+4 -> 46318 | E8: Institucional | F8: Time | G8: Quem cuida (1/8) | H8: Quem cuida: Marília | I8: Colaboradores; RH e liderança | J8: Quem vai me atender? Quem são as pessoas por trás da Fair Health? | K8: Humanizar a marca e criar vínculo | L8: Carrossel | M8: Instagram + LinkedIn | N8: FairJob; perfil de Marília (se houver e se a pessoa quiser) | O8: [Resposta de Marília a "O que é importante para você?"] | P8: Material da pessoa: retrato vertical, descrição curta sem cargo e resposta à pergunta. Aprovação da pessoa antes de publicar. | Q8: Aguardando material | R8: Por trás de todo cuidado, tem gente. Esta é a Marília. [Descrição curta, escrita com ela, sem cargo.] Perguntamos a ela o mesmo que perguntamos a quem cuidamos: o que é importante para você? "[resposta]" E para você, o que é importante? #fairhealth #saudecorporativa #cuidadocentradonapessoa #medicinadoestilodevida #saudedotrabalhador | S8: Carrossel de 3 slides: 1 retrato em tela cheia e nome · 2 quem é a Marília (sem cargo) · 3 "O que é importante para você?" e a resposta dela. | T8: Modelo M4 (retrato do time)
A9: M1-05 | B9: Mês 1 | C9: 2 | D9: =$D$2+(C9-1)*7+0 -> 46321 | E9: Produto | F9: Medicina do Estilo de Vida | G9: Pilares da MEV (abertura) | H9: Medicina do Estilo de Vida em 1 minuto: os 7 pilares | I9: Colaboradores; RH e liderança | J9: O que é Medicina do Estilo de Vida? É dieta? É academia? | K9: Apresentar a base do cuidado e abrir a série dos pilares | L9: Vídeo | M9: Instagram + LinkedIn | N9: FairJob | O9: Os pilares não funcionam isoladamente: o plano olha para a pessoa inteira. | P9: Responsável médica valida a definição de MEV e os nomes dos 7 pilares (cartilha do Escritório do Cuidado). | Q9: Pauta proposta | T9: Modelo M9 (profissional para a câmera) com etiqueta "PILARES".
A10: M1-06 | B10: Mês 1 | C10: 2 | D10: =$D$2+(C10-1)*7+1 -> 46322 | E10: Projetos, eventos e entregas | F10: Letramento e workshops | H10: Cuidado também se aprende: como funcionam os workshops nos pilares | I10: RH e liderança; Colaboradores | J10: Além da consulta, o que acontece com o time ao longo do programa? | K10: Mostrar uma entrega do programa além do atendimento individual | L10: Carrossel | M10: Instagram + LinkedIn | N10: FairJob | O10: Ao longo do programa, o cuidado também acontece em grupo, com letramento e workshops nos pilares da MEV. | P10: Time confirma formato, frequência e temas dos workshops. Fotos reais de um encontro, com autorização. | Q10: Aguardando material | T10: Modelo M7 (bastidor) com fotos reais.
A11: M1-07 | B11: Mês 1 | C11: 2 | D11: =$D$2+(C11-1)*7+3 -> 46324 | E11: Institucional | F11: Time | G11: Quem cuida (2/8) | H11: Quem cuida: Nina | I11: Colaboradores; RH e liderança | J11: Quem vai me atender? Quem são as pessoas por trás da Fair Health? | K11: Humanizar a marca e criar vínculo | L11: Vídeo | M11: Instagram + LinkedIn | N11: FairJob; perfil de Nina (se houver e se a pessoa quiser) | O11: [Resposta de Nina a "O que é importante para você?"] | P11: Material da pessoa: vídeo curto (20 a 30 s), descrição curta sem cargo e resposta à pergunta. Aprovação da pessoa antes de publicar. | Q11: Aguardando material | T11: Modelo M9 (vídeo, capa com nome)
A12: M1-08 | B12: Mês 1 | C12: 2 | D12: =$D$2+(C12-1)*7+4 -> 46325 | E12: Produto | F12: Plano Individualizado de Cuidado | G12: Como funciona o cuidado (2/3): o plano | H12: O plano é seu: como nasce o Plano Individualizado de Cuidado | I12: Colaboradores | J12: Vou receber uma lista de regras impossíveis de seguir? | K12: Explicar como o plano é montado com a pessoa (decisão compartilhada) | L12: Carrossel | M12: Instagram + LinkedIn | N12: FairJob | O12: O plano parte do que é importante para você e da sua rotina real, com ações nos pilares da MEV, e muda quando a vida muda. | P12: Responsável médica valida etapas e prazos de retorno e acompanhamento. Se usar o depoimento A1, confirmar o formato (CFM). | Q12: Pauta proposta | T12: Modelo M3 (card de interface do plano), já testado no carrossel de acolhimento.
A13: M1-09 | B13: Mês 1 | C13: 3 | D13: =$D$2+(C13-1)*7+1 -> 46329 | E13: Projetos, eventos e entregas | F13: Entregas para o RH | G13: Tecnologia a favor da pessoa | H13: Bastidores: como nasce o relatório que o RH recebe | I13: RH e liderança | J13: O que eu recebo para acompanhar o programa? Vou ver dados individuais? | K13: Mostrar a entrega para a empresa e a regra de privacidade | L13: Vídeo | M13: Instagram + LinkedIn | N13: FairJob | O13: O RH acompanha o programa por indicadores do grupo, anonimizados e integrados ao fairdata. Nenhum dado individual. | P13: Time confirma quais indicadores entram no relatório. Tela genérica, sem dado real. | Q13: Pauta proposta | T13: Vídeo narrado pela Nina sobre painel genérico (cena C4). Modelo M9.
A14: M1-10 | B14: Mês 1 | C14: 3 | D14: =$D$2+(C14-1)*7+2 -> 46330 | E14: Institucional | F14: Origem | H14: Tudo começou num hospital: do Escritório do Paciente ao Escritório do Cuidado | I14: RH e liderança; SESMT e medicina do trabalho | J14: De onde vem esse modelo? É só mais um programa de bem-estar? | K14: Dar lastro à marca com a história do modelo | L14: Carrossel | M14: Instagram + LinkedIn | N14: FairJob | O14: O modelo nasceu em 2009 para colocar o paciente no centro do cuidado. Hoje, coloca o colaborador, dentro do ecossistema FairJob. | P14: [PENDENTE] Quem idealizou o Escritório do Paciente. Conferir as datas da linha do tempo (Aims do IHI) com fonte. | Q14: Pauta proposta | T14: Modelo M2 (linha do tempo em passos).
A15: M1-11 | B15: Mês 1 | C15: 3 | D15: =$D$2+(C15-1)*7+3 -> 46331 | E15: Produto | F15: Pilar: sono | G15: Pilares da MEV (1: sono) | H15: Dormir não é tempo perdido | I15: Colaboradores | J15: Por que eu acordo cansado? O que dá para mudar na rotina? | K15: Educar sobre o pilar sono e mostrar como ele entra no cuidado | L15: Vídeo | M15: Instagram | N15: FairJob | O15: Dormir não é tempo perdido, é investimento em saúde. No Escritório do Cuidado, o sono entra no plano a partir da sua rotina real. | P15: Responsável médica valida as orientações. Fonte: guia "Saúde mental: o cuidado no dia a dia" (higiene do sono). | Q15: Pauta proposta | T15: Modelo M9 com etiqueta "PILARES · SONO". Cenas D3 da sessão de fotos.
A16: M1-12 | B16: Mês 1 | C16: 3 | D16: =$D$2+(C16-1)*7+4 -> 46332 | E16: Projetos, eventos e entregas | F16: Como começa numa empresa | G16: Como chega a uma empresa (1/2) | H16: Como o Escritório do Cuidado chega a uma empresa: diagnóstico, proposta e implantação | I16: RH e liderança; Diretoria financeira | J16: Quero isso na minha empresa. Por onde começa e o que acontece em cada etapa? | K16: Deixar clara a oferta e o primeiro passo comercial | L16: Carrossel | M16: Instagram + LinkedIn | N16: FairJob | O16: Começa com um diagnóstico gratuito, segue com uma proposta personalizada e chega à implantação, com onboarding e primeiros atendimentos. Comente CUIDADO. | P16: Não citar prazos de cada etapa sem confirmação. Confirmar o destino do link (www.fairhealth.com.br). | Q16: Pauta proposta | T16: Modelo M2 (3 passos) e chamada CUIDADO no último slide.
A17: M1-13 | B17: Mês 1 | C17: 4 | D17: =$D$2+(C17-1)*7+0 -> 46335 | E17: Institucional | F17: Time | G17: Quem cuida (3/8) | H17: Quem cuida: Ronald | I17: Colaboradores; RH e liderança | J17: Quem vai me atender? Quem são as pessoas por trás da Fair Health? | K17: Humanizar a marca e criar vínculo | L17: Vídeo | M17: Instagram + LinkedIn | N17: FairJob; perfil de Ronald (se houver e se a pessoa quiser) | O17: [Resposta de Ronald a "O que é importante para você?"] | P17: Material da pessoa: vídeo curto (20 a 30 s), descrição curta sem cargo e resposta à pergunta. Aprovação da pessoa antes de publicar. | Q17: Aguardando material | T17: Modelo M9 (vídeo, capa com nome)
A18: M1-14 | B18: Mês 1 | C18: 4 | D18: =$D$2+(C18-1)*7+1 -> 46336 | E18: Produto | F18: Tecnologia: wearables | G18: Como funciona o cuidado (3/3): o acompanhamento | H18: O cuidado não para quando a consulta acaba | I18: Colaboradores; RH e liderança | J18: Para que serve a pulseira? Vão me vigiar? | K18: Explicar o acompanhamento com tecnologia e a regra de privacidade | L18: Carrossel | M18: Instagram + LinkedIn | N18: FairJob | O18: A smartband e a bioimpedância ajudam a olhar, junto com a pessoa, como foram as últimas semanas. Os dados ficam no atendimento; o RH vê só o grupo. | P18: [PENDENTE] Quais dados a smartband registra e se todos os atendidos usam a pulseira (instagram/posts/wearables/README.md). | Q18: Em revisão | T18: Arte pronta em instagram/posts/wearables (8 slides); a capa ainda espera a foto A1. Adaptar ao visual atual.
A19: M1-15 | B19: Mês 1 | C19: 4 | D19: =$D$2+(C19-1)*7+3 -> 46338 | E19: Projetos, eventos e entregas | F19: Registro do mês | G19: Registro do mês | H19: [Registro do mês: workshop, evento ou entrega, a confirmar] | I19: A definir | J19: O que a Fair Health está fazendo agora? | K19: Mostrar movimento real e prova social | L19: Vídeo | M19: Instagram + LinkedIn | N19: FairJob; parceiros envolvidos (se autorizarem) | O19: A definir | P19: Agenda de eventos e entregas do mês. Autorizações de imagem. | Q19: Aguardando pauta | T19: Modelo M7 (bastidor).
A20: M1-16 | B20: Mês 1 | C20: 4 | D20: =$D$2+(C20-1)*7+4 -> 46339 | E20: Institucional | F20: Time | G20: Quem cuida (4/8) | H20: Quem cuida: Floriana | I20: Colaboradores; RH e liderança | J20: Quem vai me atender? Quem são as pessoas por trás da Fair Health? | K20: Humanizar a marca e criar vínculo | L20: Carrossel | M20: Instagram + LinkedIn | N20: FairJob; perfil de Floriana (se houver e se a pessoa quiser) | O20: [Resposta de Floriana a "O que é importante para você?"] | P20: Material da pessoa: retrato vertical, descrição curta sem cargo e resposta à pergunta. Aprovação da pessoa antes de publicar. | Q20: Aguardando material | T20: Modelo M4 (retrato do time)
A21: M2-01 | B21: Mês 2 | C21: 5 | D21: =$D$2+(C21-1)*7+0 -> 46342 | E21: Projetos, eventos e entregas | F21: Implantação | G21: Como chega a uma empresa (2/2) | H21: Bastidores de uma implantação: os primeiros atendimentos numa empresa | I21: RH e liderança | J21: Como é, na prática, o começo do Escritório do Cuidado numa empresa? | K21: Mostrar uma implantação real, continuando o post M1-12 | L21: Vídeo | M21: Instagram + LinkedIn | N21: FairJob; empresa-cliente (só se autorizar) | O21: Do onboarding aos primeiros atendimentos, o cuidado chega perto de quem trabalha. | P21: Empresa, datas e autorização de imagem a confirmar. Nenhum colaborador atendido identificável. | Q21: Aguardando pauta | T21: Modelo M7 (bastidor).
A22: M2-02 | B22: Mês 2 | C22: 5 | D22: =$D$2+(C22-1)*7+1 -> 46343 | E22: Produto | F22: NR-1 e riscos psicossociais | G22: NR-1 (1/4): contexto | H22: NR-1: o que muda quando os riscos psicossociais entram na gestão | I22: RH e liderança; SESMT e medicina do trabalho | J22: O que a NR-1 passa a pedir da minha empresa e por onde eu começo? | K22: Informar com rigor e mostrar que cumprir a norma é mudar o dia a dia, não só preencher documento | L22: Carrossel | M22: Instagram + LinkedIn | N22: FairJob | O22: Adequar-se à NR-1 não é só preencher a planilha de riscos. Se nada muda no dia a dia de quem trabalha, a empresa continua exposta. | P22: Texto da norma, prazos e obrigações com fonte oficial (Ministério do Trabalho). A mensagem usa a posição [SUGESTÃO] 1 do voice.md, que precisa de aprovação. Revisão da responsável médica. | Q22: Pauta proposta | T22: Modelo M2 (passos) com fonte no rodapé (M6).
A23: M2-03 | B23: Mês 2 | C23: 5 | D23: =$D$2+(C23-1)*7+2 -> 46344 | E23: Institucional | F23: Time | G23: Quem cuida (5/8) | H23: Quem cuida: Renata | I23: Colaboradores; RH e liderança | J23: Quem vai me atender? Quem são as pessoas por trás da Fair Health? | K23: Humanizar a marca e criar vínculo | L23: Vídeo | M23: Instagram + LinkedIn | N23: FairJob; perfil de Renata (se houver e se a pessoa quiser) | O23: [Resposta de Renata a "O que é importante para você?"] | P23: Material da pessoa: vídeo curto (20 a 30 s), descrição curta sem cargo e resposta à pergunta. Aprovação da pessoa antes de publicar. | Q23: Pauta proposta | T23: Modelo M9 (vídeo, capa com nome)
A24: M2-04 | B24: Mês 2 | C24: 5 | D24: =$D$2+(C24-1)*7+3 -> 46345 | E24: Produto | F24: Pilar: saúde mental e estresse | G24: Pilares da MEV (2: saúde mental e estresse) | H24: Quando o estresse não passa no fim de semana | I24: Colaboradores | J24: Isso que eu sinto é normal? Quando vale procurar ajuda? | K24: Educar com fonte, acolher e mostrar que há psicólogos por perto | L24: Carrossel | M24: Instagram + LinkedIn | N24: FairJob | O24: Estresse que não passa merece atenção. No Escritório do Cuidado, médicos e psicólogos estão perto para conversar. Em crise, o CVV atende pelo 188. | P24: Responsável médica. Fontes do guia (OMS, APA, IPq-USP). Fechar com onde pedir ajuda (CVV 188, CAPS). | Q24: Pauta proposta | T24: Modelo M5 (pilar).
A25: M2-05 | B25: Mês 2 | C25: 6 | D25: =$D$2+(C25-1)*7+0 -> 46349 | E25: Institucional | F25: Time | G25: Quem cuida (6/8) | H25: Quem cuida: Liliane | I25: Colaboradores; RH e liderança | J25: Quem vai me atender? Quem são as pessoas por trás da Fair Health? | K25: Humanizar a marca e criar vínculo | L25: Vídeo | M25: Instagram + LinkedIn | N25: FairJob; perfil de Liliane (se houver e se a pessoa quiser) | O25: [Resposta de Liliane a "O que é importante para você?"] | P25: Material da pessoa: vídeo curto (20 a 30 s), descrição curta sem cargo e resposta à pergunta. Aprovação da pessoa antes de publicar. | Q25: Pauta proposta | T25: Modelo M9 (vídeo, capa com nome)
A26: M2-06 | B26: Mês 2 | C26: 6 | D26: =$D$2+(C26-1)*7+1 -> 46350 | E26: Projetos, eventos e entregas | F26: Resultados liberados | G26: Da intenção à evidência (1: adesão e retorno) | H26: Chemitec, 1º semestre de 2026: as pessoas usam e voltam | I26: RH e liderança; Diretoria financeira | J26: Os colaboradores usam de verdade um programa como esse? | K26: Provar adesão com dado real e agregado | L26: Carrossel | M26: Instagram + LinkedIn | N26: FairJob; Chemitec (se autorizar a marcação) | O26: 161 atendimentos e 48 colaboradores atendidos (98% de adesão); 81,3% voltaram para dois ou mais atendimentos. | P26: Dados liberados (voice.md), sempre agregados. Confirmar se a empresa autoriza ser marcada ou convidada para a collab. | Q26: Pauta proposta | T26: Modelo M6 (dado com fonte).
A27: M2-07 | B27: Mês 2 | C27: 6 | D27: =$D$2+(C27-1)*7+3 -> 46352 | E27: Produto | F27: NR-1 para quem trabalha | G27: NR-1 (versão para colaboradores) | H27: Seu bem-estar no trabalho também é assunto da empresa | I27: Colaboradores | J27: O que essa tal de NR-1 tem a ver comigo? | K27: Traduzir a NR-1 para quem trabalha e apresentar o Escritório como canal de cuidado | L27: Vídeo | M27: Instagram | N27: FairJob | O27: A NR-1 pede que a empresa olhe também para o que pesa no dia a dia de quem trabalha. O Escritório do Cuidado é um dos lugares onde isso acontece. | P27: Texto da norma com fonte oficial. Revisão da responsável médica. | Q27: Pauta proposta | T27: Modelo M9 (profissional para a câmera).
A28: M2-08 | B28: Mês 2 | C28: 6 | D28: =$D$2+(C28-1)*7+4 -> 46353 | E28: Institucional | F28: Ecossistema FairJob | H28: Fair Health no ecossistema FairJob: medir, cuidar, provar, propagar | I28: RH e liderança | J28: Quem está por trás da Fair Health e como ela se conecta ao resto? | K28: Situar a marca no ecossistema e reforçar a parceria com a FairJob | L28: Carrossel | M28: Instagram + LinkedIn | N28: FairJob | O28: Dentro do ecossistema FairJob, a Fair Health é o cuidar. | P28: Confirmar com a FairJob como o ecossistema é descrito hoje e quais marcas citar. | Q28: Pauta proposta | T28: Modelo M2.
A29: M2-09 | B29: Mês 2 | C29: 7 | D29: =$D$2+(C29-1)*7+0 -> 46356 | E29: Produto | F29: NR-1 e riscos psicossociais | G29: NR-1 (2/4): diagnóstico | H29: Como enxergar o que pesa no dia a dia do time | I29: RH e liderança; SESMT e medicina do trabalho | J29: Como identifico os riscos psicossociais sem expor ninguém? | K29: Mostrar o papel da escuta e dos indicadores anonimizados no diagnóstico | L29: Vídeo | M29: Instagram + LinkedIn | N29: FairJob | O29: Escuta individual e indicadores do grupo, anonimizados, mostram onde agir sem expor ninguém. | P29: Responsável médica. Confirmar o que a plataforma de indicadores entrega (Executive Summary cita programa de prevenção de riscos psicossociais e plataforma de indicadores). | Q29: Pauta proposta | T29: Modelo M9.
A30: M2-10 | B30: Mês 2 | C30: 7 | D30: =$D$2+(C30-1)*7+1 -> 46357 | E30: Projetos, eventos e entregas | F30: Depoimentos | G30: Da intenção à evidência (2: experiência de quem é cuidado) | H30: "O processo não precisa ser perfeito para estar funcionando." | I30: Colaboradores; RH e liderança | J30: Como é ser cuidado pelo Escritório do Cuidado? | K30: Mostrar a experiência de quem é atendido, sem prometer resultado | L30: Foto única | M30: Instagram + LinkedIn | N30: FairJob | O30: Cuidado centrado na pessoa: constância vale mais que perfeição. | P30: Trecho B1 aprovado (instagram/depoimentos.md). Confirmar o formato com a responsável médica (publicidade médica, CFM). Assinatura padrão e logo em coração. | Q30: Pauta proposta | T30: Modelo M8 (citação).
A31: M2-11 | B31: Mês 2 | C31: 7 | D31: =$D$2+(C31-1)*7+3 -> 46359 | E31: Institucional | F31: Time | G31: Quem cuida (7/8) | H31: Quem cuida: Fernando | I31: Colaboradores; RH e liderança | J31: Quem vai me atender? Quem são as pessoas por trás da Fair Health? | K31: Humanizar a marca e criar vínculo | L31: Vídeo | M31: Instagram + LinkedIn | N31: FairJob; perfil de Fernando (se houver e se a pessoa quiser) | O31: [Resposta de Fernando a "O que é importante para você?"] | P31: Material da pessoa: vídeo curto (20 a 30 s), descrição curta sem cargo e resposta à pergunta. Aprovação da pessoa antes de publicar. | Q31: Pauta proposta | T31: Modelo M9 (vídeo, capa com nome)
A32: M2-12 | B32: Mês 2 | C32: 7 | D32: =$D$2+(C32-1)*7+4 -> 46360 | E32: Produto | F32: Tecnologia e dados | G32: Tecnologia a favor da pessoa | H32: Seus dados, seu cuidado: o que fica no atendimento e o que o RH vê | I32: Colaboradores; RH e liderança | J32: Vão saber o que eu contei? O que a empresa enxerga? | K32: Dar segurança sobre privacidade e explicar os relatórios anonimizados | L32: Carrossel | M32: Instagram + LinkedIn | N32: FairJob | O32: O que você conta fica entre você e quem cuida. A empresa recebe só indicadores do grupo, sem identificar ninguém. | P32: Confirmar com o time a descrição do fluxo de dados e da LGPD. | Q32: Pauta proposta | T32: Modelo M3 (cards de interface).
A33: M2-13 | B33: Mês 2 | C33: 8 | D33: =$D$2+(C33-1)*7+0 -> 46363 | E33: Projetos, eventos e entregas | F33: Letramento e workshops | G33: Registro do mês | H33: Por dentro de um workshop nos pilares [tema e data a confirmar] | I33: Colaboradores; RH e liderança | J33: Como é um encontro de letramento na prática? | K33: Registrar uma entrega real do programa | L33: Vídeo | M33: Instagram + LinkedIn | N33: FairJob; empresa-cliente (se autorizar) | O33: A definir com o registro | P33: Data, tema e autorização de imagem. Ninguém atendido identificável. | Q33: Aguardando pauta | T33: Modelo M7.
A34: M2-14 | B34: Mês 2 | C34: 8 | D34: =$D$2+(C34-1)*7+1 -> 46364 | E34: Produto | F34: NR-1 e riscos psicossociais | G34: NR-1 (3/4): cuidado individualizado | H34: Onde o Escritório do Cuidado entra na NR-1 | I34: RH e liderança; SESMT e medicina do trabalho | J34: Isso substitui o SST ou o plano de saúde? | K34: Explicar como o Escritório complementa o SST e o plano de saúde na prevenção | L34: Carrossel | M34: Instagram + LinkedIn | N34: FairJob | O34: O Escritório do Cuidado complementa o SST e o plano de saúde: leva prevenção e cuidado individualizado para perto de quem trabalha. | P34: Responsável médica. Não prometer conformidade com a norma. | Q34: Pauta proposta | T34: Modelo M2.
A35: M2-15 | B35: Mês 2 | C35: 8 | D35: =$D$2+(C35-1)*7+3 -> 46366 | E35: Institucional | F35: Time | G35: Quem cuida (8/8) | H35: Quem cuida: Charles | I35: Colaboradores; RH e liderança | J35: Quem vai me atender? Quem são as pessoas por trás da Fair Health? | K35: Humanizar a marca e criar vínculo | L35: Vídeo | M35: Instagram + LinkedIn | N35: FairJob; perfil de Charles (se houver e se a pessoa quiser) | O35: [Resposta de Charles a "O que é importante para você?"] | P35: Material da pessoa: vídeo curto (20 a 30 s), descrição curta sem cargo e resposta à pergunta. Aprovação da pessoa antes de publicar. | Q35: Pauta proposta | T35: Modelo M9 (vídeo, capa com nome)
A36: M2-16 | B36: Mês 2 | C36: 8 | D36: =$D$2+(C36-1)*7+4 -> 46367 | E36: Produto | F36: Pilar: relações sociais | G36: Pilares da MEV (3: relações sociais) | H36: Cuidar dos vínculos é cuidar da saúde | I36: Colaboradores | J36: As relações no trabalho afetam a minha saúde? | K36: Educar sobre o pilar e conectar com o cuidado em grupo | L36: Carrossel | M36: Instagram | N36: FairJob | O36: Cuidar dos vínculos é cuidar da saúde. | P36: Responsável médica valida as orientações. | Q36: Pauta proposta | T36: Modelo M5 (pilar).
A37: M3-01 | B37: Mês 3 | C37: 9 | D37: =$D$2+(C37-1)*7+0 -> 46370 | E37: Institucional | F37: Time | G37: Quem cuida (fechamento) | H37: Oito pessoas, uma pergunta: o que é importante para você? | I37: Colaboradores; RH e liderança | J37: Quem é esse time, junto? | K37: Fechar a série do time e reforçar a pergunta da marca | L37: Vídeo | M37: Instagram + LinkedIn | N37: FairJob; integrantes | O37: Pessoas diferentes, um mesmo jeito de cuidar. | P37: Trechos curtos de cada integrante (podem vir dos vídeos da série). | Q37: Ideia | T37: Modelo M9.
A38: M3-02 | B38: Mês 3 | C38: 9 | D38: =$D$2+(C38-1)*7+1 -> 46371 | E38: Produto | F38: Pilar: alimentação | G38: Pilares da MEV (4: alimentação) | H38: Comer bem é cuidar do corpo e também da mente | I38: Colaboradores | J38: Como comer melhor numa rotina corrida, sem dieta impossível? | K38: Educar sobre o pilar e mostrar como ele entra no plano | L38: Carrossel | M38: Instagram | N38: FairJob | O38: Comer bem é cuidar do corpo e também da mente. No plano, a alimentação parte da sua rotina real. | P38: Responsável médica. Nenhum número da cartilha sem fonte verificada. | Q38: Ideia | T38: Modelo M5.
A39: M3-03 | B39: Mês 3 | C39: 9 | D39: =$D$2+(C39-1)*7+3 -> 46373 | E39: Projetos, eventos e entregas | F39: Depoimentos | G39: Da intenção à evidência (3: adesão entre colegas) | H39: "Ela não gosta de gravar vídeo. Gravou um mesmo assim." | I39: Colaboradores; RH e liderança | J39: Os colegas recomendam? | K39: Mostrar adesão espontânea com trechos aprovados | L39: Vídeo | M39: Instagram + LinkedIn | N39: FairJob | O39: "O que é bom a gente tem que compartilhar." | P39: Trechos A1 a A6 aprovados; o vídeo original não é postado. Formato confirmado com a responsável médica (CFM). | Q39: Ideia | T39: Modelo M8 animado (trechos em cards).
A40: M3-04 | B40: Mês 3 | C40: 9 | D40: =$D$2+(C40-1)*7+4 -> 46374 | E40: Institucional | F40: Quem cuida de quem cuida | H40: Quem cuida também precisa ser cuidado | I40: RH e liderança; SESMT e medicina do trabalho | J40: Por que a Fair Health fala também de quem cuida? | K40: Mostrar a visão integrada do cuidado (dos Aims da saúde à empresa) | L40: Carrossel | M40: Instagram + LinkedIn | N40: FairJob | O40: Cuidado bom é bom para quem recebe e para quem cuida. | P40: Conceitos e datas dos Aims (IHI) com fonte. | Q40: Ideia | T40: Modelo M2.
A41: M3-05 | B41: Mês 3 | C41: 10 | D41: =$D$2+(C41-1)*7+0 -> 46377 | E41: Produto | F41: NR-1 e riscos psicossociais | G41: NR-1 (4/4): acompanhamento | H41: A NR-1 não termina no diagnóstico: como acompanhar ao longo do ano | I41: RH e liderança; SESMT e medicina do trabalho | J41: Fiz o diagnóstico. Como sei se o que estamos fazendo funciona? | K41: Mostrar acompanhamento contínuo e indicadores | L41: Vídeo | M41: Instagram + LinkedIn | N41: FairJob | O41: Cuidado sem dado é intenção. O acompanhamento mostra o que muda ao longo do programa. | P41: Responsável médica. Posição [SUGESTÃO] 4 do voice.md precisa de aprovação. | Q41: Ideia | T41: Modelo M9.
...

Sheet Listas
A1: Linha editorial | B1: Formato | C1: Canal | D1: Status | E1: Mês | F1: Públicos (provisórios)
A2: Institucional | B2: Vídeo | C2: Instagram + LinkedIn | D2: Ideia | E2: Mês 1 | F2: RH e liderança
A3: Produto | B3: Carrossel | C3: Instagram | D3: Pauta proposta | E3: Mês 2 | F3: Colaboradores
A4: Projetos, eventos e entregas | B4: Foto única | C4: Instagram Stories | D4: Pauta aprovada | E4: Mês 3 | F4: SESMT e medicina do trabalho
B5: Stories | C5: LinkedIn | D5: Aguardando material | E5: Mês 4 | F5: Diretoria financeira
D6: Aguardando pauta | E6: Mês 5
D7: Roteiro pronto | E7: Mês 6
D8: Em produção | E8: Mês 7
D9: Em revisão | E9: Mês 8
D10: Validação médica | E10: Mês 9
D11: Aprovado | E11: Mês 10
D12: Agendado | E12: Mês 11
D13: Publicado | E13: Mês 12
D14: Descartada
