Workbook

Sheet Como usar
A1: Calendário editorial · Fair Health · Instagram e LinkedIn
A2: Versão de 09/10/2026: planejamento MENSAL (um mês por vez). A versão anterior, de 90 dias, está em marketing/arquivo/.
A4: O mês conta uma história
A5: Fio de todos os meses: "Cuidar antes". O plano de saúde trata depois; a Fair Health cuida antes, dentro da empresa, começando por uma pergunta.
A6: Cada mês trabalha um argumento do grupo (aba Visão do mês) e cada semana é uma cena: Abertura/Dor ("isso é comigo?"), Virada ("como a Fair Health resolve?"), Prova ("por que acreditar?") e Convite ("como começo?").
A7: Base: instagram/posicionamento-e-plano-mensal.md (análise da arquitetura de marcas e do posicionamento v3.2).
A9: Restrições em vigor (09/10)
A10: 1. Não apresentamos o time por enquanto (questão administrativa). A série Quem cuida está na aba Banco de ideias, com status Adiada.
A11: 2. Não filmamos clientes: nada gravado dentro das empresas-clientes nem com pessoas atendidas. Os vídeos do mês são de tipografia, motion, gravação de tela ou imagem de banco (aba Formatos).
A12: 3. Nunca citamos nomes reais de pessoas ou empresas nos posts. Quando a história precisa de alguém, usamos personagem fictícia, sinalizada como "história ilustrativa". O artigo da RH Pra Você (25/09/2026) é citado só pelo título e pelo veículo.
A13: 4. Números são bem-vindos, mas o foco é o cuidado: a frase de cuidado vem primeiro e o número entra como contexto, em tom calmo, com a fonte visível (regras na aba Ciência).
A14: 5. Artigos científicos e fontes oficiais viram posts que conectam a evidência ao nosso trabalho (aba Ciência). Medicina do Estilo de Vida: 6 pilares, sem espiritualidade (a confirmar).
... A41: Linhas e personas · Pendências · Listas (valores das listas suspensas).

Sheet Visão do mês
A1: Visão do mês: o capítulo e o equilíbrio
A2: Primeiro nível do planejamento. As contagens são automáticas e servem para a checagem de equilíbrio na revisão mensal.
A4: Mês | B4: Mês 1
A5: Período | B5: =TEXT('Calendário'!$D$2,"DD/MM")&" a "&TEXT('Calendário'!$D$2+27,"DD/MM")
A6: Capítulo | B6: "Tudo começa com uma pergunta": quem somos, por que cuidar antes e como o cuidado funciona.
A7: Argumento principal | B7: Liderança Bem-Estar, com a apresentação da marca. A NR-1 entra como contexto (artigo da RH Pra Você) e a ciência sustenta o mês (OMS, Diabetes Prevention Program, RAND).
A8: Mensagem do mês | B8: Todo afastamento tem um antes. A Fair Health cuida nesse antes: dentro da empresa, com gente de verdade, começando por uma pergunta.
A9: Frase-tese | B9: Não é benefício. É infraestrutura de cuidado.
A10: Restrições | B10: Sem apresentar o time (questão administrativa), sem filmar clientes e sem nomes reais (personagens fictícias quando preciso). Vídeos de tipografia, motion, gravação de tela ou imagem de banco.
A11: Números | B11: Sim, com suavidade: cuidado primeiro, número como contexto, fonte visível. Um número principal por peça.
A12: Datas do calendário | B12: 02/11 feriado (Finados): a semana 3 começa na terça. 14/11 (sábado) Dia Mundial do Diabetes: post de ciência na véspera (M1-16) e stories no dia. Novembro Azul: só se houver conexão real.
A14: A história semana a semana
A15: Semana | B15: Cena | C15: Pergunta que responde | D15: Peças (IDs) | E15: Total | F15: Vídeos | G15: Institucional | H15: Produto | I15: Projetos
A16: 1 | B16: Abertura e Dor | C16: "Isso é comigo?" A marca se apresenta e o RH se reconhece no problema. | D16: M1-01 a M1-04 | E16: =COUNTIFS('Calendário'!$C$5:$C$400,$A16) | F16: =COUNTIFS('Calendário'!$C$5:$C$400,$A16,'Calendário'!$N$5:$N$400,"Vídeo") | G16: =COUNTIFS('Calendário'!$C$5:$C$400,$A16,'Calendário'!$E$5:$E$400,"Institucional") | H16: =COUNTIFS('Calendário'!$C$5:$C$400,$A16,'Calendário'!$E$5:$E$400,"Produto") | I16: =COUNTIFS('Calendário'!$C$5:$C$400,$A16,'Calendário'!$E$5:$E$400,"Projetos, eventos e entregas")
A17: 2 | B17: Virada | C17: "Como a Fair Health resolve?" Método, tese e o que o RH recebe. | D17: M1-05 a M1-08 | E17: =COUNTIFS('Calendário'!$C$5:$C$400,$A17) | F17: =COUNTIFS('Calendário'!$C$5:$C$400,$A17,'Calendário'!$N$5:$N$400,"Vídeo") | G17: =COUNTIFS('Calendário'!$C$5:$C$400,$A17,'Calendário'!$E$5:$E$400,"Institucional") | H17: =COUNTIFS('Calendário'!$C$5:$C$400,$A17,'Calendário'!$E$5:$E$400,"Produto") | I17: =COUNTIFS('Calendário'!$C$5:$C$400,$A17,'Calendário'!$E$5:$E$400,"Projetos, eventos e entregas")
A18: 3 | B18: Prova | C18: "Por que acreditar?" Adesão, acompanhamento, origem e autoridade. | D18: M1-09 a M1-12 | E18: =COUNTIFS('Calendário'!$C$5:$C$400,$A18) | F18: =COUNTIFS('Calendário'!$C$5:$C$400,$A18,'Calendário'!$N$5:$N$400,"Vídeo") | G18: =COUNTIFS('Calendário'!$C$5:$C$400,$A18,'Calendário'!$E$5:$E$400,"Institucional") | H18: =COUNTIFS('Calendário'!$C$5:$C$400,$A18,'Calendário'!$E$5:$E$400,"Produto") | I18: =COUNTIFS('Calendário'!$C$5:$C$400,$A18,'Calendário'!$E$5:$E$400,"Projetos, eventos e entregas")
A19: 4 | B19: Convite | C19: "Como começo?" Para o colaborador, o líder e o RH, com a ciência por trás do cuidado. | D19: M1-13 a M1-16 | E19: =COUNTIFS('Calendário'!$C$5:$C$400,$A19) | F19: =COUNTIFS('Calendário'!$C$5:$C$400,$A19,'Calendário'!$N$5:$N$400,"Vídeo") | G19: =COUNTIFS('Calendário'!$C$5:$C$400,$A19,'Calendário'!$E$5:$E$400,"Institucional") | H19: =COUNTIFS('Calendário'!$C$5:$C$400,$A19,'Calendário'!$E$5:$E$400,"Produto") | I19: =COUNTIFS('Calendário'!$C$5:$C$400,$A19,'Calendário'!$E$5:$E$400,"Projetos, eventos e entregas")
A20: Total | E20: =SUM(E16:E19) | F20: =SUM(F16:F19) | G20: =SUM(G16:G19) | H20: =SUM(H16:H19) | I20: =SUM(I16:I19)
A22: Equilíbrio por argumento e por cena
A23: Argumento | B23: Peças | D23: Cena | E23: Peças | G23: Pautas com validação médica
A24: Apresentação | B24: =COUNTIFS('Calendário'!$F$5:$F$400,$A24) | D24: Abertura | E24: =COUNTIFS('Calendário'!$G$5:$G$400,$D24) | G24: =SUMPRODUCT(('Calendário'!$B$5:$B$400<>"")*ISNUMBER(SEARCH("responsável médica",'Calendário'!$T$5:$T$400)))
A25: Liderança Bem-Estar | B25: =COUNTIFS('Calendário'!$F$5:$F$400,$A25) | D25: Dor | E25: =COUNTIFS('Calendário'!$G$5:$G$400,$D25)
A26: NR-1 | B26: =COUNTIFS('Calendário'!$F$5:$F$400,$A26) | D26: Virada | E26: =COUNTIFS('Calendário'!$G$5:$G$400,$D26)
A27: Stop Loss | B27: =COUNTIFS('Calendário'!$F$5:$F$400,$A27) | D27: Prova | E27: =COUNTIFS('Calendário'!$G$5:$G$400,$D27)
A28: Ambiente positivo | B28: =COUNTIFS('Calendário'!$F$5:$F$400,$A28) | D28: Convite | E28: =COUNTIFS('Calendário'!$G$5:$G$400,$D28)
A29: Marca empregadora | B29: =COUNTIFS('Calendário'!$F$5:$F$400,$A29)

Sheet Calendário
A1: Calendário editorial · Fair Health · Mês 1
A2: Início do mês (segunda-feira): | D2: 46314 | E2: Mude a data amarela para reposicionar o mês. Os dias da semana são só sugestão.
A4: ID | B4: Mês | C4: Semana | D4: Data sugerida | E4: Linha editorial | F4: Argumento | G4: Cena | H4: Tema | I4: Série (parte) | J4: Título provisório | K4: Persona | L4: Necessidade ou pergunta da persona | M4: Objetivo | N4: Formato | O4: Por que este formato | P4: Canal | Q4: Collab / perfis | R4: Mensagem principal | S4: Fonte | T4: Validação necessária | U4: Status | V4: Texto / legenda | W4: Roteiro / estrutura | X4: Criativo (modelo e arte) | Y4: Responsável | Z4: Comentários da revisão
A5: M1-01 | B5: Mês 1 | C5: 1 | D5: =$D$2+(C5-1)*7+0 | E5: Institucional | F5: Apresentação | G5: Abertura | H5: Apresentação da Fair Health | J5: Antes de qualquer exame, uma conversa | K5: Colaboradores; RH | L5: O que é a Fair Health e o que ela faz dentro da empresa? | M5: Apresentar a marca e o jeito de cuidar | N5: Vídeo | O5: Vídeo de abertura com a pergunta da marca: apresenta em 30 s o que é, onde fica e como começa. Texto na tela para quem assiste sem som. | P5: Instagram + LinkedIn | Q5: FairJob | R5: A Fair Health leva o cuidado para dentro da empresa, e todo cuidado começa com uma pergunta: o que é importante para você? | S5: Posicionamento Fair Health v3.2 (promessa e pergunta). | T5: Roteiro e legenda citam assistentes sociais: confirmar se fazem parte do atendimento (o posicionamento cita médico e psicológico). Sem time em cena e sem gravar nas empresas-clientes (decisão de 09/10). Definir onde gravar (local próprio ou neutro) ou montar com fotos e tipografia. | U5: Roteiro pronto | V5: Antes de qualquer exame, uma conversa. Esse é o Escritório do Cuidado: um espaço dentro da empresa, com médicos, psicólogos e assistentes sociais, perto de quem trabalha. Aqui, todo cuidado começa com a mesma pergunta: o que é importante para você? A partir da resposta, montamos juntos um plano que cabe na sua rotina e seguimos acompanhando. Seja bem-vindo. Nos próximos dias, a gente mostra como esse cuidado funciona. #fairhealth #saudecorporativa #cuidadocentradonapessoa #medicinadoestilodevida #saudedotrabalhador | W5: Reel de 30 a 34 s (instagram/primeiros-posts-acolhimento.md, ID 1). 0–3 s: "Antes de qualquer exame, a gente começa com uma conversa." Porta se abrindo. 3–9 s: o espaço (recepção, copa, sala), sem pessoas. 9–16 s: detalhes que acolhem: mãos servindo café, cadeira puxada, sem rosto. 16–23 s: a pergunta "O que é importante para você?" aparece na tela, em voz em off. 23–30 s: a partir da resposta, um cuidado que cabe na rotina. 30–34 s: logo e assinatura. | X5: Vídeo 1080x1920. Texto na tela dentro da área segura. Capa no modelo M1 (Tiffany, pergunta), conferindo o recorte da grade. LinkedIn: mesmo vídeo, legenda adaptada para RH. | Z5: Aprovado na revisão de 09/10. Ajustes pelas restrições de 09/10: a legenda não promete mais apresentar o time ("você vai conhecer quem cuida" virou "a gente mostra como esse cuidado funciona") e, no roteiro, a pergunta entra na tela em voz em off (antes cada integrante dizia um pedaço).
A6: M1-02 | B6: Mês 1 | C6: 1 | D6: =$D$2+(C6-1)*7+1 | E6: Produto | F6: Apresentação | G6: Abertura | H6: Escritório do Cuidado | I6: Como funciona o cuidado (1/3): o percurso | J6: Aqui, o cuidado começa com uma pergunta | K6: Colaboradores | L6: O que acontece quando eu vou ao Escritório do Cuidado? Vou ser julgado? O que eu contar fica entre nós? | M6: Explicar o percurso do atendimento e reduzir a barreira de ir | N6: Carrossel | O6: Carrossel passo a passo: o formato mais salvo em conteúdo explicativo. Responde as objeções (julgamento, sigilo) uma por slide. | P6: Instagram + LinkedIn | Q6: FairJob | R6: Primeiro a gente te ouve e entende sua rotina; depois monta o plano com você e acompanha. O que você conta fica entre você e quem cuida. | S6: Cartilha do Escritório do Cuidado. | T6: Responsável médica confere as etapas citadas (anamnese, bioimpedância, smartband por 48 horas, retorno). | U6: Em revisão | V6: Aqui, o cuidado começa com uma pergunta: o que é importante para você? Antes de exame, antes de número, a gente quer saber da sua rotina, do seu trabalho, do que anda pesando e do que você gostaria de mudar. O Escritório do Cuidado fica dentro da empresa, perto de onde você já está. Lá, médicos e psicólogos se revezam para montar com você um cuidado que caiba na sua vida, com base na Medicina do Estilo de Vida. O objetivo da fairhealth é melhorar a qualidade de vida de quem trabalha, com um cuidado feito para cada pessoa e acompanhado de perto. E o que você conta fica entre você e quem cuida. Arrasta para o lado para ver como funciona. #fairhealth #saudecorporativa #cuidadocentradonapessoa #medicinadoestilodevida #saudedotrabalhador | W6: 10 slides: 1 capa (pergunta) · 2 fica dentro da empresa · 3 gente que cuida de gente · 4 Passo 1: a gente te conhece · 5 Passo 2: o que é importante para você? · 6 Passo 3: entender antes de propor (bioimpedância e smartband por 48 h) · 7 Passo 4: o plano é seu · 8 Passo 5: retorno e acompanhamento · 9 sigilo · 10 convite para comentar. | X6: Arte no Canva (design DAHW6JfDldU, 11 páginas): escolher entre as versões originais e as novas dos slides 1, 5, 7, 9 e 10. Modelos M1, M2 e M3. LinkedIn: exportar em PDF. | Z6: Conferir o slide 3 ("gente que cuida de gente"): não pode ter foto ou nome de integrante do time.
A7: M1-03 | B7: Mês 1 | C7: 1 | D7: =$D$2+(C7-1)*7+3 | E7: Institucional | F7: Liderança Bem-Estar | G7: Dor | H7: Cuidar antes (manifesto) | J7: Antes do afastamento, teve um sinal | K7: RH; Lideranças | L7: Por que as pessoas só aparecem quando já estão doentes ou afastadas? | M7: Plantar o fio do mês ("cuidar antes") e fazer o RH se reconhecer na dor | N7: Vídeo | O7: Reel de tipografia animada: não depende de filmagem nem de rosto, o gancho está na primeira frase e a cadeia do "antes" prende até o fim. Fácil de adaptar para o LinkedIn. | P7: Instagram + LinkedIn | Q7: FairJob | R7: Todo afastamento tem um antes. A Fair Health cuida nesse antes, dentro da empresa, começando por uma pergunta. | S7: Posicionamento Fair Health v3.2 (eixo "antes"). Ministério da Previdência Social: 472.328 licenças por transtornos mentais em 2024, maior número da série iniciada em 2014 (dados divulgados em 2025; conferir no painel oficial de dados abertos antes de publicar). | T7: Sem promessa de evitar doença (CFM): o texto fala de cuidado, não de resultado. Número suave: cuidado primeiro, número como contexto, fonte visível e discreta (aba Ciência). Conferir o número no painel oficial. | U7: Pauta proposta | V7: Antes do afastamento, teve um atestado. Antes do atestado, teve uma semana pesada. Antes da semana pesada, teve uma noite sem dormir. E antes de tudo isso, ninguém perguntou: o que é importante para você? Em 2024, o Brasil registrou mais de 470 mil licenças do trabalho por saúde mental, o maior número em dez anos (Ministério da Previdência Social). Cada uma delas teve um antes. A Fair Health existe para cuidar nesse antes. Dentro da empresa, perto de quem trabalha, com médicos e psicólogos e um plano feito para cada pessoa. Cuidar antes também é papel da liderança. Na sua empresa, quem faz essa pergunta? #fairhealth #saudecorporativa #cuidadocentradonapessoa #medicinadoestilodevida #saudedotrabalhador | W7: Reel de 22 a 26 s, só tipografia sobre o fundo Tiffany, frase a frase, com corte seco. 0–3 s: "Antes do afastamento, teve um atestado." 3–6 s: "Antes do atestado, teve uma semana pesada." 6–9 s: "Antes da semana pesada, uma noite sem dormir." 9–14 s: "E antes de tudo isso, ninguém perguntou:" 14–18 s: "O que é importante para você?" (palavra-chave em destaque) 18–22 s: em texto menor e calmo: "Em 2024, mais de 470 mil licenças por saúde mental no Brasil. Cada uma teve um antes." Fonte no rodapé. 22–26 s: "Cuidar antes." + logo. Trilha calma, sem locução (ou voz em off opcional). | X7: Modelo M9 (vídeo) só com tipografia Raleway. Capa: "Antes do afastamento, teve um sinal". Sem imagem de banco.
A8: M1-04 | B8: Mês 1 | C8: 1 | D8: =$D$2+(C8-1)*7+4 | E8: Projetos, eventos e entregas | F8: NR-1 | G8: Dor | H8: Na imprensa: artigo sobre riscos psicossociais | I8: Saúde mental é de todos (1/2) | J8: O trabalho não é o único vilão | K8: RH; Lideranças; Risco e Compliance | L8: A NR-1 colocou os riscos psicossociais na conta da empresa. O que é responsabilidade da empresa e o que não é? | M8: Trazer a NR-1 com uma visão madura e transferir a autoridade da publicação para a marca | N8: Carrossel | O8: Carrossel-resumo de artigo publicado: formato muito compartilhado entre profissionais de RH. Leva a autoridade do veículo para a marca, sem citar pessoas. | P8: Instagram + LinkedIn | Q8: FairJob; RH Pra Você (marcar o veículo, se fizer sentido) | R8: A NR-1 formalizou que o trabalho pode adoecer, e a empresa responde pelo ambiente que constrói. Mas saúde mental é multifatorial: é, ao mesmo tempo, de cada um e de todos. | S8: Artigo "Riscos psicossociais no ambiente de trabalho e saúde", RH Pra Você, 25/09/2026. https://rhpravoce.com.br/colab/riscos-psicossociais-no-ambiente-de-trabalho-2 Dado do slide 4: Global Burden of Disease (citado no artigo). | T8: Citar só o artigo (título e veículo), sem o nome do autor. Nenhum nome real de pessoa ou empresa no post (decisão de 09/10). Conferir as citações literais com o artigo. Número suave: cuidado primeiro, número como contexto, fonte visível e discreta (aba Ciência). | U8: Pauta proposta | V8: O trabalho pode adoecer. Mas não é o único vilão. Desde maio de 2026, a NR-1 exige que as empresas identifiquem, avaliem e gerenciem os riscos psicossociais. É um avanço necessário: assédio, excesso de pressão, jornadas inadequadas e lideranças despreparadas têm impacto real na saúde mental. Um artigo publicado na RH Pra Você propõe ampliar o debate: ninguém começa a vida quando é contratado. Família, escola, comunidade e condições de vida chegam ao trabalho junto com a pessoa. Isso não diminui a responsabilidade da empresa. Ela responde pelo ambiente que constrói. Mas não controla todas as variáveis. "Saúde mental é, ao mesmo tempo, de cada um e de todos." O artigo completo está no link dos stories. Concorda? Conta pra gente nos comentários. #fairhealth #nr1 #riscospsicossociais #saudementalnotrabalho #rh | W8: 8 slides. 1 Capa: "O trabalho pode adoecer. Mas não é o único vilão." + "Da RH Pra Você". 2 Desde maio de 2026, a NR-1 exige identificar, avaliar e gerenciar os riscos psicossociais. 3 É um avanço necessário: ambientes tóxicos, assédio, excesso de pressão, jornadas inadequadas, insegurança e lideranças despreparadas adoecem. 4 "Nenhuma pessoa começa sua vida quando é contratada por uma empresa." Abaixo, em texto menor: no mundo, quase 1 bilhão de pessoas convivem com algum transtorno mental (Global Burden of Disease, 2019). 5 A empresa responde pelo ambiente que constrói. Não controla todas as variáveis. 6 Responsabilidade compartilhada: poder público, sociedade, empresas e cada pessoa (sem culpar quem adoece). 7 "Saúde mental é, ao mesmo tempo, de cada um e de todos." (do artigo, sem nome) 8 A parte da empresa começa antes: um cuidado dentro do trabalho, que começa com uma pergunta. Link nos stories. | X8: Modelo M8 (citação) nos slides 4 e 7 e M2 nos demais. Sem foto. Stories no mesmo dia com o link do artigo.
A9: M1-05 | B9: Mês 1 | C9: 2 | D9: =$D$2+(C9-1)*7+0 | E9: Produto | F9: Liderança Bem-Estar | G9: Virada | H9: Medicina do Estilo de Vida | I9: Pilares da MEV (abertura) | J9: Medicina do Estilo de Vida em 1 minuto | K9: Colaboradores; RH | L9: O que é Medicina do Estilo de Vida? É dieta? É academia? | M9: Apresentar a base científica do cuidado e abrir a série dos pilares | N9: Vídeo | O9: Explicador animado com ícones (motion): conceito novo explicado em 1 minuto, sem rosto. Responde ao mito "é só dieta e academia". | P9: Instagram + LinkedIn | Q9: FairJob | R9: Seis pilares, uma pessoa inteira: alimentação, atividade física, sono, manejo do estresse, relacionamentos e evitar substâncias de risco. O plano olha para todos, a partir da rotina real. | S9: ACLM (American College of Lifestyle Medicine), 6 pilares; CBMEV (Colégio Brasileiro de Medicina do Estilo de Vida); cartilha do Escritório do Cuidado. | T9: 6 pilares, sem espiritualidade (decisão de 09/10, ainda a confirmar). Responsável médica valida a definição de MEV e os nomes dos pilares. | U9: Pauta proposta | W9: Reel de 45 a 60 s, motion com ícones, voz em off. 0–3 s: "Medicina do Estilo de Vida é dieta e academia? Não só." 3–10 s: definição curta, com fonte na tela. 10–40 s: os 6 pilares, um ícone e uma frase por pilar: alimentação · atividade física · sono · manejo do estresse · relacionamentos · evitar substâncias de risco. 40–50 s: "Os pilares conversam entre si: o plano olha para a pessoa inteira." 50–60 s: "No Escritório do Cuidado, começa com uma pergunta." + logo. | X9: Modelo M9 com ícones lineares em verde-escuro sobre Tiffany. Etiqueta "PILARES".
A10: M1-06 | B10: Mês 1 | C10: 2 | D10: =$D$2+(C10-1)*7+1 | E10: Institucional | F10: Liderança Bem-Estar | G10: Virada | H10: Tese da marca | J10: Não é benefício. É infraestrutura de cuidado. | K10: RH; RI e C-Level | L10: Isso é mais um benefício para a lista? Por que seria diferente do que já temos? | M10: Fixar a frase-tese e posicionar a categoria sem citar concorrentes | N10: Carrossel | O10: Carrossel comparativo de duas colunas (isto × aquilo): a diferença fica clara em segundos e o post é salvo e repassado ao decisor. | P10: Instagram + LinkedIn | Q10: FairJob | R10: Benefício é algo que a pessoa usa se lembrar. Infraestrutura de cuidado está dentro da empresa todo dia, começa antes do problema e tem gente acompanhando. | S10: Posicionamento Fair Health v3.2 (diferenciais). | T10: Não citar marcas de terceiros nem operadoras. Sem números. | U10: Pauta proposta | W10: 6 slides. 1 Capa: "Não é benefício. É infraestrutura de cuidado." 2 Benefício: a pessoa usa se lembrar. Infraestrutura: está lá todo dia, dentro da empresa. 3 Benefício: espera o problema aparecer. Infraestrutura: começa antes. 4 Benefício: é um cartão. Infraestrutura: é gente acompanhando, com um plano para cada pessoa. 5 Benefício: termina na adesão. Infraestrutura: o RH acompanha o cuidado por indicadores do grupo. 6 "O que é importante para você?" Comente CUIDADO para saber como funciona. | X10: Modelo M1 na capa e comparativo em duas colunas (Tiffany × verde-escuro) nos slides 2 a 5.
A11: M1-07 | B11: Mês 1 | C11: 2 | D11: =$D$2+(C11-1)*7+3 | E11: Projetos, eventos e entregas | F11: NR-1 | G11: Virada | H11: Entregas para o RH | I11: Tecnologia a favor da pessoa | J11: O que o RH vê (e o que não vê) | K11: RH; Risco e Compliance | L11: O que eu recebo para acompanhar o programa? Vou ver dados individuais? | M11: Mostrar a entrega para a empresa e a regra de privacidade | N11: Vídeo | O11: Gravação de tela de um painel genérico, com texto na tela: mostra o produto de verdade sem expor ninguém e responde a dúvida que trava a decisão do RH. | P11: Instagram + LinkedIn | Q11: FairJob; fairdata | R11: O RH acompanha o cuidado por indicadores do grupo, anonimizados e integrados à fairdata. O que cada pessoa conta fica no atendimento. | S11: Posicionamento Fair Health v3.2 (fairdata). | T11: Time confirma quais indicadores entram no relatório. Painel com dados fictícios e aviso "dados ilustrativos". Não prometer conformidade com a NR-1. | U11: Pauta proposta | W11: Reel de 25 a 30 s, gravação de tela. 0–3 s: "O que o RH vê no Escritório do Cuidado?" 3–15 s: rolagem pelo painel (adesão, retorno, temas mais procurados), dados ilustrativos. 15–22 s: "O que o RH não vê: o que cada pessoa contou." 22–30 s: "Indicadores do grupo para cuidar antes." + logo. | X11: Modelo M9. Painel montado com dados fictícios, moldura de navegador ou de notebook.
A12: M1-08 | B12: Mês 1 | C12: 2 | D12: =$D$2+(C12-1)*7+4 | E12: Produto | F12: Apresentação | G12: Virada | H12: Plano Individualizado de Cuidado | I12: Como funciona o cuidado (2/3): o plano | J12: O plano é seu: como nasce o Plano Individualizado de Cuidado | K12: Colaboradores | L12: Vou receber uma lista de regras impossíveis de seguir? | M12: Explicar como o plano é montado com a pessoa (decisão compartilhada) | N12: Carrossel | O12: Carrossel com card de interface (M3), já testado no carrossel de acolhimento, contado pela história de uma personagem fictícia: história prende mais que explicação e mostra o plano como algo possível. | P12: Instagram + LinkedIn | Q12: FairJob | R12: O plano parte do que é importante para você e da sua rotina real, com ações nos pilares da MEV, e muda quando a vida muda. | S12: Cartilha do Escritório do Cuidado. Personagem fictícia. | T12: Responsável médica valida etapas e prazos. Nome único do plano: "Plano Individualizado de Cuidado" ou "Plano de Cuidado Personalizado"? Indicar no slide e na legenda que é uma história ilustrativa (personagem fictícia), para não parecer depoimento. | U12: Pauta proposta | W12: 7 slides, com a Clara (personagem fictícia, 41 anos, supervisora de turno). 1 Capa: "O plano é seu." 2 A Clara chegou dizendo: "Quero voltar a ter energia para brincar com meu filho." Isso é o que importa para ela. 3 Card do plano da Clara: 3 ações pequenas (dormir 30 min mais cedo, caminhada de 10 min no almoço, conversa quinzenal com a psicóloga). 4 Cabe na rotina real: no turno dela, não numa rotina ideal. 5 Muda quando a vida muda. 6 Alguém acompanha, sem julgamento. 7 "E para você, o que é importante?" Rodapé: "História ilustrativa. Personagem fictícia." | X12: Modelo M3 (card de interface do plano). Sem foto de pessoa: a personagem aparece só no texto e no card.
A13: M1-09 | B13: Mês 1 | C13: 3 | D13: =$D$2+(C13-1)*7+1 | E13: Projetos, eventos e entregas | F13: Liderança Bem-Estar | G13: Prova | H13: Adesão (número liberado) | J13: Quando o cuidado está perto, as pessoas voltam | K13: RH; Diretoria financeira | L13: Programa de saúde que ninguém usa é custo. As pessoas usam isso de verdade? | M13: Provar adesão com número liberado, contado como cuidado e não como resultado | N13: Vídeo | O13: Número contado como história: primeiro a cena de cuidado, depois o número, em tom calmo. É a prova que o RH leva para a diretoria, sem cara de anúncio. | P13: Instagram + LinkedIn | Q13: FairJob | R13: Quando o cuidado está perto e começa por uma conversa, as pessoas voltam: numa indústria atendida, 8 em cada 10 pessoas voltaram para mais de um atendimento. | S13: Dados internos de um cliente do setor industrial, 1º semestre de 2026 (liberados; ver aba Fontes). Sempre agregado e sem o nome da empresa. | T13: Nenhum nome real de pessoa ou empresa no post (decisão de 09/10). Usar "uma indústria". Número suave: cuidado primeiro, número como contexto, fonte visível e discreta (aba Ciência). | U13: Pauta proposta | W13: Reel de 18 a 22 s, tipografia e números suaves. 0–4 s: "Ninguém volta a um lugar onde não se sentiu cuidado." 4–9 s: "Numa indústria que atendemos, no primeiro semestre de 2026..." 9–14 s: "8 em cada 10 pessoas voltaram para mais de um atendimento." (número em destaque, sem exagero) 14–18 s: em texto menor: "A adesão chegou a 98%." 18–22 s: "Cuidado que as pessoas procuram." + fonte discreta + logo. | X13: Modelo M6 (dado com fonte) animado, em ritmo lento. Número em verde-escuro, nunca em vermelho; sem setas para cima nem efeito de "conquista".
A14: M1-10 | B14: Mês 1 | C14: 3 | D14: =$D$2+(C14-1)*7+2 | E14: Produto | F14: Apresentação | G14: Prova | H14: Tecnologia: wearables | I14: Como funciona o cuidado (3/3): o acompanhamento | J14: O cuidado não para quando a consulta acaba | K14: Colaboradores; RH | L14: Para que serve a pulseira? Vão me vigiar? | M14: Explicar o acompanhamento com tecnologia e a regra de privacidade | N14: Carrossel | O14: Carrossel explicativo com a objeção no título ("vão me vigiar?"): responde a dúvida mais comum antes que ela vire resistência. | P14: Instagram + LinkedIn | Q14: FairJob | R14: A smartband e a bioimpedância ajudam a olhar, junto com a pessoa, como foram as últimas semanas. Os dados ficam no atendimento; o RH vê só o grupo. | S14: Cartilha do Escritório do Cuidado. | T14: [PENDENTE] Quais dados a smartband registra e se todos os atendidos usam a pulseira (instagram/posts/wearables/README.md). | U14: Em revisão | X14: Arte pronta em instagram/posts/wearables (8 slides). Capa: foto de pulso sem rosto (modelo com autorização, fora das empresas-clientes) ou capa só tipográfica.
A15: M1-11 | B15: Mês 1 | C15: 3 | D15: =$D$2+(C15-1)*7+3 | E15: Institucional | F15: Apresentação | G15: Prova | H15: Origem | J15: Tudo começou num hospital | K15: RH; Medicina do Trabalho | L15: De onde vem esse modelo? É só mais um programa de bem-estar? | M15: Dar lastro à marca com a história do modelo | N15: Vídeo | O15: Linha do tempo animada (ano grande + uma frase): história de origem gera confiança e não precisa mostrar pessoas. | P15: Instagram + LinkedIn | Q15: FairJob | R15: O modelo nasceu em 2009, num hospital, para colocar o paciente no centro do cuidado. Hoje, coloca quem trabalha no centro, dentro da empresa. | S15: Histórico do Escritório do Paciente (2009); caso do hospital onde o modelo começou (liberado; ver aba Fontes). | T15: Sem nomes de pessoas nem do hospital. Não usar "validado no SUS" até confirmar a fonte. Conferir datas. | U15: Pauta proposta | W15: Reel de 25 a 30 s, linha do tempo em tipografia. 0–3 s: "Tudo começou num hospital." 3–10 s: 2009: Escritório do Paciente, o paciente no centro. 10–18 s: o que o hospital aprendeu: ouvir antes de propor. 18–25 s: hoje: o Escritório do Cuidado, dentro da empresa. 25–30 s: "Mesma pergunta: o que é importante para você?" + logo. Alternativa: carrossel no modelo M2. | X15: Modelo M9 com marcos da linha do tempo (modelo M2 animado). Sem fotos de pessoas.
A16: M1-12 | B16: Mês 1 | C16: 3 | D16: =$D$2+(C16-1)*7+4 | E16: Projetos, eventos e entregas | F16: NR-1 | G16: Prova | H16: Na imprensa: artigo sobre riscos psicossociais | I16: Saúde mental é de todos (2/2) | J16: A pergunta maior | K16: RH; Lideranças | L16: Como olhar para a saúde mental do time sem simplificar? | M16: Reaproveitar o artigo com uma frase forte e reforçar a autoridade | N16: Foto única | O16: Card de citação: uma frase forte, fácil de compartilhar nos stories e no LinkedIn. Reaproveita o artigo sem repetir o carrossel. | P16: Instagram + LinkedIn | Q16: FairJob | R16: "Antes de perguntar apenas o que o trabalho está fazendo com a saúde mental das pessoas, deveríamos fazer uma pergunta maior: o que a nossa forma de viver em sociedade está fazendo com a saúde mental das pessoas?" | S16: Artigo "Riscos psicossociais no ambiente de trabalho e saúde", RH Pra Você, 25/09/2026. https://rhpravoce.com.br/colab/riscos-psicossociais-no-ambiente-de-trabalho-2 | T16: Citação literal conferida com o artigo. Crédito só ao artigo e ao veículo, sem nome do autor. Nenhum nome real de pessoa ou empresa no post (decisão de 09/10). | U16: Pauta proposta | W16: Imagem única: a pergunta em destaque, assinatura "Do artigo 'Riscos psicossociais no ambiente de trabalho e saúde', RH Pra Você". Legenda curta que liga a pergunta à da marca ("o que é importante para você?") e convida a ler o artigo. | X16: Modelo M8 (citação), sem foto.
A17: M1-13 | B17: Mês 1 | C17: 4 | D17: =$D$2+(C17-1)*7+0 | E17: Produto | F17: Liderança Bem-Estar | G17: Convite | H17: Pilar: sono | I17: Pilares da MEV (1: sono) | J17: Dormir não é tempo perdido | K17: Colaboradores | L17: Por que eu acordo cansado? O que dá para mudar na rotina? | M17: Educar sobre o pilar sono e convidar o colaborador a procurar o Escritório | N17: Vídeo | O17: Reel de "3 hábitos" com texto na tela sobre imagens de banco: dica prática e salvável, sem rosto e sem gravar nas empresas. | P17: Instagram | Q17: FairJob | R17: Dormir não é tempo perdido. A faixa saudável para adultos fica entre 7 e 9 horas por noite. No Escritório do Cuidado, o sono entra no plano a partir da sua rotina real. | S17: Guia "Saúde mental: o cuidado no dia a dia" (higiene do sono; OMS, APA, IPq-USP). Hafner M. et al. Why sleep matters: the economic costs of insufficient sleep. RAND Europe, 2016 (RR-1791). https://www.rand.org/news/press/2016/11/30.html | T17: Responsável médica valida as orientações. Sem promessa clínica. Número suave: cuidado primeiro, número como contexto, fonte visível e discreta (aba Ciência). | U17: Pauta proposta | W17: Reel de 22 a 27 s. 0–3 s: "Acorda cansado mesmo dormindo?" 3–6 s: em texto calmo: "Para adultos, o sono saudável fica entre 7 e 9 horas." (fonte discreta: RAND Europe, 2016) 6–19 s: 3 hábitos, um por cena (tela antes de dormir, horário regular, cafeína à tarde). 19–27 s: "Se o cansaço não passa, conversa com a gente no Escritório do Cuidado." + logo. Legenda (opcional, para o RH no LinkedIn): um estudo da RAND Europe estimou que a falta de sono custa mais de 1 milhão de dias de trabalho por ano só nos Estados Unidos. | X17: Modelo M9 com etiqueta "PILARES · SONO". Imagens de banco (quarto, celular à noite), sem rosto identificável.
A18: M1-14 | B18: Mês 1 | C18: 4 | D18: =$D$2+(C18-1)*7+1 | E18: Institucional | F18: Liderança Bem-Estar | G18: Convite | H18: A pergunta (com a recomendação da OMS) | I18: Ciência no cuidado | J18: Uma pergunta que todo líder pode fazer | K18: Lideranças; RH | L18: Como a liderança pode cuidar do time no dia a dia, sem ser médica nem psicóloga? | M18: Levar a pergunta da marca para a liderança, com o respaldo da recomendação da OMS, e gerar conversa | N18: Carrossel | O18: Carrossel de ciência aplicada: a recomendação de uma fonte respeitada (OMS) vira um gesto simples que o líder pode repetir. Fecha com pergunta aberta, que gera comentários. | P18: Instagram + LinkedIn | Q18: FairJob | R18: A OMS recomenda preparar as lideranças para prevenir ambientes de estresse e acolher quem está em sofrimento. Um bom começo cabe numa pergunta: o que é importante para você? | S18: OMS. Guidelines on mental health at work, 28/09/2022 (com a OIT: policy brief "Mental health at work"). https://www.who.int/news/item/28-09-2022-who-and-ilo-call-for-new-measures-to-tackle-mental-health-issues-at-work | T18: Conferir a redação da recomendação nas diretrizes da OMS. O líder não substitui o cuidado clínico: deixar claro onde pedir ajuda. | U18: Pauta proposta | W18: 6 slides. 1 Capa: "Uma pergunta que todo líder pode fazer." 2 Em 2022, a OMS publicou suas primeiras diretrizes sobre saúde mental no trabalho. Uma das recomendações: preparar as lideranças. 3 Para quê? Para prevenir ambientes de estresse e acolher quem está em sofrimento. 4 Não é virar terapeuta. É perguntar, ouvir e saber para onde encaminhar. 5 Um bom começo: "O que é importante para você?" 6 Líder, quando foi a última vez que você fez essa pergunta? Conta nos comentários. Fonte: OMS, 2022. Stories no mesmo dia com caixa de perguntas. | X18: Modelo M1 na capa e M2 nos demais; fonte no rodapé (M6).
A19: M1-15 | B19: Mês 1 | C19: 4 | D19: =$D$2+(C19-1)*7+3 | E19: Projetos, eventos e entregas | F19: Apresentação | G19: Convite | H19: Como começa numa empresa | I19: Como chega a uma empresa | J19: Como o Escritório do Cuidado chega à sua empresa | K19: RH; Diretoria financeira | L19: Quero isso na minha empresa. Por onde começa? | M19: Deixar clara a oferta e o primeiro passo comercial | N19: Vídeo | O19: Passo a passo animado com chamada para ação por palavra-chave ("comente CUIDADO"): fecha o mês com um caminho claro para o RH. | P19: Instagram + LinkedIn | Q19: FairJob | R19: Começa com um diagnóstico gratuito, segue com uma proposta personalizada e chega à implantação. Comente CUIDADO. | S19: Executive Summary (etapas comerciais). | T19: Não citar prazos de cada etapa sem confirmação. Confirmar o destino do link (www.fairhealth.com.br) e quem responde os comentários e DMs. | U19: Pauta proposta | W19: Reel de 20 a 25 s, motion em 3 passos. 0–3 s: "Como levar o Escritório do Cuidado para a sua empresa?" 3–9 s: PASSO 1 · Diagnóstico gratuito 9–15 s: PASSO 2 · Proposta personalizada 15–20 s: PASSO 3 · Implantação e primeiros atendimentos 20–25 s: "Comente CUIDADO." + logo. | X19: Modelo M2 (passos) animado e M1 no fim.
A20: M1-16 | B20: Mês 1 | C20: 4 | D20: =$D$2+(C20-1)*7+4 | E20: Produto | F20: Liderança Bem-Estar | G20: Convite | H20: Ciência: estilo de vida e diabetes (Dia Mundial do Diabetes, 14/11) | I20: Ciência no cuidado | J20: Estilo de vida também é tratamento sério | K20: Colaboradores; RH; Medicina do Trabalho | L20: Mudar hábitos faz diferença de verdade ou é só conselho? | M20: Mostrar a base científica da MEV com um estudo clássico, na véspera do Dia Mundial do Diabetes | N20: Carrossel | O20: Carrossel "o que a ciência diz": um estudo, uma ideia, a fonte completa. Conecta uma data do calendário ao nosso trabalho com evidência, sem oportunismo. | P20: Instagram + LinkedIn | Q20: FairJob | R20: Num estudo clássico, publicado no New England Journal of Medicine, mudanças de estilo de vida reduziram em 58% os novos casos de diabetes tipo 2 em pessoas com risco, em comparação com o placebo. É por isso que o nosso cuidado começa pela rotina. | S20: Diabetes Prevention Program Research Group. Reduction in the incidence of type 2 diabetes with lifestyle intervention or metformin. N Engl J Med. 2002;346(6):393-403. doi:10.1056/NEJMoa012512 | T20: Responsável médica valida a leitura do estudo. Deixar claro que o estudo foi com adultos com pré-diabetes (risco aumentado) e que não é promessa individual. Número suave: cuidado primeiro, número como contexto, fonte visível e discreta (aba Ciência). | U20: Pauta proposta | W20: 7 slides. 1 Capa: "Estilo de vida também é tratamento sério." 2 Amanhã é o Dia Mundial do Diabetes. Vale lembrar de um estudo que mudou a forma de cuidar. 3 Mais de 3 mil adultos com risco aumentado de diabetes tipo 2 foram acompanhados por quase 3 anos. 4 Quem mudou a rotina (alimentação e 150 minutos de atividade física por semana) teve 58% menos casos novos do que o grupo placebo. 5 Em texto menor: mais do que o grupo que recebeu medicamento (31%). 6 Não é promessa: é a ciência dizendo que a rotina importa. Por isso o nosso cuidado começa nela, com um plano feito para cada pessoa. 7 "O que é importante para você?" Fonte completa: Diabetes Prevention Program, N Engl J Med, 2002. | X20: Modelo M6 (dado com fonte) suave nos slides 4 e 5, M2 nos demais. Números em verde-escuro, sem destaque alarmista.
A21: M2-01 | B21: Mês 2 | C21: 5 | D21: =$D$2+(C21-1)*7+0 | E21: Projetos, eventos e entregas | F21: Stop Loss | G21: Prova | H21: Ciência: prevenção como investimento | I21: Ciência no cuidado | J21: Prevenção também é investimento | K21: RH; Diretoria financeira | L21: Prevenção dá retorno para a empresa ou é só mais um custo? | M21: Mostrar, com estudos externos e a fonte visível, que prevenção também é investimento | N21: Foto única | O21: A arte já está pronta: é o slide de números que saiu do carrossel "O que é a fairhealth" para ele caber em 10 fotos. Um post só dele dá espaço para explicar cada estudo com calma. | P21: Instagram + LinkedIn | Q21: FairJob | R21: O que os estudos apontam: −28% de absenteísmo (Harvard Business Review, 2022) e −22% de custos com saúde (SHRM, 2023). | S21: Harvard Business Review (2022); SHRM (2023). Números oficiais desde 25/09 (instagram/voice.md). | T21: Confirmar o que cada estudo mediu (tipo de programa e população) antes de publicar. São estudos externos, nunca resultado da Fair Health. Número suave: cuidado primeiro, número como contexto, fonte visível e discreta (aba Ciência). | U21: Em revisão | V21: Prevenção também é investimento. Cuidar antes faz bem para as pessoas. E os estudos mostram que também faz diferença para a empresa: −28% de absenteísmo (Harvard Business Review, 2022) −22% de custos com saúde (SHRM, 2023) São números de estudos externos, não uma promessa de resultado. É esse o trabalho da fairhealth: medicina preventiva, dentro da empresa, com um plano de cuidado para cada pessoa. Quer conversar sobre isso na sua empresa? Fale com a gente pelo direct. #fairhealth #saudecorporativa #medicinapreventiva #absenteismo #gestaodepessoas | W21: Foto única 1080x1350, já pronta. Se quisermos explicar melhor cada estudo, vira um carrossel curto: capa, um número por slide com a fonte, fechamento. | X21: Canva: design "O que é a fairhealth · carrossel v7", página guardada depois do carrossel (luz tiffany, números em tiffany, sem brilho). Repositório: instagram/posts/o-que-e-a-fairhealth/png-v10/d10.png. | Z21: Decisão da Nina (12/10): o slide de números saiu do carrossel "O que é a fairhealth" (limite de 10 fotos do Instagram) e vira um post separado.

Sheet Formatos
A1: Formatos do mês: sem time em cena, sem gravar nas empresas-clientes e sem nomes reais
A2: Formato | B2: Como é | C2: Por que funciona | D2: O que precisa para produzir | E2: Cuidados | F2: Onde usamos
A3: Reel de tipografia animada | B3: Frases curtas na tela, uma por vez, sobre o fundo da marca. Trilha calma; voz em off opcional. | C3: Gancho na primeira frase, lido sem som. Não depende de filmagem. Sequências do tipo "antes do..." prendem até o fim. | D3: Texto aprovado, Canva (animação de texto) ou CapCut. 1 a 2 horas. | E3: Frases curtas; no máximo 7 cenas; logo só no fim. | F3: M1-03, M1-11
A4: Explicador animado (motion com ícones) | B4: Conceito explicado com ícones e voz em off, em até 60 s. | C4: Explica um conceito novo (MEV, passos da oferta) mais rápido que um carrossel e circula bem no LinkedIn. | D4: Roteiro aprovado, ícones lineares, voz em off (pode ser gravada pelo celular em local silencioso). | E4: Validação médica de tudo o que for clínico. | F4: M1-05, M1-15
A5: Gravação de tela | B5: Rolagem por um painel ou tela do produto, com texto na tela. | C5: Mostra o produto de verdade sem expor ninguém e responde à dúvida "o que eu recebo?". | D5: Painel com dados fictícios e aviso "dados ilustrativos". | E5: Nunca dado real nem individual. | F5: M1-07
A6: Número contado como história | B6: Primeiro a cena de cuidado, depois o número, em ritmo lento e com a fonte discreta. | C6: O número prova sem tirar o foco do cuidado; o RH leva a prova para a diretoria sem cara de anúncio. | D6: Números liberados (aba Fontes) ou de estudos (aba Ciência). | E6: Sempre agregado; sem nome da empresa; regras de número suave (abaixo). | F6: M1-09
A7: Carrossel "o que a ciência diz" | B7: Um estudo por post: o que foi feito, o que encontrou, o que isso tem a ver com o nosso cuidado, e a referência completa. | C7: Transfere a autoridade da ciência para a marca e educa sem prometer. Conecta datas do calendário ao trabalho sem oportunismo. | D7: Estudo da aba Ciência, lido pela responsável médica. | E7: Explicar para quem o estudo vale; nunca transformar em promessa individual. | F7: M1-14, M1-16
A8: Reel de dicas com imagem de banco | B8: "3 hábitos" com texto na tela sobre imagens de banco. | C8: Dica prática é salva e compartilhada; imagens de banco evitam gravar pessoas. | D8: Banco de imagens (Canva, Pexels) sem rosto identificável. | E8: Sem promessa clínica; validação médica. | F8: M1-13
A9: Carrossel passo a passo | B9: Um passo ou uma objeção por slide, com capa-pergunta. | C9: É o formato mais salvo em conteúdo explicativo e o que já testamos no carrossel de acolhimento. | D9: Modelos M1, M2 e M3 no Canva. | E9: Até 10 slides; uma ideia por slide. | F9: M1-02, M1-10
A10: História com personagem fictícia | B10: Uma personagem inventada (nome, idade, rotina) mostra como o cuidado funciona na prática. | C10: História prende mais que explicação e permite mostrar o plano sem expor ninguém. | D10: Personagem escrita com a responsável médica para ser plausível. | E10: Sinalizar "história ilustrativa, personagem fictícia" no post; nunca apresentar como depoimento. | F10: M1-08
A11: Carrossel-resumo de artigo | B11: As ideias principais de um artigo publicado, com citações literais e link nos stories. | C11: Leva a autoridade do veículo para a marca; muito compartilhado entre profissionais de RH. | D11: Artigo publicado. | E11: Citar só o artigo e o veículo, sem nome do autor; citações literais conferidas. | F11: M1-04
A12: Carrossel comparativo (isto × aquilo) | B12: Duas colunas que contrastam duas ideias. | C12: A diferença fica clara em segundos; ajuda o RH a defender a decisão internamente. | D12: Modelo M1 e comparativo em duas colunas. | E12: Não citar marcas de terceiros. | F12: M1-06
A13: Card de citação | B13: Uma frase em destaque com assinatura. | C13: Fácil de compartilhar nos stories e no LinkedIn; reaproveita conteúdo sem repetir. | D13: Modelo M8. | E13: Citação literal; crédito ao artigo, sem nome de pessoa. | F13: M1-12
A14: Checklist salvável | B14: Perguntas ou itens numerados, um por slide, com convite para salvar. | C14: Conteúdo útil é salvo e repassado à liderança. | D14: Modelo M2 com etiqueta 1/5. | E14: Fonte oficial quando cita norma. | F14: Banco de ideias (NR-1)
A16: Números com suavidade (decisão de 09/10: números sim, foco no cuidado)
A17: Regra | B17: Como fazer | C17: Exemplo | D17: Evitar
A18: Cuidado primeiro | B18: A frase de cuidado abre; o número entra depois, como contexto. | C18: "Ninguém volta a um lugar onde não se sentiu cuidado." → "8 em cada 10 voltaram." | D18: Abrir com o número como manchete.
A19: Um número principal por peça | B19: Os outros números, se houver, vão em texto menor ou na legenda. | C19: M1-09: 8 em cada 10 em destaque; 98% em texto menor. | D19: Painel de números em sequência.
A20: Traduzir em gente | B20: Preferir "8 em cada 10 pessoas" a "81,3%"; arredondar com honestidade. | C20: "Mais de 470 mil licenças" em vez de "472.328". | D20: Casas decimais e jargão estatístico.
A21: Tom calmo | B21: Verde-escuro, ritmo lento, sem efeito de conquista. | C21: Número em Raleway, peso médio, sem seta. | D21: Vermelho, alarme, "explodiu", "recorde assustador".
A22: Fonte sempre | B22: Fonte visível no rodapé e referência completa na aba Ciência ou Fontes. | C22: "Fonte: OMS, 2022." | D22: Número sem fonte ou "estudos mostram".
A23: Sem promessa | B23: O número fala do estudo ou do grupo, nunca do resultado de quem vai ser atendido. | C23: "No estudo, 58% menos casos novos." | D23: "Você vai reduzir 58% do seu risco."

Sheet Ciência
A1: Ciência: estudos e fontes oficiais para posts (sempre com a referência completa)
A2: Estudo ou fonte | B2: Referência completa | C2: O que encontrou | D2: Como apresentar com suavidade | E2: Ligação com o nosso trabalho | F2: Cuidados | G2: Onde usamos
A3: Diabetes Prevention Program (2002) | B3: Diabetes Prevention Program Research Group. Reduction in the incidence of type 2 diabetes with lifestyle intervention or metformin. N Engl J Med. 2002;346(6):393-403. doi:10.1056/NEJMoa012512 | C3: 3.234 adultos com pré-diabetes, acompanhados por 2,8 anos em média: mudança de estilo de vida (alimentação, 7% de perda de peso, 150 min de atividade física por semana) reduziu em 58% os casos novos de diabetes tipo 2 em relação ao placebo; a metformina reduziu 31%. | D3: "Quem mudou a rotina teve 58% menos casos novos." O 31% do medicamento em texto menor. | E3: A base da Medicina do Estilo de Vida: o cuidado começa pela rotina. | F3: Vale para adultos com risco aumentado; não é promessa individual. Validação médica. | G3: M1-16
A4: OMS: diretrizes sobre saúde mental no trabalho (2022) | B4: OMS. Guidelines on mental health at work, 28/09/2022 (com a OIT: policy brief "Mental health at work"). https://www.who.int/news/item/28-09-2022-who-and-ilo-call-for-new-measures-to-tackle-mental-health-issues-at-work | C4: Primeiras diretrizes da OMS sobre o tema. Recomenda, entre outras ações, preparar gestores para prevenir ambientes de estresse e acolher quem está em sofrimento. Com a OIT, estima que depressão e ansiedade custam cerca de 12 bilhões de dias de trabalho por ano no mundo. | D4: Recomendação como gesto simples para o líder; os 12 bilhões de dias, se usados, em texto menor. | E4: Liderança Bem-Estar e NR-1: preparar líderes e cuidar dentro da empresa. | F4: Conferir a redação exata nas diretrizes. | G4: M1-14
A5: Licenças por transtornos mentais no Brasil (2024) | B5: Ministério da Previdência Social: 472.328 licenças por transtornos mentais em 2024, maior número da série iniciada em 2014 (dados divulgados em 2025; conferir no painel oficial de dados abertos antes de publicar). | C5: 472.328 licenças por transtornos mentais em 2024, o maior número da série iniciada em 2014. Ansiedade e depressão lideram. | D5: "Mais de 470 mil licenças. Cada uma teve um antes." Em texto calmo, depois da frase de cuidado. | E5: O eixo "cuidar antes". | F5: Os números divulgados variam entre veículos (440 mil e 472 mil): conferir no painel oficial e citar a fonte primária. | G5: M1-03
A6: Why sleep matters (RAND Europe, 2016) | B6: Hafner M. et al. Why sleep matters: the economic costs of insufficient sleep. RAND Europe, 2016 (RR-1791). https://www.rand.org/news/press/2016/11/30.html | C6: Sono insuficiente custa até 2,28% do PIB dos EUA e cerca de 1,2 milhão de dias de trabalho por ano; dormir menos de 6 horas está associado a risco de mortalidade 13% maior do que dormir de 7 a 9 horas. | D6: Usar a faixa saudável (7 a 9 horas) para o colaborador; o custo em dias de trabalho só para o RH, na legenda do LinkedIn. | E6: Pilar sono. | F6: Estimativas modeladas ("até"); evitar o dado de mortalidade em post para colaborador. | G6: M1-13
A7: Global Burden of Disease 2019 (citado no artigo da RH Pra Você) | B7: GBD 2019 Mental Disorders Collaborators; artigo na Revista Brasileira de Epidemiologia (SciELO): https://www.scielo.br/j/rbepid/a/cwDkPDjSkDcC3hB73kp7yfC/ | C7: Pessoas vivendo com 12 transtornos mentais em 204 países: de 654,8 milhões (1990) para 970,1 milhões (2019), +48,1%. | D7: "Quase 1 bilhão de pessoas", em texto menor, como contexto. | E7: Saúde mental é multifatorial; a empresa cuida da parte dela. | F7: Citar a fonte primária. | G7: M1-04
A8: Atividade física e saúde mental (Singh et al., 2023) | B8: Singh B. et al. Effectiveness of physical activity interventions for improving depression, anxiety and distress: an overview of systematic reviews. Br J Sports Med. 2023. doi:10.1136/bjsports-2022-106195 | C8: Revisão de 97 revisões (1.039 estudos, mais de 128 mil participantes): atividade física teve efeito moderado na redução de sintomas de depressão, ansiedade e sofrimento psicológico. | D8: "Mexer o corpo também cuida da mente", com o efeito descrito em palavras, sem número. | E8: Pilar atividade física e manejo do estresse. | F8: Não usar o "1,5 vez melhor que remédio" da imprensa: não está no resumo do artigo. | G8: Banco de ideias
A9: Relações sociais e mortalidade (Holt-Lunstad et al., 2010) | B9: Holt-Lunstad J., Smith T.B., Layton J.B. Social relationships and mortality risk: a meta-analytic review. PLoS Med. 2010;7(7):e1000316. doi:10.1371/journal.pmed.1000316 | C9: 148 estudos, 308.849 participantes: relações sociais mais fortes associadas a maior chance de sobrevivência (razão de chances 1,50), efeito comparável a fatores de risco conhecidos. | D9: "Vínculos também são saúde", sem o número na peça para colaborador. | E9: Pilar relacionamentos; ambiente de trabalho. | F9: Evitar o "equivale a 15 cigarros por dia" da imprensa: não está no artigo. | G9: Banco de ideias
A10: Estressores no trabalho, mortalidade e custos (Goh, Pfeffer e Zenios, 2016) | B10: Goh J., Pfeffer J., Zenios S.A. The relationship between workplace stressors and mortality and health costs in the United States. Management Science. 2016;62(2):608-628. doi:10.1287/mnsc.2014.2115 | C10: Modelo com 10 estressores do trabalho (jornadas longas, insegurança, baixa autonomia, conflito trabalho-família, entre outros) estima mais de 120 mil mortes por ano e de 5% a 8% dos gastos com saúde nos EUA. | D10: Para o RH: "o jeito de trabalhar também entra na conta da saúde", número em texto menor. | E10: NR-1 e riscos psicossociais; Stop Loss. | F10: Conferir os números no artigo original antes de usar (vieram de resumos). | G10: Banco de ideias

Sheet Fontes
A1: Fontes internas, o artigo e o que não usar (nomes de clientes só para uso interno, nunca no post)
A2: Fonte | B2: O que diz | C2: Como usar | D2: Situação | E2: Onde usamos
A3: Artigo "Riscos psicossociais no ambiente de trabalho e saúde" (RH Pra Você, 25/09/2026) | B3: Desde maio de 2026 a NR-1 exige que as empresas identifiquem, avaliem e gerenciem os riscos psicossociais; o trabalho pode adoecer, mas não é o único vilão; a empresa responde pelo ambiente que constrói, mas não controla todas as variáveis; responsabilidade compartilhada (poder público, sociedade, empresas e indivíduo); "Saúde mental é, ao mesmo tempo, de cada um e de todos." URL: https://rhpravoce.com.br/colab/riscos-psicossociais-no-ambiente-de-trabalho-2 | C3: Resumo em carrossel, card de citação, link nos stories. Citar só o artigo e o veículo, sem nome do autor. Citações sempre literais. | D3: Publicado. | E3: M1-04, M1-12
A4: Cliente do setor industrial, 1º semestre de 2026 (uso interno: Chemitec) | B4: 161 atendimentos, 48 colaboradores atendidos (98% de adesão), 81,3% voltaram para 2 ou mais atendimentos, 46 smartbands em uso. | C4: Sempre agregado e como "uma indústria". Nunca o nome da empresa. | D4: Liberado (instagram/voice.md). | E4: M1-09
A5: Hospital onde o modelo começou, 2025 (uso interno: Hospital Dia Santo Amaro) | B5: Reclamações mensais de 34 para cerca de 20 (cerca de 40% a menos); conformidade média de 98,2%; apresentado em congresso internacional. | C5: História de origem e prova do modelo, sem o nome do hospital. | D5: Liberado (instagram/voice.md). | E5: Banco de ideias
A6: Harvard Business Review (2022) e SHRM (2023) | B6: −28% de absenteísmo (HBR 2022); −22% de custos com saúde (SHRM 2023). | C6: Argumento de retorno, sempre com a fonte. Post próprio em 16/11 (saiu do carrossel "O que é a fairhealth"). | D6: Liberado (instagram/voice.md). Falta confirmar o que cada estudo mediu. | E6: M2-01
A7: ACLM e CBMEV | B7: Definição de Medicina do Estilo de Vida e seus 6 pilares: alimentação, atividade física, sono, manejo do estresse, relacionamentos e evitar substâncias de risco. | C7: Base do explicador de MEV. | D7: Responsável médica confere. Espiritualidade fora (a confirmar). | E7: M1-05
A8: Não usar | B8: "23% mais caro", "R$ 2.400 por colaborador", "maior índice de burnout" (sem fonte no posicionamento); −27%, "R$ 2,70 por R$ 1" e "70% dos custos do plano"; "validado no SUS" até confirmar. | C8: — | D8: Bloqueado até ter fonte. | E8: —

Sheet Banco de ideias
A1: Banco de ideias: o que ficou para depois e os próximos meses
A2: Ideia | B2: Origem | C2: Status | D2: Motivo / o que destrava | E2: Próximo uso sugerido
A3: Série Quem cuida (apresentação de cada integrante do time) | B3: Calendário de 90 dias | C3: Adiada | D3: Não vamos apresentar o time por agora (questão administrativa). As capas já feitas ficam guardadas em instagram/posts/time. | E3: Quando a questão for resolvida
A4: Um dia no Escritório do Cuidado (vídeo no espaço) | B4: Calendário de 90 dias (M1-03) | C4: Adiada | D4: Não podemos filmar clientes: o espaço fica dentro das empresas-clientes. | E4: Recriar em local próprio ou em motion
A5: Bastidores de uma implantação | B5: Calendário de 90 dias (M2-01) | C5: Adiada | D5: Mesmo motivo: gravação dentro da empresa-cliente. | E5: Versão em motion, com empresa fictícia
A6: Depoimentos em vídeo e por escrito | B6: Calendário de 90 dias (M2-10, M3-03) | C6: Adiada | D6: Não podemos filmar clientes; nunca nomes; limites do CFM para depoimentos. | E6: Trocar por histórias com personagem fictícia
A7: Workshops nos pilares (fotos reais) | B7: Calendário de 90 dias (M1-06, M2-13) | C7: Aguardando material | D7: Fotos de encontros expõem clientes. Possível versão só com materiais e slides do workshop. | E7: Mês de Ambiente positivo
A8: Registro do mês | B8: Calendário de 90 dias | C8: Aguardando pauta | D8: Depende da agenda de eventos e entregas. | E8: Quando houver evento próprio
A9: Checklist "Antes de preencher a planilha: 5 perguntas sobre riscos psicossociais" | B9: Mês 1 (versão de 09/10) | C9: Ideia | D9: Saiu do Mês 1 para dar lugar ao post de ciência do Dia Mundial do Diabetes. Abre bem o mês da NR-1. | E9: Mês 2, semana 1
A10: Série NR-1 (contexto, diagnóstico, cuidado individualizado, acompanhamento, versão para colaboradores) | B10: Plano mensal (Mês 2) | C10: Ideia | D10: Próximo capítulo. O artigo da RH Pra Você já abre o tema. Estudo de Goh, Pfeffer e Zenios (aba Ciência) para o RH. | E10: Mês 2
A11: Série "Ciência no cuidado": um estudo por mês ligado ao pilar ou ao argumento do mês | B11: Decisão de 09/10 | C11: Ideia | D11: Estudos na aba Ciência: atividade física e saúde mental (Singh, 2023), relações sociais (Holt-Lunstad, 2010), estressores do trabalho (Goh, 2016), OMS (12 bilhões de dias). | E11: Todo mês
A12: "O que nos diferencia": plano de saúde, plataformas de bem-estar e QVT (3 posts) | B12: Posicionamento v3.2 | C12: Ideia | D12: Falar da categoria, sem citar marcas. | E12: Mês 2 ou 3
A13: "Quem cuida também precisa de cuidado" (edição especial para a saúde) | B13: Posicionamento v3.2 (arenas) | C13: Ideia | D13: Liga a origem hospitalar ao cuidado de quem cuida. | E13: Mês 3
... A17: Indicadores para o RH (HBR 2022, SHRM 2023) | B17: voice.md (liberado) | C17: Pauta proposta | D17: Virou o post M2-01 "Prevenção também é investimento" (arte pronta, saiu do carrossel "O que é a fairhealth" em 12/10). | E17: Mês 2, semana 1 (M2-01)

Sheet Linhas e personas
A1: Linhas editoriais
A2: Linha | B2: O que entra | C2: Objetivos típicos | D2: Formatos que funcionam agora | E2: Peso no mês
A3: Institucional | B3: O que é a Fair Health, por que existe, de onde veio (Escritório do Paciente → Escritório do Cuidado, ecossistema FairJob) e em que acredita ("cuidar antes", "não é benefício, é infraestrutura de cuidado"). | C3: Apresentar, gerar confiança, fixar a tese. | D3: Tipografia animada, linha do tempo, comparativo, card de pergunta. | E3: Cerca de 1/3
A4: Produto | B4: Escritório do Cuidado (percurso, sigilo), Medicina do Estilo de Vida e os pilares, plano individualizado, tecnologia e temas do entorno (NR-1, saúde mental) quando a ligação com a oferta é clara. | C4: Explicar, educar com rigor, tirar dúvidas, levar à conversa comercial. | D4: Carrossel passo a passo, explicador animado, checklist, dicas com imagem de banco. | E4: Cerca de 1/3 a 2/5
A5: Projetos, eventos e entregas | B5: O que a Fair Health está fazendo e entregando: números liberados, entregas para o RH, participações na imprensa e em eventos, como chega a uma empresa. | C5: Provar, mostrar movimento, gerar autoridade. | D5: Dado animado, gravação de tela, resumo de artigo, card de citação. | E5: Cerca de 1/4 a 1/3
A7: Personas (posicionamento v3.2)
A8: Persona | B8: Quem é | C8: Dor de entrada | D8: Como falar | E8: Cuidados
A9: RH | B9: CHROs, gerentes de pessoas e business partners de empresas de médio e grande porte, principalmente indústria. Público principal. | C9: Como atender à NR-1 de um jeito que mude algo? Meu programa tem adesão? O que eu recebo? Como começar? | D9: Assertivo e pragmático, com processo e evidência. | E9: Números só liberados e com fonte.
A10: Lideranças | B10: Gestores e líderes de equipe. | C10: Como cuidar do time no dia a dia sem ser médico nem psicólogo? | D10: Direto, com perguntas práticas. | E10: Não transferir ao líder a responsabilidade clínica.
A11: Colaboradores | B11: Quem é ou pode ser atendido pelo Escritório do Cuidado. | C11: Vou ser julgado? O que eu contar fica entre nós? Cabe na minha rotina? | D11: Acolhedor, em segunda pessoa, sem números de negócio. | E11: Nunca expor quem é atendido.
A12: Medicina do Trabalho | B12: Médicos do trabalho e equipes de SST. | C12: Isso substitui ou complementa o que já fazemos? | D12: Técnico, com fontes e precisão. | E12: Validação da responsável médica.
A13: Risco e Compliance | B13: Áreas de risco, compliance e jurídico. | C13: Como documentar e acompanhar os riscos psicossociais? | D13: Objetivo, com a norma e a fonte. | E13: Não prometer conformidade.
A14: Diretoria financeira | B14: Diretoria financeira. | C14: Qual o retorno? O que muda na sinistralidade? | D14: Indicadores com fonte, sem promessa. | E14: Argumento de retorno no mês de Stop Loss.
A15: RI e C-Level | B15: C-Level e relações com investidores (ESG). | C15: Como o cuidado aparece nos indicadores da empresa? | D15: Estratégico, curto. | E15: Sem números sem fonte.

Sheet Pendências
A1: Pendências e validações
A2: # | B2: Pendência | C2: Quem confirma | D2: Pautas afetadas | E2: Situação
A3: 1 | B3: Questão administrativa que adia a apresentação do time: previsão para retomar a série Quem cuida. | C3: Sócios | D3: Banco de ideias | E3: Aberta
A4: 2 | B4: Onde gravar o vídeo de abertura sem time e sem empresa-cliente (local próprio ou neutro) ou montar com fotos e tipografia. | C4: Comunicação | D4: M1-01 | E4: Aberta
A5: 3 | B5: Assistentes sociais fazem parte do atendimento? (o posicionamento cita médico e psicológico) | C5: Time Fair Health | D5: M1-01 | E5: Aberta
