Workbook

Sheet Como usar
A1: Programação do Instagram da fairhealth · 19/10 a 13/11
A2: 12 posts em 4 semanas, 3 por semana (1 reel e 2 posts estáticos). Versão de 14/10/2026. A mesma programação está em PowerPoint: marketing/Programacao_Instagram_19-10_a_13-11_v4.pptx.
A4: Abas
A5: Cronograma: a lista dos 12 posts com data, formato e status, os prazos de roteiro, criação e aprovação e um gráfico de barras dia a dia. É a aba principal: as outras puxam os dados dela.
A6: Calendário: o mês em formato de calendário, com uma cor por formato (Reel em Tiffany, Carrossel em verde, Foto única em branco).
A7: Posts: a ficha completa de cada post: subtítulo, gancho, objetivo, o que estamos dizendo por trás, fio da história, direção visual, material, legenda pronta, stories de apoio, fonte e validação.
A8: Roteiros: cada reel cena por cena (tempo, texto na tela, fala e visual) e cada carrossel slide por slide.
A9: Blocos: os 4 blocos (Reconhecimento, Relevância, Compreensão e Confiança), com a pergunta e o intuito de cada um.
A10: Validações: o que precisa de aval antes de publicar, com quem confirma e a situação.
A11: Listas: feriados, datas especiais e os valores das listas suspensas.
A13: Como editar
A14: Células amarelas (aba Cronograma, linha 2): a data de início do mês e os prazos de roteiro, criação e aprovação, em dias úteis antes da publicação. Mude ali e todos os prazos se ajustam.
... A25: marketing/calendario-12-posts.md · instagram/essencia.md · instagram/voice.md · instagram/posts/nossa-historia/README.md · planilha do calendário editorial (roteiros de 09/10 a 13/10).

Sheet Cronograma
A1: Cronograma de produção e publicação · 19/10 a 13/11 · 12 posts, 3 por semana
A2: Início do mês | B2: 46314 | D2: Roteiro: dias úteis antes | F2: 5 | G2: Criação (arte ou gravação): dias úteis antes | H2: 2 | I2: Aprovação: dias úteis antes | J2: 1
A3: Barras do cronograma: R roteiro · C criação (arte ou gravação) · A aprovação · P publicação. Os prazos descontam fins de semana e feriados (aba Listas). | M3: =CHOOSE(WEEKDAY(M4,2),"S","T","Q","Q","S","S","D") -> S | N3: =CHOOSE(WEEKDAY(N4,2),"S","T","Q","Q","S","S","D") -> T | O3: =CHOOSE(WEEKDAY(O4,2),"S","T","Q","Q","S","S","D") -> Q | P3: =CHOOSE(WEEKDAY(P4,2),"S","T","Q","Q","S","S","D") -> Q | Q3: =CHOOSE(WEEKDAY(Q4,2),"S","T","Q","Q","S","S","D") -> S | R3: =CHOOSE(WEEKDAY(R4,2),"S","T","Q","Q","S","S","D") -> S | S3: =CHOOSE(WEEKDAY(S4,2),"S","T","Q","Q","S","S","D") -> D | T3: =CHOOSE(WEEKDAY(T4,2),"S","T","Q","Q","S","S","D") -> S | ... AU3: =CHOOSE(WEEKDAY(AU4,2),"S","T","Q","Q","S","S","D") -> D
A4: ID | B4: Publicação | C4: Dia | D4: Semana | E4: Bloco | F4: Formato | G4: Título | H4: Roteiro até | I4: Criação até | J4: Aprovação até | K4: Status | L4: Responsável | M4: =$B$2-7 -> 46307 | N4: =M4+1 -> 46308 | O4: =N4+1 -> 46309 | P4: =O4+1 -> 46310 | Q4: =P4+1 -> 46311 | R4: =Q4+1 -> 46312 | S4: =R4+1 -> 46313 | T4: =S4+1 -> 46314 | U4: =T4+1 -> 46315 | ... AU4: =AT4+1 -> 46341
A5: P01 | B5: 46314 | C5: =CHOOSE(WEEKDAY(B5,2),"seg","ter","qua","qui","sex","sáb","dom") -> seg | D5: =INT((B5-$B$2)/7)+1 -> 1 | E5: 1 · Reconhecimento | F5: Reel | G5: Quem somos, na voz do Dr. Ronald | H5: 46309 | I5: 46310 | J5: =WORKDAY(B5,-$J$2,Listas!$A$3:$A$6) -> 46311 | K5: Roteiro em revisão | M5: =IF(M$4=$B5,"P",IF(M$4=$J5,"A",IF(M$4=$I5,"C",IF(M$4=$H5,"R","")))) | N5: =IF(N$4=$B5,"P",IF(N$4=$J5,"A",IF(N$4=$I5,"C",IF(N$4=$H5,"R","")))) | O5: =IF(O$4=$B5,"P",IF(O$4=$J5,"A",IF(O$4=$I5,"C",IF(O$4=$H5,"R","")))) -> R | P5: =IF(P$4=$B5,"P",IF(P$4=$J5,"A",IF(P$4=$I5,"C",IF(P$4=$H5,"R","")))) -> C | Q5: =IF(Q$4=$B5,"P",IF(Q$4=$J5,"A",IF(Q$4=$I5,"C",IF(Q$4=$H5,"R","")))) -> A | R5: =IF(R$4=$B5,"P",IF(R$4=$J5,"A",IF(R$4=$I5,"C",IF(R$4=$H5,"R","")))) | S5: =IF(S$4=$B5,"P",IF(S$4=$J5,"A",IF(S$4=$I5,"C",IF(S$4=$H5,"R","")))) | T5: =IF(T$4=$B5,"P",IF(T$4=$J5,"A",IF(T$4=$I5,"C",IF(T$4=$H5,"R","")))) -> P | ... AU5: =IF(AU$4=$B5,"P",IF(AU$4=$J5,"A",IF(AU$4=$I5,"C",IF(AU$4=$H5,"R",""))))
A6: P02 | B6: 46316 | C6: =CHOOSE(WEEKDAY(B6,2),"seg","ter","qua","qui","sex","sáb","dom") -> qua | D6: =INT((B6-$B$2)/7)+1 -> 1 | E6: 1 · Reconhecimento | F6: Carrossel | G6: Por que a FairHealth existe? | H6: =WORKDAY(B6,-$F$2,Listas!$A$3:$A$6) -> 46309 | I6: =WORKDAY(B6,-$H$2,Listas!$A$3:$A$6) -> 46314 | J6: =WORKDAY(B6,-$J$2,Listas!$A$3:$A$6) -> 46315 | K6: Arte pronta | M6: =IF(M$4=$B6,"P",IF(M$4=$J6,"A",IF(M$4=$I6,"C",IF(M$4=$H6,"R","")))) | N6: =IF(N$4=$B6,"P",IF(N$4=$J6,"A",IF(N$4=$I6,"C",IF(N$4=$H6,"R","")))) | O6: =IF(O$4=$B6,"P",IF(O$4=$J6,"A",IF(O$4=$I6,"C",IF(O$4=$H6,"R","")))) -> R | P6: =IF(P$4=$B6,"P",IF(P$4=$J6,"A",IF(P$4=$I6,"C",IF(P$4=$H6,"R","")))) | Q6: =IF(Q$4=$B6,"P",IF(Q$4=$J6,"A",IF(Q$4=$I6,"C",IF(Q$4=$H6,"R","")))) | R6: =IF(R$4=$B6,"P",IF(R$4=$J6,"A",IF(R$4=$I6,"C",IF(R$4=$H6,"R","")))) | S6: =IF(S$4=$B6,"P",IF(S$4=$J6,"A",IF(S$4=$I6,"C",IF(S$4=$H6,"R","")))) | T6: =IF(T$4=$B6,"P",IF(T$4=$J6,"A",IF(T$4=$I6,"C",IF(T$4=$H6,"R","")))) -> C | ... AU6: =IF(AU$4=$B6,"P",IF(AU$4=$J6,"A",IF(AU$4=$I6,"C",IF(AU$4=$H6,"R",""))))
A7: P03 | B7: 46318 | C7: =CHOOSE(WEEKDAY(B7,2),"seg","ter","qua","qui","sex","sáb","dom") -> sex | D7: =INT((B7-$B$2)/7)+1 -> 1 | E7: 2 · Relevância | F7: Carrossel | G7: Cuidar da saúde não deveria começar quando algo vai mal | H7: =WORKDAY(B7,-$F$2,Listas!$A$3:$A$6) -> 46311 | I7: =WORKDAY(B7,-$H$2,Listas!$A$3:$A$6) -> 46316 | J7: =WORKDAY(B7,-$J$2,Listas!$A$3:$A$6) -> 46317 | K7: Roteiro em revisão | M7: =IF(M$4=$B7,"P",IF(M$4=$J7,"A",IF(M$4=$I7,"C",IF(M$4=$H7,"R","")))) | N7: =IF(N$4=$B7,"P",IF(N$4=$J7,"A",IF(N$4=$I7,"C",IF(N$4=$H7,"R","")))) | O7: =IF(O$4=$B7,"P",IF(O$4=$J7,"A",IF(O$4=$I7,"C",IF(O$4=$H7,"R","")))) | P7: =IF(P$4=$B7,"P",IF(P$4=$J7,"A",IF(P$4=$I7,"C",IF(P$4=$H7,"R","")))) | Q7: =IF(Q$4=$B7,"P",IF(Q$4=$J7,"A",IF(Q$4=$I7,"C",IF(Q$4=$H7,"R","")))) -> R | R7: =IF(R$4=$B7,"P",IF(R$4=$J7,"A",IF(R$4=$I7,"C",IF(R$4=$H7,"R","")))) | S7: =IF(S$4=$B7,"P",IF(S$4=$J7,"A",IF(S$4=$I7,"C",IF(S$4=$H7,"R","")))) | T7: =IF(T$4=$B7,"P",IF(T$4=$J7,"A",IF(T$4=$I7,"C",IF(T$4=$H7,"R","")))) | ... AU7: =IF(AU$4=$B7,"P",IF(AU$4=$J7,"A",IF(AU$4=$I7,"C",IF(AU$4=$H7,"R",""))))
A8: P04 | B8: 46321 | C8: =CHOOSE(WEEKDAY(B8,2),"seg","ter","qua","qui","sex","sáb","dom") -> seg | D8: =INT((B8-$B$2)/7)+1 -> 2 | E8: 2 · Relevância | F8: Reel | G8: O que acontece quando o cuidado não faz parte da rotina? | H8: =WORKDAY(B8,-$F$2,Listas!$A$3:$A$6) -> 46314 | I8: =WORKDAY(B8,-$H$2,Listas!$A$3:$A$6) -> 46317 | J8: =WORKDAY(B8,-$J$2,Listas!$A$3:$A$6) -> 46318 | K8: Roteiro em revisão | M8: =IF(M$4=$B8,"P",IF(M$4=$J8,"A",IF(M$4=$I8,"C",IF(M$4=$H8,"R","")))) | N8: =IF(N$4=$B8,"P",IF(N$4=$J8,"A",IF(N$4=$I8,"C",IF(N$4=$H8,"R","")))) | O8: =IF(O$4=$B8,"P",IF(O$4=$J8,"A",IF(O$4=$I8,"C",IF(O$4=$H8,"R","")))) | P8: =IF(P$4=$B8,"P",IF(P$4=$J8,"A",IF(P$4=$I8,"C",IF(P$4=$H8,"R","")))) | Q8: =IF(Q$4=$B8,"P",IF(Q$4=$J8,"A",IF(Q$4=$I8,"C",IF(Q$4=$H8,"R","")))) | R8: =IF(R$4=$B8,"P",IF(R$4=$J8,"A",IF(R$4=$I8,"C",IF(R$4=$H8,"R","")))) | S8: =IF(S$4=$B8,"P",IF(S$4=$J8,"A",IF(S$4=$I8,"C",IF(S$4=$H8,"R","")))) | T8: =IF(T$4=$B8,"P",IF(T$4=$J8,"A",IF(T$4=$I8,"C",IF(T$4=$H8,"R","")))) -> R | ... AU8: =IF(AU$4=$B8,"P",IF(AU$4=$J8,"A",IF(AU$4=$I8,"C",IF(AU$4=$H8,"R",""))))
A9: P05 | B9: 46323 | C9: =CHOOSE(WEEKDAY(B9,2),"seg","ter","qua","qui","sex","sáb","dom") -> qua | D9: =INT((B9-$B$2)/7)+1 -> 2 | E9: 2 · Relevância | F9: Foto única | G9: Prevenção também é investimento | H9: =WORKDAY(B9,-$F$2,Listas!$A$3:$A$6) -> 46316 | I9: =WORKDAY(B9,-$H$2,Listas!$A$3:$A$6) -> 46321 | J9: =WORKDAY(B9,-$J$2,Listas!$A$3:$A$6) -> 46322 | K9: Arte pronta | M9: =IF(M$4=$B9,"P",IF(M$4=$J9,"A",IF(M$4=$I9,"C",IF(M$4=$H9,"R","")))) | N9: =IF(N$4=$B9,"P",IF(N$4=$J9,"A",IF(N$4=$I9,"C",IF(N$4=$H9,"R","")))) | O9: =IF(O$4=$B9,"P",IF(O$4=$J9,"A",IF(O$4=$I9,"C",IF(O$4=$H9,"R","")))) | P9: =IF(P$4=$B9,"P",IF(P$4=$J9,"A",IF(P$4=$I9,"C",IF(P$4=$H9,"R","")))) | Q9: =IF(Q$4=$B9,"P",IF(Q$4=$J9,"A",IF(Q$4=$I9,"C",IF(Q$4=$H9,"R","")))) | R9: =IF(R$4=$B9,"P",IF(R$4=$J9,"A",IF(R$4=$I9,"C",IF(R$4=$H9,"R","")))) | S9: =IF(S$4=$B9,"P",IF(S$4=$J9,"A",IF(S$4=$I9,"C",IF(S$4=$H9,"R","")))) | T9: =IF(T$4=$B9,"P",IF(T$4=$J9,"A",IF(T$4=$I9,"C",IF(T$4=$H9,"R","")))) | ... AU9: =IF(AU$4=$B9,"P",IF(AU$4=$J9,"A",IF(AU$4=$I9,"C",IF(AU$4=$H9,"R",""))))
A10: P06 | B10: 46325 | C10: =CHOOSE(WEEKDAY(B10,2),"seg","ter","qua","qui","sex","sáb","dom") -> sex | D10: =INT((B10-$B$2)/7)+1 -> 2 | E10: 2 · Relevância | F10: Carrossel | G10: Como transformar a prevenção em parte da rotina de uma empresa? | H10: =WORKDAY(B10,-$F$2,Listas!$A$3:$A$6) -> 46318 | I10: =WORKDAY(B10,-$H$2,Listas!$A$3:$A$6) -> 46323 | J10: =WORKDAY(B10,-$J$2,Listas!$A$3:$A$6) -> 46324 | K10: Roteiro em revisão | M10: =IF(M$4=$B10,"P",IF(M$4=$J10,"A",IF(M$4=$I10,"C",IF(M$4=$H10,"R","")))) | N10: =IF(N$4=$B10,"P",IF(N$4=$J10,"A",IF(N$4=$I10,"C",IF(N$4=$H10,"R","")))) | O10: =IF(O$4=$B10,"P",IF(O$4=$J10,"A",IF(O$4=$I10,"C",IF(O$4=$H10,"R","")))) | P10: =IF(P$4=$B10,"P",IF(P$4=$J10,"A",IF(P$4=$I10,"C",IF(P$4=$H10,"R","")))) | Q10: =IF(Q$4=$B10,"P",IF(Q$4=$J10,"A",IF(Q$4=$I10,"C",IF(Q$4=$H10,"R","")))) | R10: =IF(R$4=$B10,"P",IF(R$4=$J10,"A",IF(R$4=$I10,"C",IF(R$4=$H10,"R","")))) | S10: =IF(S$4=$B10,"P",IF(S$4=$J10,"A",IF(S$4=$I10,"C",IF(S$4=$H10,"R","")))) | T10: =IF(T$4=$B10,"P",IF(T$4=$J10,"A",IF(T$4=$I10,"C",IF(T$4=$H10,"R","")))) | ... AU10: =IF(AU$4=$B10,"P",IF(AU$4=$J10,"A",IF(AU$4=$I10,"C",IF(AU$4=$H10,"R",""))))
A11: P07 | B11: 46329 | C11: =CHOOSE(WEEKDAY(B11,2),"seg","ter","qua","qui","sex","sáb","dom") -> ter | D11: =INT((B11-$B$2)/7)+1 -> 3 | E11: 3 · Compreensão | F11: Carrossel | G11: Como funciona o cuidado na prática? | H11: =WORKDAY(B11,-$F$2,Listas!$A$3:$A$6) -> 46321 | I11: =WORKDAY(B11,-$H$2,Listas!$A$3:$A$6) -> 46324 | J11: =WORKDAY(B11,-$J$2,Listas!$A$3:$A$6) -> 46325 | K11: Aguardando decisão | M11: =IF(M$4=$B11,"P",IF(M$4=$J11,"A",IF(M$4=$I11,"C",IF(M$4=$H11,"R","")))) | N11: =IF(N$4=$B11,"P",IF(N$4=$J11,"A",IF(N$4=$I11,"C",IF(N$4=$H11,"R","")))) | O11: =IF(O$4=$B11,"P",IF(O$4=$J11,"A",IF(O$4=$I11,"C",IF(O$4=$H11,"R","")))) | P11: =IF(P$4=$B11,"P",IF(P$4=$J11,"A",IF(P$4=$I11,"C",IF(P$4=$H11,"R","")))) | Q11: =IF(Q$4=$B11,"P",IF(Q$4=$J11,"A",IF(Q$4=$I11,"C",IF(Q$4=$H11,"R","")))) | R11: =IF(R$4=$B11,"P",IF(R$4=$J11,"A",IF(R$4=$I11,"C",IF(R$4=$H11,"R","")))) | S11: =IF(S$4=$B11,"P",IF(S$4=$J11,"A",IF(S$4=$I11,"C",IF(S$4=$H11,"R","")))) | T11: =IF(T$4=$B11,"P",IF(T$4=$J11,"A",IF(T$4=$I11,"C",IF(T$4=$H11,"R","")))) | ... AU11: =IF(AU$4=$B11,"P",IF(AU$4=$J11,"A",IF(AU$4=$I11,"C",IF(AU$4=$H11,"R",""))))
A12: P08 | B12: 46330 | C12: =CHOOSE(WEEKDAY(B12,2),"seg","ter","qua","qui","sex","sáb","dom") -> qua | D12: =INT((B12-$B$2)/7)+1 -> 3 | E12: 3 · Compreensão | F12: Reel | G12: Quatro frentes, um cuidado conectado | H12: =WORKDAY(B12,-$F$2,Listas!$A$3:$A$6) -> 46322 | I12: =WORKDAY(B12,-$H$2,Listas!$A$3:$A$6) -> 46325 | J12: =WORKDAY(B12,-$J$2,Listas!$A$3:$A$6) -> 46329 | K12: Roteiro em revisão | M12: =IF(M$4=$B12,"P",IF(M$4=$J12,"A",IF(M$4=$I12,"C",IF(M$4=$H12,"R","")))) | N12: =IF(N$4=$B12,"P",IF(N$4=$J12,"A",IF(N$4=$I12,"C",IF(N$4=$H12,"R","")))) | O12: =IF(O$4=$B12,"P",IF(O$4=$J12,"A",IF(O$4=$I12,"C",IF(O$4=$H12,"R","")))) | P12: =IF(P$4=$B12,"P",IF(P$4=$J12,"A",IF(P$4=$I12,"C",IF(P$4=$H12,"R","")))) | Q12: =IF(Q$4=$B12,"P",IF(Q$4=$J12,"A",IF(Q$4=$I12,"C",IF(Q$4=$H12,"R","")))) | R12: =IF(R$4=$B12,"P",IF(R$4=$J12,"A",IF(R$4=$I12,"C",IF(R$4=$H12,"R","")))) | S12: =IF(S$4=$B12,"P",IF(S$4=$J12,"A",IF(S$4=$I12,"C",IF(S$4=$H12,"R","")))) | T12: =IF(T$4=$B12,"P",IF(T$4=$J12,"A",IF(T$4=$I12,"C",IF(T$4=$H12,"R","")))) | ... AU12: =IF(AU$4=$B12,"P",IF(AU$4=$J12,"A",IF(AU$4=$I12,"C",IF(AU$4=$H12,"R",""))))
A13: P09 | B13: 46332 | C13: =CHOOSE(WEEKDAY(B13,2),"seg","ter","qua","qui","sex","sáb","dom") -> sex | D13: =INT((B13-$B$2)/7)+1 -> 3 | E13: 4 · Confiança | F13: Carrossel | G13: Uma história de cuidado que começou em 2009 | H13: =WORKDAY(B13,-$F$2,Listas!$A$3:$A$6) -> 46324 | I13: =WORKDAY(B13,-$H$2,Listas!$A$3:$A$6) -> 46330 | J13: =WORKDAY(B13,-$J$2,Listas!$A$3:$A$6) -> 46331 | K13: Roteiro em revisão | M13: =IF(M$4=$B13,"P",IF(M$4=$J13,"A",IF(M$4=$I13,"C",IF(M$4=$H13,"R","")))) | N13: =IF(N$4=$B13,"P",IF(N$4=$J13,"A",IF(N$4=$I13,"C",IF(N$4=$H13,"R","")))) | O13: =IF(O$4=$B13,"P",IF(O$4=$J13,"A",IF(O$4=$I13,"C",IF(O$4=$H13,"R","")))) | P13: =IF(P$4=$B13,"P",IF(P$4=$J13,"A",IF(P$4=$I13,"C",IF(P$4=$H13,"R","")))) | Q13: =IF(Q$4=$B13,"P",IF(Q$4=$J13,"A",IF(Q$4=$I13,"C",IF(Q$4=$H13,"R","")))) | R13: =IF(R$4=$B13,"P",IF(R$4=$J13,"A",IF(R$4=$I13,"C",IF(R$4=$H13,"R","")))) | S13: =IF(S$4=$B13,"P",IF(S$4=$J13,"A",IF(S$4=$I13,"C",IF(S$4=$H13,"R","")))) | T13: =IF(T$4=$B13,"P",IF(T$4=$J13,"A",IF(T$4=$I13,"C",IF(T$4=$H13,"R","")))) | ... AU13: =IF(AU$4=$B13,"P",IF(AU$4=$J13,"A",IF(AU$4=$I13,"C",IF(AU$4=$H13,"R",""))))
A14: P10 | B14: 46335 | C14: =CHOOSE(WEEKDAY(B14,2),"seg","ter","qua","qui","sex","sáb","dom") -> seg | D14: =INT((B14-$B$2)/7)+1 -> 4 | E14: 4 · Confiança | F14: Reel | G14: Cuidado na prática: experiências e resultados reais | H14: 46309 | I14: 46310 | J14: =WORKDAY(B14,-$J$2,Listas!$A$3:$A$6) -> 46332 | K14: Roteiro em revisão | M14: =IF(M$4=$B14,"P",IF(M$4=$J14,"A",IF(M$4=$I14,"C",IF(M$4=$H14,"R","")))) | N14: =IF(N$4=$B14,"P",IF(N$4=$J14,"A",IF(N$4=$I14,"C",IF(N$4=$H14,"R","")))) | O14: =IF(O$4=$B14,"P",IF(O$4=$J14,"A",IF(O$4=$I14,"C",IF(O$4=$H14,"R","")))) -> R | P14: =IF(P$4=$B14,"P",IF(P$4=$J14,"A",IF(P$4=$I14,"C",IF(P$4=$H14,"R","")))) -> C | Q14: =IF(Q$4=$B14,"P",IF(Q$4=$J14,"A",IF(Q$4=$I14,"C",IF(Q$4=$H14,"R","")))) | R14: =IF(R$4=$B14,"P",IF(R$4=$J14,"A",IF(R$4=$I14,"C",IF(R$4=$H14,"R","")))) | S14: =IF(S$4=$B14,"P",IF(S$4=$J14,"A",IF(S$4=$I14,"C",IF(S$4=$H14,"R","")))) | T14: =IF(T$4=$B14,"P",IF(T$4=$J14,"A",IF(T$4=$I14,"C",IF(T$4=$H14,"R","")))) | ... AU14: =IF(AU$4=$B14,"P",IF(AU$4=$J14,"A",IF(AU$4=$I14,"C",IF(AU$4=$H14,"R",""))))
A15: P11 | B15: 46337 | C15: =CHOOSE(WEEKDAY(B15,2),"seg","ter","qua","qui","sex","sáb","dom") -> qua | D15: =INT((B15-$B$2)/7)+1 -> 4 | E15: 4 · Confiança | F15: Carrossel | G15: Estilo de vida também é tratamento sério | H15: =WORKDAY(B15,-$F$2,Listas!$A$3:$A$6) -> 46330 | I15: =WORKDAY(B15,-$H$2,Listas!$A$3:$A$6) -> 46335 | J15: =WORKDAY(B15,-$J$2,Listas!$A$3:$A$6) -> 46336 | K15: Roteiro pronto | M15: =IF(M$4=$B15,"P",IF(M$4=$J15,"A",IF(M$4=$I15,"C",IF(M$4=$H15,"R","")))) | N15: =IF(N$4=$B15,"P",IF(N$4=$J15,"A",IF(N$4=$I15,"C",IF(N$4=$H15,"R","")))) | O15: =IF(O$4=$B15,"P",IF(O$4=$J15,"A",IF(O$4=$I15,"C",IF(O$4=$H15,"R","")))) | P15: =IF(P$4=$B15,"P",IF(P$4=$J15,"A",IF(P$4=$I15,"C",IF(P$4=$H15,"R","")))) | Q15: =IF(Q$4=$B15,"P",IF(Q$4=$J15,"A",IF(Q$4=$I15,"C",IF(Q$4=$H15,"R","")))) | R15: =IF(R$4=$B15,"P",IF(R$4=$J15,"A",IF(R$4=$I15,"C",IF(R$4=$H15,"R","")))) | S15: =IF(S$4=$B15,"P",IF(S$4=$J15,"A",IF(S$4=$I15,"C",IF(S$4=$H15,"R","")))) | T15: =IF(T$4=$B15,"P",IF(T$4=$J15,"A",IF(T$4=$I15,"C",IF(T$4=$H15,"R","")))) | ... AU15: =IF(AU$4=$B15,"P",IF(AU$4=$J15,"A",IF(AU$4=$I15,"C",IF(AU$4=$H15,"R",""))))
A16: P12 | B16: 46339 | C16: =CHOOSE(WEEKDAY(B16,2),"seg","ter","qua","qui","sex","sáb","dom") -> sex | D16: =INT((B16-$B$2)/7)+1 -> 4 | E16: 4 · Confiança | F16: Carrossel | G16: Como levar a FairHealth para sua empresa? | H16: =WORKDAY(B16,-$F$2,Listas!$A$3:$A$6) -> 46332 | I16: =WORKDAY(B16,-$H$2,Listas!$A$3:$A$6) -> 46337 | J16: =WORKDAY(B16,-$J$2,Listas!$A$3:$A$6) -> 46338 | K16: Roteiro em revisão | M16: =IF(M$4=$B16,"P",IF(M$4=$J16,"A",IF(M$4=$I16,"C",IF(M$4=$H16,"R","")))) | N16: =IF(N$4=$B16,"P",IF(N$4=$J16,"A",IF(N$4=$I16,"C",IF(N$4=$H16,"R","")))) | O16: =IF(O$4=$B16,"P",IF(O$4=$J16,"A",IF(O$4=$I16,"C",IF(O$4=$H16,"R","")))) | P16: =IF(P$4=$B16,"P",IF(P$4=$J16,"A",IF(P$4=$I16,"C",IF(P$4=$H16,"R","")))) | Q16: =IF(Q$4=$B16,"P",IF(Q$4=$J16,"A",IF(Q$4=$I16,"C",IF(Q$4=$H16,"R","")))) | R16: =IF(R$4=$B16,"P",IF(R$4=$J16,"A",IF(R$4=$I16,"C",IF(R$4=$H16,"R","")))) | S16: =IF(S$4=$B16,"P",IF(S$4=$J16,"A",IF(S$4=$I16,"C",IF(S$4=$H16,"R","")))) | T16: =IF(T$4=$B16,"P",IF(T$4=$J16,"A",IF(T$4=$I16,"C",IF(T$4=$H16,"R","")))) | ... AU16: =IF(AU$4=$B16,"P",IF(AU$4=$J16,"A",IF(AU$4=$I16,"C",IF(AU$4=$H16,"R",""))))
A18: Resumo
A19: Reels | B19: =COUNTIF(F5:F16,"Reel") -> 4
A20: Carrosséis | B20: =COUNTIF(F5:F16,"Carrossel") -> 7
A21: Fotos únicas | B21: =COUNTIF(F5:F16,"Foto única") -> 1
A22: Total | B22: =COUNTA(A5:A16) -> 12
A23: Publicados | B23: =COUNTIF(K5:K16,"Publicado") -> 0

Sheet Calendário
A1: Calendário do mês · 19/10 a 13/11
A2: Os títulos vêm da aba Cronograma: mudou a data lá, muda aqui. A cor mostra o formato.
F3: Reel | G3: Carrossel | H3: Foto única
A4: Semana | B4: seg | C4: ter | D4: qua | E4: qui | F4: sex | G4: sáb | H4: dom
A5: Semana 1 | B5: =Cronograma!$B$2+0 -> 46314 | C5: =Cronograma!$B$2+1 -> 46315 | D5: =Cronograma!$B$2+2 -> 46316 | E5: =Cronograma!$B$2+3 -> 46317 | F5: =Cronograma!$B$2+4 -> 46318 | G5: =Cronograma!$B$2+5 -> 46319 | H5: =Cronograma!$B$2+6 -> 46320
A6: =TEXT(B5,"dd/mm")&" a "&TEXT(H5,"dd/mm") -> 19/10 a 25/10 | B6: =IFERROR(INDEX(Cronograma!$G$5:$G$16,MATCH(B5,Cronograma!$B$5:$B$16,0)),IFERROR(INDEX(Listas!$E$3:$E$5,MATCH(B5,Listas!$D$3:$D$5,0)),"")) -> Quem somos, na voz do Dr. Ronald | C6: =IFERROR(INDEX(Cronograma!$G$5:$G$16,MATCH(C5,Cronograma!$B$5:$B$16,0)),IFERROR(INDEX(Listas!$E$3:$E$5,MATCH(C5,Listas!$D$3:$D$5,0)),"")) | D6: =IFERROR(INDEX(Cronograma!$G$5:$G$16,MATCH(D5,Cronograma!$B$5:$B$16,0)),IFERROR(INDEX(Listas!$E$3:$E$5,MATCH(D5,Listas!$D$3:$D$5,0)),"")) -> Por que a FairHealth existe? | E6: =IFERROR(INDEX(Cronograma!$G$5:$G$16,MATCH(E5,Cronograma!$B$5:$B$16,0)),IFERROR(INDEX(Listas!$E$3:$E$5,MATCH(E5,Listas!$D$3:$D$5,0)),"")) | F6: =IFERROR(INDEX(Cronograma!$G$5:$G$16,MATCH(F5,Cronograma!$B$5:$B$16,0)),IFERROR(INDEX(Listas!$E$3:$E$5,MATCH(F5,Listas!$D$3:$D$5,0)),"")) -> Cuidar da saúde não deveria começar quando algo vai mal | G6: =IFERROR(INDEX(Cronograma!$G$5:$G$16,MATCH(G5,Cronograma!$B$5:$B$16,0)),IFERROR(INDEX(Listas!$E$3:$E$5,MATCH(G5,Listas!$D$3:$D$5,0)),"")) | H6: =IFERROR(INDEX(Cronograma!$G$5:$G$16,MATCH(H5,Cronograma!$B$5:$B$16,0)),IFERROR(INDEX(Listas!$E$3:$E$5,MATCH(H5,Listas!$D$3:$D$5,0)),""))
B7: =IFERROR(INDEX(Cronograma!$F$5:$F$16,MATCH(B5,Cronograma!$B$5:$B$16,0))&" · "&INDEX(Cronograma!$A$5:$A$16,MATCH(B5,Cronograma!$B$5:$B$16,0)),"") -> Reel · P01 | C7: =IFERROR(INDEX(Cronograma!$F$5:$F$16,MATCH(C5,Cronograma!$B$5:$B$16,0))&" · "&INDEX(Cronograma!$A$5:$A$16,MATCH(C5,Cronograma!$B$5:$B$16,0)),"") | D7: =IFERROR(INDEX(Cronograma!$F$5:$F$16,MATCH(D5,Cronograma!$B$5:$B$16,0))&" · "&INDEX(Cronograma!$A$5:$A$16,MATCH(D5,Cronograma!$B$5:$B$16,0)),"") -> Carrossel · P02 | E7: =IFERROR(INDEX(Cronograma!$F$5:$F$16,MATCH(E5,Cronograma!$B$5:$B$16,0))&" · "&INDEX(Cronograma!$A$5:$A$16,MATCH(E5,Cronograma!$B$5:$B$16,0)),"") | F7: =IFERROR(INDEX(Cronograma!$F$5:$F$16,MATCH(F5,Cronograma!$B$5:$B$16,0))&" · "&INDEX(Cronograma!$A$5:$A$16,MATCH(F5,Cronograma!$B$5:$B$16,0)),"") -> Carrossel · P03 | G7: =IFERROR(INDEX(Cronograma!$F$5:$F$16,MATCH(G5,Cronograma!$B$5:$B$16,0))&" · "&INDEX(Cronograma!$A$5:$A$16,MATCH(G5,Cronograma!$B$5:$B$16,0)),"") | H7: =IFERROR(INDEX(Cronograma!$F$5:$F$16,MATCH(H5,Cronograma!$B$5:$B$16,0))&" · "&INDEX(Cronograma!$A$5:$A$16,MATCH(H5,Cronograma!$B$5:$B$16,0)),"")
A9: Semana 2 | B9: =Cronograma!$B$2+7 -> 46321 | C9: =Cronograma!$B$2+8 -> 46322 | D9: =Cronograma!$B$2+9 -> 46323 | E9: =Cronograma!$B$2+10 -> 46324 | F9: =Cronograma!$B$2+11 -> 46325 | G9: =Cronograma!$B$2+12 -> 46326 | H9: =Cronograma!$B$2+13 -> 46327
A10: =TEXT(B9,"dd/mm")&" a "&TEXT(H9,"dd/mm") -> 26/10 a 01/11 | B10: =IFERROR(INDEX(Cronograma!$G$5:$G$16,MATCH(B9,Cronograma!$B$5:$B$16,0)),IFERROR(INDEX(Listas!$E$3:$E$5,MATCH(B9,Listas!$D$3:$D$5,0)),"")) -> O que acontece quando o cuidado não faz parte da rotina? | C10: =IFERROR(INDEX(Cronograma!$G$5:$G$16,MATCH(C9,Cronograma!$B$5:$B$16,0)),IFERROR(INDEX(Listas!$E$3:$E$5,MATCH(C9,Listas!$D$3:$D$5,0)),"")) | D10: =IFERROR(INDEX(Cronograma!$G$5:$G$16,MATCH(D9,Cronograma!$B$5:$B$16,0)),IFERROR(INDEX(Listas!$E$3:$E$5,MATCH(D9,Listas!$D$3:$D$5,0)),"")) -> Prevenção também é investimento | E10: =IFERROR(INDEX(Cronograma!$G$5:$G$16,MATCH(E9,Cronograma!$B$5:$B$16,0)),IFERROR(INDEX(Listas!$E$3:$E$5,MATCH(E9,Listas!$D$3:$D$5,0)),"")) | F10: =IFERROR(INDEX(Cronograma!$G$5:$G$16,MATCH(F9,Cronograma!$B$5:$B$16,0)),IFERROR(INDEX(Listas!$E$3:$E$5,MATCH(F9,Listas!$D$3:$D$5,0)),"")) -> Como transformar a prevenção em parte da rotina de uma empresa? | G10: =IFERROR(INDEX(Cronograma!$G$5:$G$16,MATCH(G9,Cronograma!$B$5:$B$16,0)),IFERROR(INDEX(Listas!$E$3:$E$5,MATCH(G9,Listas!$D$3:$D$5,0)),"")) | H10: =IFERROR(INDEX(Cronograma!$G$5:$G$16,MATCH(H9,Cronograma!$B$5:$B$16,0)),IFERROR(INDEX(Listas!$E$3:$E$5,MATCH(H9,Listas!$D$3:$D$5,0)),""))
B11: =IFERROR(INDEX(Cronograma!$F$5:$F$16,MATCH(B9,Cronograma!$B$5:$B$16,0))&" · "&INDEX(Cronograma!$A$5:$A$16,MATCH(B9,Cronograma!$B$5:$B$16,0)),"") -> Reel · P04 | C11: =IFERROR(INDEX(Cronograma!$F$5:$F$16,MATCH(C9,Cronograma!$B$5:$B$16,0))&" · "&INDEX(Cronograma!$A$5:$A$16,MATCH(C9,Cronograma!$B$5:$B$16,0)),"") | D11: =IFERROR(INDEX(Cronograma!$F$5:$F$16,MATCH(D9,Cronograma!$B$5:$B$16,0))&" · "&INDEX(Cronograma!$A$5:$A$16,MATCH(D9,Cronograma!$B$5:$B$16,0)),"") -> Foto única · P05 | E11: =IFERROR(INDEX(Cronograma!$F$5:$F$16,MATCH(E9,Cronograma!$B$5:$B$16,0))&" · "&INDEX(Cronograma!$A$5:$A$16,MATCH(E9,Cronograma!$B$5:$B$16,0)),"") | F11: =IFERROR(INDEX(Cronograma!$F$5:$F$16,MATCH(F9,Cronograma!$B$5:$B$16,0))&" · "&INDEX(Cronograma!$A$5:$A$16,MATCH(F9,Cronograma!$B$5:$B$16,0)),"") -> Carrossel · P06 | G11: =IFERROR(INDEX(Cronograma!$F$5:$F$16,MATCH(G9,Cronograma!$B$5:$B$16,0))&" · "&INDEX(Cronograma!$A$5:$A$16,MATCH(G9,Cronograma!$B$5:$B$16,0)),"") | H11: =IFERROR(INDEX(Cronograma!$F$5:$F$16,MATCH(H9,Cronograma!$B$5:$B$16,0))&" · "&INDEX(Cronograma!$A$5:$A$16,MATCH(H9,Cronograma!$B$5:$B$16,0)),"")
A13: Semana 3 | B13: =Cronograma!$B$2+14 -> 46328 | C13: =Cronograma!$B$2+15 -> 46329 | D13: =Cronograma!$B$2+16 -> 46330 | E13: =Cronograma!$B$2+17 -> 46331 | F13: =Cronograma!$B$2+18 -> 46332 | G13: =Cronograma!$B$2+19 -> 46333 | H13: =Cronograma!$B$2+20 -> 46334
A14: =TEXT(B13,"dd/mm")&" a "&TEXT(H13,"dd/mm") -> 02/11 a 08/11 | B14: =IFERROR(INDEX(Cronograma!$G$5:$G$16,MATCH(B13,Cronograma!$B$5:$B$16,0)),IFERROR(INDEX(Listas!$E$3:$E$5,MATCH(B13,Listas!$D$3:$D$5,0)),"")) -> Finados (feriado) | C14: =IFERROR(INDEX(Cronograma!$G$5:$G$16,MATCH(C13,Cronograma!$B$5:$B$16,0)),IFERROR(INDEX(Listas!$E$3:$E$5,MATCH(C13,Listas!$D$3:$D$5,0)),"")) -> Como funciona o cuidado na prática? | D14: =IFERROR(INDEX(Cronograma!$G$5:$G$16,MATCH(D13,Cronograma!$B$5:$B$16,0)),IFERROR(INDEX(Listas!$E$3:$E$5,MATCH(D13,Listas!$D$3:$D$5,0)),"")) -> Quatro frentes, um cuidado conectado | E14: =IFERROR(INDEX(Cronograma!$G$5:$G$16,MATCH(E13,Cronograma!$B$5:$B$16,0)),IFERROR(INDEX(Listas!$E$3:$E$5,MATCH(E13,Listas!$D$3:$D$5,0)),"")) | F14: =IFERROR(INDEX(Cronograma!$G$5:$G$16,MATCH(F13,Cronograma!$B$5:$B$16,0)),IFERROR(INDEX(Listas!$E$3:$E$5,MATCH(F13,Listas!$D$3:$D$5,0)),"")) -> Uma história de cuidado que começou em 2009 | G14: =IFERROR(INDEX(Cronograma!$G$5:$G$16,MATCH(G13,Cronograma!$B$5:$B$16,0)),IFERROR(INDEX(Listas!$E$3:$E$5,MATCH(G13,Listas!$D$3:$D$5,0)),"")) | H14: =IFERROR(INDEX(Cronograma!$G$5:$G$16,MATCH(H13,Cronograma!$B$5:$B$16,0)),IFERROR(INDEX(Listas!$E$3:$E$5,MATCH(H13,Listas!$D$3:$D$5,0)),""))
B15: =IFERROR(INDEX(Cronograma!$F$5:$F$16,MATCH(B13,Cronograma!$B$5:$B$16,0))&" · "&INDEX(Cronograma!$A$5:$A$16,MATCH(B13,Cronograma!$B$5:$B$16,0)),"") | C15: =IFERROR(INDEX(Cronograma!$F$5:$F$16,MATCH(C13,Cronograma!$B$5:$B$16,0))&" · "&INDEX(Cronograma!$A$5:$A$16,MATCH(C13,Cronograma!$B$5:$B$16,0)),"") -> Carrossel · P07 | D15: =IFERROR(INDEX(Cronograma!$F$5:$F$16,MATCH(D13,Cronograma!$B$5:$B$16,0))&" · "&INDEX(Cronograma!$A$5:$A$16,MATCH(D13,Cronograma!$B$5:$B$16,0)),"") -> Reel · P08 | E15: =IFERROR(INDEX(Cronograma!$F$5:$F$16,MATCH(E13,Cronograma!$B$5:$B$16,0))&" · "&INDEX(Cronograma!$A$5:$A$16,MATCH(E13,Cronograma!$B$5:$B$16,0)),"") | F15: =IFERROR(INDEX(Cronograma!$F$5:$F$16,MATCH(F13,Cronograma!$B$5:$B$16,0))&" · "&INDEX(Cronograma!$A$5:$A$16,MATCH(F13,Cronograma!$B$5:$B$16,0)),"") -> Carrossel · P09 | G15: =IFERROR(INDEX(Cronograma!$F$5:$F$16,MATCH(G13,Cronograma!$B$5:$B$16,0))&" · "&INDEX(Cronograma!$A$5:$A$16,MATCH(G13,Cronograma!$B$5:$B$16,0)),"") | H15: =IFERROR(INDEX(Cronograma!$F$5:$F$16,MATCH(H13,Cronograma!$B$5:$B$16,0))&" · "&INDEX(Cronograma!$A$5:$A$16,MATCH(H13,Cronograma!$B$5:$B$16,0)),"")
A17: Semana 4 | B17: =Cronograma!$B$2+21 -> 46335 | C17: =Cronograma!$B$2+22 -> 46336 | D17: =Cronograma!$B$2+23 -> 46337 | E17: =Cronograma!$B$2+24 -> 46338 | F17: =Cronograma!$B$2+25 -> 46339 | G17: =Cronograma!$B$2+26 -> 46340 | H17: =Cronograma!$B$2+27 -> 46341
A18: =TEXT(B17,"dd/mm")&" a "&TEXT(H17,"dd/mm") -> 09/11 a 15/11 | B18: =IFERROR(INDEX(Cronograma!$G$5:$G$16,MATCH(B17,Cronograma!$B$5:$B$16,0)),IFERROR(INDEX(Listas!$E$3:$E$5,MATCH(B17,Listas!$D$3:$D$5,0)),"")) -> Cuidado na prática: experiências e resultados reais | C18: =IFERROR(INDEX(Cronograma!$G$5:$G$16,MATCH(C17,Cronograma!$B$5:$B$16,0)),IFERROR(INDEX(Listas!$E$3:$E$5,MATCH(C17,Listas!$D$3:$D$5,0)),"")) | D18: =IFERROR(INDEX(Cronograma!$G$5:$G$16,MATCH(D17,Cronograma!$B$5:$B$16,0)),IFERROR(INDEX(Listas!$E$3:$E$5,MATCH(D17,Listas!$D$3:$D$5,0)),"")) -> Estilo de vida também é tratamento sério | E18: =IFERROR(INDEX(Cronograma!$G$5:$G$16,MATCH(E17,Cronograma!$B$5:$B$16,0)),IFERROR(INDEX(Listas!$E$3:$E$5,MATCH(E17,Listas!$D$3:$D$5,0)),"")) | F18: =IFERROR(INDEX(Cronograma!$G$5:$G$16,MATCH(F17,Cronograma!$B$5:$B$16,0)),IFERROR(INDEX(Listas!$E$3:$E$5,MATCH(F17,Listas!$D$3:$D$5,0)),"")) -> Como levar a FairHealth para sua empresa? | G18: =IFERROR(INDEX(Cronograma!$G$5:$G$16,MATCH(G17,Cronograma!$B$5:$B$16,0)),IFERROR(INDEX(Listas!$E$3:$E$5,MATCH(G17,Listas!$D$3:$D$5,0)),"")) -> Dia Mundial do Diabetes | H18: =IFERROR(INDEX(Cronograma!$G$5:$G$16,MATCH(H17,Cronograma!$B$5:$B$16,0)),IFERROR(INDEX(Listas!$E$3:$E$5,MATCH(H17,Listas!$D$3:$D$5,0)),"")) -> Proclamação da República (feriado)
B19: =IFERROR(INDEX(Cronograma!$F$5:$F$16,MATCH(B17,Cronograma!$B$5:$B$16,0))&" · "&INDEX(Cronograma!$A$5:$A$16,MATCH(B17,Cronograma!$B$5:$B$16,0)),"") -> Reel · P10 | C19: =IFERROR(INDEX(Cronograma!$F$5:$F$16,MATCH(C17,Cronograma!$B$5:$B$16,0))&" · "&INDEX(Cronograma!$A$5:$A$16,MATCH(C17,Cronograma!$B$5:$B$16,0)),"") | D19: =IFERROR(INDEX(Cronograma!$F$5:$F$16,MATCH(D17,Cronograma!$B$5:$B$16,0))&" · "&INDEX(Cronograma!$A$5:$A$16,MATCH(D17,Cronograma!$B$5:$B$16,0)),"") -> Carrossel · P11 | E19: =IFERROR(INDEX(Cronograma!$F$5:$F$16,MATCH(E17,Cronograma!$B$5:$B$16,0))&" · "&INDEX(Cronograma!$A$5:$A$16,MATCH(E17,Cronograma!$B$5:$B$16,0)),"") | F19: =IFERROR(INDEX(Cronograma!$F$5:$F$16,MATCH(F17,Cronograma!$B$5:$B$16,0))&" · "&INDEX(Cronograma!$A$5:$A$16,MATCH(F17,Cronograma!$B$5:$B$16,0)),"") -> Carrossel · P12 | G19: =IFERROR(INDEX(Cronograma!$F$5:$F$16,MATCH(G17,Cronograma!$B$5:$B$16,0))&" · "&INDEX(Cronograma!$A$5:$A$16,MATCH(G17,Cronograma!$B$5:$B$16,0)),"") | H19: =IFERROR(INDEX(Cronograma!$F$5:$F$16,MATCH(H17,Cronograma!$B$5:$B$16,0))&" · "&INDEX(Cronograma!$A$5:$A$16,MATCH(H17,Cronograma!$B$5:$B$16,0)),"")
B22: Reels | C22: =COUNTIF(Cronograma!$F$5:$F$16,"Reel") -> 4 | D22: Carrosséis | E22: =COUNTIF(Cronograma!$F$5:$F$16,"Carrossel") -> 7 | F22: Fotos únicas | G22: =COUNTIF(Cronograma!$F$5:$F$16,"Foto única") -> 1
B23: Ritmo: 1 reel e 2 posts estáticos por semana, segunda, quarta e sexta (na semana de Finados, terça, quarta e sexta).

Sheet Posts
A1: Ficha de cada post
A2: Data, dia, semana, bloco, formato, título e status vêm da aba Cronograma. Na arte e na legenda, a marca vai em minúsculas (fairhealth).
A4: ID | B4: Publicação | C4: Dia | D4: Semana | E4: Bloco | F4: Formato | G4: Título (calendário) | H4: Subtítulo | I4: No calendário de 12 posts | J4: Especificação | K4: Gancho / capa (primeira frase) | L4: Objetivo | M4: O que estamos dizendo por trás | N4: Persona | O4: Fio da história (vem de · leva para) | P4: Direção visual | Q4: Material necessário | R4: Legenda (pronta para colar) | S4: Stories de apoio | T4: Fonte | U4: Validar antes de publicar | V4: Status | W4: Link da arte | X4: Comentários da revisão
A5: P01 | B5: =Cronograma!B5 -> 46314 | C5: =Cronograma!C5 -> seg | D5: =Cronograma!D5 -> 1 | E5: =Cronograma!E5 -> 1 · Reconhecimento | F5: =Cronograma!F5 -> Reel | G5: =Cronograma!G5 -> Quem somos, na voz do Dr. Ronald | H5: Resumo dos posts já publicados, contado pelo fundador do Escritório do Paciente, puxando a origem em 2009 | I5: Novo (antes do post 02) | J5: Reel 9:16 (1080 × 1920), 35 a 45 s. Capa 4:5 para a grade. | K5: Se você chegou agora, em 40 segundos eu te conto o que é a fairhealth. | L5: Dar rosto e voz médica à marca, retomar os dois posts publicados e abrir o post da origem. | M5: Rosto e voz médica para a marca, com confiança desde o começo. | N5: RH; Colaboradores | O5: Vem de: os posts publicados "O que é a fairhealth?" e "Conheça o Escritório do Cuidado". Leva para: P02, a origem em 2009 (a última frase do reel anuncia o post). | P5: Dr. Ronald em plano médio, olhando para a câmera, em sala clara e neutra (nunca numa empresa-cliente). Legendas sempre na tela, em Raleway. Cortes secos, trilha calma e baixa. Capa com fundo Tiffany e a frase "O que é a fairhealth, em 40 segundos". | Q5: Gravação vertical com celular ou câmera, microfone de lapela, luz natural ou de janela. Autorização de uso de imagem assinada. Gravar no mesmo dia que o P10. | R5: Se você chegou agora, o Dr. Ronald te conta em 40 segundos o que é a fairhealth. Medicina preventiva, dentro da empresa: médicos e psicólogos perto de quem trabalha, um plano de cuidado para cada pessoa e acompanhamento de perto. Tudo começa no Escritório do Cuidado, com uma pergunta: o que é importante para você? E essa pergunta tem história. Ela nasceu num hospital, em 2009. É o nosso próximo post. #fairhealth #saudecorporativa #medicinapreventiva #escritoriodocuidado #cuidadocentradonapessoa | S5: Repost do reel com a caixa de perguntas "O que você quer saber sobre a fairhealth?". | T5: Posicionamento v3.2 e one-pager (11/10); essencia.md ("De onde veio"). | U5: Autorização de uso de imagem do Dr. Ronald. Como creditar (nome e função) na legenda e na tela. Exceção à decisão de 09/10 de não ter o time em cena (o post do time segue segurado). | V5: =Cronograma!K5 -> Roteiro em revisão
A6: P02 | B6: =Cronograma!B6 -> 46316 | C6: =Cronograma!C6 -> qua | D6: =Cronograma!D6 -> 1 | E6: =Cronograma!E6 -> 1 · Reconhecimento | F6: =Cronograma!F6 -> Carrossel | G6: =Cronograma!G6 -> Por que a FairHealth existe? | H6: A origem do modelo de cuidado em 2009 e sua evolução até as empresas | I6: Post 02 | J6: Carrossel 4:5 (1080 × 1350), 6 slides. | K6: Antes de chegar às empresas, nossa história começou em um hospital. | L6: Contar a origem do modelo e criar conexão com o propósito. | M6: O modelo tem história: não somos mais uma startup de bem-estar. O cuidado começa pela pessoa. | N6: RH; Colaboradores; Medicina do Trabalho | O6: Vem de: o reel do Dr. Ronald, que termina em "nasceu num hospital, em 2009". Leva para: P03, por que o cuidado precisa chegar antes. | P6: Arte v2: Tiffany como cor principal (fundos Tiffany nos slides 2, 4 e 6, verde nos 3 e 5, capa de luz tiffany). Um fio contínuo creme atravessa os seis slides, de um ponto na capa até o logo. | Q6: Arte pronta: instagram/posts/nossa-historia/png-v2/ (h01 a h06). Levar ao Canva com elementos editáveis, se precisar ajustar. | R6: A história por trás da fairhealth começou muito antes de chegarmos às empresas. Em 2009, dentro de um hospital, nascia o Escritório do Paciente: um modelo de cuidado que tinha a escuta e as necessidades de cada pessoa como ponto de partida. Ao longo do tempo, essa forma de cuidar evoluiu e encontrou novos espaços. O Escritório do Paciente virou o Escritório do Cuidado. Hoje, na fairhealth, levamos essa filosofia para dentro das empresas, aproximando o cuidado preventivo da rotina das pessoas. Porque, para nós, cuidar não é apenas olhar para a saúde. É olhar para quem está por trás dela. O cuidado começa pela pessoa. #fairhealth #saudecorporativa #medicinapreventiva #cuidadohumanizado #escritoriodocuidado | S6: Slide 2 (2009) com a enquete "Você sabia que a fairhealth nasceu num hospital?". | T6: essencia.md ("De onde veio"). Proposta de roteiro da Nina (13/10). | U6: Confirmar o ano de 2009 e a passagem do Escritório do Paciente para o Escritório do Cuidado (2024 e 2025). Sem o nome do hospital nem de pessoas. "Validado no SUS" fica de fora. | V6: =Cronograma!K6 -> Arte pronta
A7: P03 | B7: =Cronograma!B7 -> 46318 | C7: =Cronograma!C7 -> sex | D7: =Cronograma!D7 -> 1 | E7: =Cronograma!E7 -> 2 · Relevância | F7: =Cronograma!F7 -> Carrossel | G7: =Cronograma!G7 -> Cuidar da saúde não deveria começar quando algo vai mal | H7: A importância de uma abordagem preventiva, e não apenas reativa | I7: Post 04 | J7: Carrossel 4:5 (1080 × 1350), 8 slides. | K7: Cuidar da saúde não deveria começar quando algo vai mal. | L7: Mostrar a diferença entre cuidado reativo e preventivo, voltando no tempo a cada slide. | M7: O plano de saúde entra depois. A fairhealth entra antes. | N7: RH; Lideranças | O7: Vem de: P02, o cuidado que saiu do hospital para chegar antes. Leva para: P04, o que acontece quando o cuidado não está na rotina. | P7: Carrossel "de trás para frente": o fio contínuo corre da direita para a esquerda, com um ponto em cada etapa (afastamento, atestado, semana pesada, noite sem dormir). Capa Tiffany; slides 2 a 5 alternando verde e Tiffany; frase da pergunta em negrito itálico. | Q7: Só tipografia e o fio. Sem foto. | R7: Todo afastamento tem um antes. Antes do afastamento, teve um atestado. Antes do atestado, uma semana pesada. Antes dela, uma noite sem dormir. E, no começo de tudo, uma pergunta que ninguém fez: o que é importante para você? O cuidado reativo chega quando a doença já apareceu. O preventivo chega antes, na rotina e nos primeiros sinais. É nesse antes que a fairhealth trabalha, dentro da empresa. Salve este post e mande para quem cuida das pessoas na sua empresa. #fairhealth #saudecorporativa #medicinapreventiva #saudemental #gestaodepessoas | S7: Caixa de perguntas: "Qual é o primeiro sinal de que alguém do seu time não está bem?". | T7: Posicionamento v3.2 (eixo "antes"). | U7: Sem promessa de evitar doença (CFM): o texto fala de cuidado, não de resultado. | V7: =Cronograma!K7 -> Roteiro em revisão
A8: P04 | B8: =Cronograma!B8 -> 46321 | C8: =Cronograma!C8 -> seg | D8: =Cronograma!D8 -> 2 | E8: =Cronograma!E8 -> 2 · Relevância | F8: =Cronograma!F8 -> Reel | G8: =Cronograma!G8 -> O que acontece quando o cuidado não faz parte da rotina? | H8: Desafios da saúde dos colaboradores: acesso e continuidade do cuidado | I8: Post 05 | J8: Reel 9:16 (1080 × 1920), 25 a 30 s, só tipografia. Capa 4:5. | K8: O que acontece quando o cuidado não faz parte da rotina? | L8: Mostrar o tamanho do problema com um número oficial e as três barreiras do dia a dia. | M8: O problema não é a falta de plano de saúde: é o cuidado estar longe. | N8: RH; Diretoria financeira | O8: Vem de: P03, cuidar antes. Leva para: P05, para a empresa, cuidar antes também é investimento. | P8: Tipografia animada em Raleway, frase a frase, alternando fundos Tiffany e verde. Número em verde-escuro, calmo, nunca em vermelho. Fonte no rodapé. Texto dentro da área segura. Trilha calma. | Q8: Só tipografia (Canva ou CapCut). Sem foto e sem locução (voz em off opcional). | R8: Em 2024, o Brasil registrou mais de 470 mil licenças do trabalho por saúde mental, o maior número em dez anos (Ministério da Previdência Social). Por trás de cada número, quase sempre tem um cuidado que chegou tarde. Não por falta de plano de saúde, mas por três barreiras do dia a dia: falta de tempo, cuidado longe de onde a pessoa está e nenhuma continuidade depois da consulta. Quando o cuidado está perto, ele deixa de ser exceção e vira rotina. #fairhealth #saudementalnotrabalho #saudecorporativa #medicinapreventiva #gestaodepessoas | S8: Enquete: "Na sua empresa, o cuidado com a saúde é rotina ou exceção?". | T8: Ministério da Previdência Social: 472.328 licenças por transtornos mentais em 2024, maior número da série iniciada em 2014 (dados divulgados em 2025). | U8: Conferir o número no painel oficial de dados abertos (veículos divulgam 440 mil e 472 mil) e a frase "o maior número em dez anos". | V8: =Cronograma!K8 -> Roteiro em revisão
A9: P05 | B9: =Cronograma!B9 -> 46323 | C9: =Cronograma!C9 -> qua | D9: =Cronograma!D9 -> 2 | E9: =Cronograma!E9 -> 2 · Relevância | F9: =Cronograma!F9 -> Foto única | G9: =Cronograma!G9 -> Prevenção também é investimento | H9: O que os estudos mostram sobre absenteísmo e custos com saúde quando a empresa cuida antes | I9: Extra | J9: Foto única 4:5 (1080 × 1350). | K9: Prevenção também é investimento. | L9: Mostrar, com estudos externos e a fonte visível, que cuidar antes também faz sentido para a empresa. | M9: Cuidar antes também faz sentido para o financeiro. O retorno é consequência, não promessa. | N9: RH; Diretoria financeira | O9: Vem de: P04, o tamanho do problema. Leva para: P06, como a prevenção vira rotina. | P9: Arte pronta (luz tiffany, números em Tiffany, sem brilho). Tirar a paginação e a etiqueta do carrossel antigo. | Q9: Canva: design DAHX17FZzNQ (https://www.canva.com/d/E6Gp2hFDhnNw1ME). Repositório: instagram/posts/o-que-e-a-fairhealth/png-v10/d10.png. | R9: Prevenção também é investimento. Cuidar antes faz bem para as pessoas. E os estudos mostram que também faz diferença para a empresa: −28% de absenteísmo (Harvard Business Review, 2022) −22% de custos com saúde (SHRM, 2023) São números de estudos externos, não uma promessa de resultado. É esse o trabalho da fairhealth: medicina preventiva, dentro da empresa, com um plano de cuidado para cada pessoa. Quer conversar sobre isso na sua empresa? Fale com a gente pelo direct. #fairhealth #saudecorporativa #medicinapreventiva #absenteismo #gestaodepessoas | S9: Repost com o adesivo de link para o artigo ou com a pergunta "Sua empresa mede o absenteísmo?". | T9: Harvard Business Review (2022); SHRM (2023). Números liberados desde 25/09 (voice.md). | U9: Confirmar o que cada estudo mediu (tipo de programa e população). São estudos externos, nunca resultado da fairhealth. | V9: =Cronograma!K9 -> Arte pronta
A10: P06 | B10: =Cronograma!B10 -> 46325 | C10: =Cronograma!C10 -> sex | D10: =Cronograma!D10 -> 2 | E10: =Cronograma!E10 -> 2 · Relevância | F10: =Cronograma!F10 -> Carrossel | G10: =Cronograma!G10 -> Como transformar a prevenção em parte da rotina de uma empresa? | H10: Conectar o problema ao modelo de cuidado oferecido pela FairHealth | I10: Post 06 | J10: Carrossel 4:5 (1080 × 1350), 7 slides. | K10: Prevenção não é campanha. É rotina. | L10: Ligar o problema ao modelo da fairhealth em cinco movimentos práticos. | M10: Prevenção é estrutura, não campanha pontual. | N10: RH; Lideranças | O10: Vem de: P05, prevenção também é investimento. Fecha o bloco de relevância. Leva para: P07, como isso acontece na prática. | P10: Passo a passo numerado no fio contínuo (um ponto por movimento). Capa Tiffany; slides alternando verde e Tiffany; número de cada movimento grande e fino. | Q10: Só tipografia, o fio e ícones lineares finos. | R10: Prevenção não acontece numa campanha de um mês. Ela precisa fazer parte da rotina. Na prática, isso pede cinco movimentos: levar o cuidado para perto de quem trabalha, começar pela escuta, montar um plano que caiba na vida real, acompanhar de forma contínua e dar ao RH uma visão do todo, sem expor ninguém. É assim que a fairhealth trabalha dentro das empresas. Na semana que vem, a gente mostra como isso acontece na prática. #fairhealth #saudecorporativa #medicinapreventiva #medicinadoestilodevida #gestaodepessoas | S10: Sequência com os 5 movimentos, um por story, e o adesivo "Salvar". | T10: One-pager (11/10); posicionamento v3.2 (diferenciais). | U10: Indicadores que entram no relatório do RH (fairdata). Não prometer conformidade com a NR-1. | V10: =Cronograma!K10 -> Roteiro em revisão
A11: P07 | B11: =Cronograma!B11 -> 46329 | C11: =Cronograma!C11 -> ter | D11: =Cronograma!D11 -> 3 | E11: =Cronograma!E11 -> 3 · Compreensão | F11: =Cronograma!F11 -> Carrossel | G11: =Cronograma!G11 -> Como funciona o cuidado na prática? | H11: A jornada entre escuta, atendimento, plano individualizado e acompanhamento | I11: Post 08 | J11: Carrossel 4:5 (1080 × 1350), 8 slides. | K11: Como funciona o cuidado na prática? | L11: Retomar o Escritório do Cuidado pela experiência de quem é atendido, sem repetir a apresentação. | M11: O plano é possível e humano: cabe na rotina real de cada pessoa. | N11: Colaboradores; RH | O11: Vem de: P06 ("na semana que vem, como isso acontece na prática"). Leva para: P08, as quatro frentes que sustentam essa jornada. | P11: Card de interface com o plano da Clara (modelo M3). Sem foto de pessoa: a personagem aparece só no texto e no card. Rodapé "História ilustrativa. Personagem fictícia." em todos os slides com a Clara. | Q11: Tipografia, card do plano e ícones finos. Se a decisão for não usar personagem: mesma jornada falando direto com quem lê ("você chega, a gente pergunta..."). | R11: Como funciona o cuidado na prática? A gente mostra pela história da Clara. Ela chegou ao Escritório do Cuidado e a primeira pergunta foi: o que é importante para você? A resposta dela: "quero voltar a ter energia para brincar com meu filho". Depois vieram o questionário de estilo de vida e as medições, um plano com três ações pequenas que cabem no turno dela e o acompanhamento de perto. Se a vida muda, o plano muda junto. História ilustrativa, com personagem fictícia. E para você, o que é importante? Conta pra gente nos comentários. #fairhealth #escritoriodocuidado #medicinadoestilodevida #saudecorporativa #cuidadocentradonapessoa | S11: Caixa de perguntas: "O que é importante para você hoje?". | T11: Dinâmica das consultas (essencia.md); one-pager (11/10). Personagem fictícia. | U11: Decidir: com a Clara (personagem fictícia, sinalizada) ou sem personagem. A responsável médica confere as etapas (questionário, bioimpedância, smartband por 48 h, retorno) e se o plano da Clara é plausível. Nome do plano: "Plano de Cuidado Individualizado". | V11: =Cronograma!K11 -> Aguardando decisão
A12: P08 | B12: =Cronograma!B12 -> 46330 | C12: =Cronograma!C12 -> qua | D12: =Cronograma!D12 -> 3 | E12: =Cronograma!E12 -> 3 · Compreensão | F12: =Cronograma!F12 -> Reel | G12: =Cronograma!G12 -> Quatro frentes, um cuidado conectado | H12: Medicina do Estilo de Vida, Escritório do Cuidado, plataforma e wearables | I12: Post 09 | J12: Reel 9:16 (1080 × 1920), 25 a 30 s, motion. Capa 4:5. | K12: Quatro frentes. Um cuidado só. | L12: Mostrar que as quatro frentes funcionam juntas, ligadas pelo fio contínuo. | M12: Não são quatro produtos: é um cuidado só. | N12: RH; RI e C-Level | O12: Vem de: P07, a jornada de uma pessoa. Leva para: P09, de onde vem esse método. | P12: Motion em Tiffany e verde. O fio contínuo (creme) passa por quatro pontos; em cada ponto, um ícone linear fino e o nome da frente. No fim, o fio se fecha em volta da palavra "pessoa". Sem pessoas em cena. | Q12: Motion no Canva ou After Effects, ícones lineares finos, trilha calma. | R12: Não são quatro produtos soltos. É um cuidado só. O Escritório do Cuidado leva médicos e psicólogos para dentro da empresa. O Programa de Medicina do Estilo de Vida leva informação para todos. A plataforma digital guarda o histórico e as metas de cada pessoa. E os wearables ajudam a acompanhar a rotina entre uma consulta e outra. Juntas, as quatro frentes fazem o cuidado continuar depois que a consulta acaba. #fairhealth #saudecorporativa #medicinadoestilodevida #escritoriodocuidado #tecnologiaemsaude | S12: Quiz: "Qual destas frentes acompanha a rotina entre as consultas?" (resposta: wearables). | T12: One-pager (11/10): as quatro frentes. | U12: Nomes das frentes iguais aos do one-pager e do post "O que é a fairhealth?". | V12: =Cronograma!K12 -> Roteiro em revisão
A13: P09 | B13: =Cronograma!B13 -> 46332 | C13: =Cronograma!C13 -> sex | D13: =Cronograma!D13 -> 3 | E13: =Cronograma!E13 -> 4 · Confiança | F13: =Cronograma!F13 -> Carrossel | G13: =Cronograma!G13 -> Uma história de cuidado que começou em 2009 | H13: Linha do tempo da metodologia e evolução até a FairHealth | I13: Post 10 | J13: Carrossel 4:5 (1080 × 1350), 8 slides. | K13: A fairhealth é nova. O jeito de cuidar, não. | L13: Mostrar que o método tem base, trajetória e evidência (o P02 contou o porquê; este mostra o como). | M13: O método tem base internacional, trajetória e evidência. | N13: RH; Medicina do Trabalho; RI e C-Level | O13: Vem de: P08, as quatro frentes. Leva para: P10, os resultados na prática. | P13: Linha do tempo no fio contínuo, um marco por slide, ano grande e fino. Capa Tiffany; slides alternando verde e Tiffany. | Q13: Só tipografia e o fio. | R13: A fairhealth é nova. O jeito de cuidar, não. Ele começou em 2009, num hospital, com o Escritório do Paciente, e acompanhou a evolução das grandes metas da saúde: qualidade, acesso e custo; depois o cuidado com quem cuida; depois a equidade. No hospital onde tudo começou, as reclamações caíram de 34 para cerca de 20 por mês. Em 2024, o modelo chegou às empresas como Escritório do Cuidado. Desde 2009, a mesma ideia: a pessoa no centro do cuidado. #fairhealth #saudecorporativa #experienciadopaciente #cuidadocentradonapessoa #escritoriodocuidado | S13: Slide do caso do hospital com a pergunta "Você conhecia os Aims da saúde?". | T13: essencia.md ("De onde veio"): IHI Triple Aim (2007 e 2008), Escritório do Paciente (2009), Quadruple Aim (2014), Quintuple Aim (2021), Escritório do Cuidado (2024 e 2025); caso do hospital (reclamações de 34 para cerca de 20 por mês, apresentado em congresso). | U13: Conferir as datas e a descrição de cada Aim. Números do caso liberados e sempre sem o nome do hospital. "Validado no SUS" fica de fora até ter fonte. | V13: =Cronograma!K13 -> Roteiro em revisão
A14: P10 | B14: =Cronograma!B14 -> 46335 | C14: =Cronograma!C14 -> seg | D14: =Cronograma!D14 -> 4 | E14: =Cronograma!E14 -> 4 · Confiança | F14: =Cronograma!F14 -> Reel | G14: =Cronograma!G14 -> Cuidado na prática: experiências e resultados reais | H14: Evidências e resultados documentados, contados pelo Dr. Ronald | I14: Post 11 | J14: Reel 9:16 (1080 × 1920), 35 a 45 s. Capa 4:5. | K14: Ninguém volta a um lugar onde não se sentiu cuidado. | L14: Provar com números liberados que as pessoas usam e voltam, na voz de um médico. | M14: A prova de que as pessoas usam e voltam. Ninguém volta a um lugar onde não se sentiu cuidado. | N14: RH; Diretoria financeira | O14: Vem de: P09, a trajetória do método. Leva para: P11, a ciência por trás desse jeito de cuidar. | P14: Mesmo cenário e enquadramento do P01, para a série ficar reconhecível. Números na tela em verde-escuro sobre Tiffany, calmos, com a fonte em texto pequeno. Legendas sempre. | Q14: Gravado no mesmo dia que o P01. Autorização de uso de imagem. | R14: Ninguém volta a um lugar onde não se sentiu cuidado. Numa indústria que atendemos, no primeiro semestre de 2026, 8 em cada 10 pessoas voltaram para mais de um atendimento, e a adesão chegou a 98%. O Dr. Ronald conta por que isso acontece: o cuidado está perto, começa por uma conversa e é feito para cada pessoa. #fairhealth #saudecorporativa #medicinapreventiva #escritoriodocuidado #gestaodepessoas | S14: Repost com o número "8 em cada 10" e a caixa de perguntas "Quer saber como isso funciona na sua empresa?". | T14: Dados internos de um cliente do setor industrial, 1º semestre de 2026 (liberados): 81,3% voltaram para 2 ou mais atendimentos; adesão de 98%. Sempre agregado e sem o nome da empresa. | U14: Só números liberados, sempre "uma indústria que atendemos", sem o nome. Confirmar a fonte da adesão de 98%. | V14: =Cronograma!K14 -> Roteiro em revisão
A15: P11 | B15: =Cronograma!B15 -> 46337 | C15: =Cronograma!C15 -> qua | D15: =Cronograma!D15 -> 4 | E15: =Cronograma!E15 -> 4 · Confiança | F15: =Cronograma!F15 -> Carrossel | G15: =Cronograma!G15 -> Estilo de vida também é tratamento sério | H15: O que a ciência mostra sobre mudar a rotina, na semana do Dia Mundial do Diabetes | I15: Extra | J15: Carrossel 4:5 (1080 × 1350), 7 slides. | K15: Estilo de vida também é tratamento sério. | L15: Mostrar a base científica da Medicina do Estilo de Vida com um estudo clássico, na semana do Dia Mundial do Diabetes (14/11). | M15: A Medicina do Estilo de Vida tem ciência por trás. O cuidado começa pela rotina porque a rotina importa. | N15: Colaboradores; RH; Medicina do Trabalho | O15: Vem de: P10, os resultados. Leva para: P12, o convite para o RH. | P15: Modelo de dado com fonte (M6), suave, nos slides 4 e 5. Números em verde-escuro, sem destaque alarmista. Capa Tiffany. | Q15: Só tipografia e o fio. | R15: Mudar a rotina faz diferença de verdade? A ciência responde. Num estudo clássico, publicado no New England Journal of Medicine, mais de 3 mil adultos com risco aumentado de diabetes tipo 2 foram acompanhados por quase 3 anos. Quem mudou a rotina, com alimentação e 150 minutos de atividade física por semana, teve 58% menos casos novos do que o grupo placebo. Não é promessa individual. É a ciência mostrando que a rotina importa, e é por isso que o nosso cuidado começa nela. Neste sábado, 14/11, é o Dia Mundial do Diabetes. Fonte: Diabetes Prevention Program Research Group, N Engl J Med, 2002. #fairhealth #medicinadoestilodevida #diamundialdodiabetes #saudecorporativa #prevencao | S15: No sábado, 14/11, story do Dia Mundial do Diabetes com o slide 4 e o link para o post. | T15: Diabetes Prevention Program Research Group. Reduction in the incidence of type 2 diabetes with lifestyle intervention or metformin. N Engl J Med. 2002;346(6):393-403. doi:10.1056/NEJMoa012512 | U15: A responsável médica valida a leitura do estudo. Deixar claro que o estudo foi com adultos com risco aumentado e que não é promessa individual. | V15: =Cronograma!K15 -> Roteiro pronto
A16: P12 | B16: =Cronograma!B16 -> 46339 | C16: =Cronograma!C16 -> sex | D16: =Cronograma!D16 -> 4 | E16: =Cronograma!E16 -> 4 · Confiança | F16: =Cronograma!F16 -> Carrossel | G16: =Cronograma!G16 -> Como levar a FairHealth para sua empresa? | H16: Encerramento da apresentação inicial com orientação para o RH | I16: Post 12 | J16: Carrossel 4:5 (1080 × 1350), 6 slides. | K16: Como levar a fairhealth para a sua empresa? | L16: Fechar a apresentação inicial com um caminho claro e simples para o RH. | M16: Um caminho claro para o RH, sem preço e sem promessa. | N16: RH; Diretoria financeira | O16: Vem de: P11, a ciência por trás do cuidado. Recapitula os 4 blocos e fecha a programação. | P16: Passos numerados no fio contínuo. Capa Tiffany. Último slide com logo e slogan. | Q16: Só tipografia e o fio. | R16: Nas últimas semanas, a gente contou quem é a fairhealth, por que cuidar antes, como o cuidado funciona na prática e por que acreditar nele. Se você é de RH e quer levar esse cuidado para a sua empresa, o caminho tem três passos: um diagnóstico para entender as necessidades do seu time, uma proposta personalizada e a implementação, com os primeiros atendimentos. Fale com a gente pelo direct. Fazemos o certo pelos motivos certos. #fairhealth #saudecorporativa #rh #gestaodepessoas #medicinapreventiva | S16: Sequência com os 3 passos e o adesivo de link ou "Mande uma mensagem". | T16: One-pager (11/10): "Vem com a gente!" (diagnóstico, proposta personalizada, implementação). | U16: "Diagnóstico" sem "gratuito". Não citar prazos de cada etapa. Definir quem responde o direct. | V16: =Cronograma!K16 -> Roteiro em revisão

Sheet Roteiros
A1: Roteiros: cena por cena (reels) e slide por slide (carrosséis)
A2: Título, formato e data vêm da aba Cronograma pelo ID. "Fala" só existe nos reels falados.
A4: ID | B4: Post | C4: Formato | D4: Publicação | E4: Parte | F4: Texto na tela / no slide | G4: Fala (reels) | H4: Visual e direção | I4: Observação
A5: P01 | B5: =INDEX(Cronograma!$G$5:$G$16,MATCH(A5,Cronograma!$A$5:$A$16,0)) -> Quem somos, na voz do Dr. Ronald | C5: =INDEX(Cronograma!$F$5:$F$16,MATCH(A5,Cronograma!$A$5:$A$16,0)) -> Reel | D5: =INDEX(Cronograma!$B$5:$B$16,MATCH(A5,Cronograma!$A$5:$A$16,0)) -> 46314 | E5: 0 a 3 s | F5: O que é a fairhealth, em 40 segundos | G5: Se você chegou agora, em 40 segundos eu te conto o que é a fairhealth. | H5: Plano médio, olhar na câmera. Texto entra em cima. | I5: Gancho: a frase precisa vir antes de qualquer apresentação.
A6: P01 | B6: =INDEX(Cronograma!$G$5:$G$16,MATCH(A6,Cronograma!$A$5:$A$16,0)) -> Quem somos, na voz do Dr. Ronald | C6: =INDEX(Cronograma!$F$5:$F$16,MATCH(A6,Cronograma!$A$5:$A$16,0)) -> Reel | D6: =INDEX(Cronograma!$B$5:$B$16,MATCH(A6,Cronograma!$A$5:$A$16,0)) -> 46314 | E6: 3 a 12 s | F6: Medicina preventiva, dentro da empresa | G6: A fairhealth leva medicina preventiva para dentro da empresa. Médicos e psicólogos perto de quem trabalha, com um plano de cuidado para cada pessoa. | H6: Mesmo plano, leve aproximação no fim.
A7: P01 | B7: =INDEX(Cronograma!$G$5:$G$16,MATCH(A7,Cronograma!$A$5:$A$16,0)) -> Quem somos, na voz do Dr. Ronald | C7: =INDEX(Cronograma!$F$5:$F$16,MATCH(A7,Cronograma!$A$5:$A$16,0)) -> Reel | D7: =INDEX(Cronograma!$B$5:$B$16,MATCH(A7,Cronograma!$A$5:$A$16,0)) -> 46314 | E7: 12 a 22 s | F7: O que é importante para você? | G7: Esse cuidado acontece no Escritório do Cuidado. E começa sempre com a mesma pergunta: o que é importante para você? | H7: Corte para plano mais fechado na pergunta. | I7: A pergunta é o elemento da marca: destaque em negrito itálico.
A8: P01 | B8: =INDEX(Cronograma!$G$5:$G$16,MATCH(A8,Cronograma!$A$5:$A$16,0)) -> Quem somos, na voz do Dr. Ronald | C8: =INDEX(Cronograma!$F$5:$F$16,MATCH(A8,Cronograma!$A$5:$A$16,0)) -> Reel | D8: =INDEX(Cronograma!$B$5:$B$16,MATCH(A8,Cronograma!$A$5:$A$16,0)) -> 46314 | E8: 22 a 32 s | F8: Um plano que cabe na rotina | G8: A partir da resposta, a gente monta um plano que cabe na rotina e acompanha de perto. | H8: Volta ao plano médio.
A9: P01 | B9: =INDEX(Cronograma!$G$5:$G$16,MATCH(A9,Cronograma!$A$5:$A$16,0)) -> Quem somos, na voz do Dr. Ronald | C9: =INDEX(Cronograma!$F$5:$F$16,MATCH(A9,Cronograma!$A$5:$A$16,0)) -> Reel | D9: =INDEX(Cronograma!$B$5:$B$16,MATCH(A9,Cronograma!$A$5:$A$16,0)) -> 46314 | E9: 32 a 40 s | F9: Tudo começou num hospital, em 2009 | G9: Mas essa pergunta não nasceu numa empresa. Ela nasceu num hospital, em 2009. No próximo post, eu te conto essa história. | H9: Fecha com o logo sobre fundo Tiffany nos 2 últimos segundos. | I9: Ponte para o P02.
A10: P02 | B10: =INDEX(Cronograma!$G$5:$G$16,MATCH(A10,Cronograma!$A$5:$A$16,0)) -> Por que a FairHealth existe? | C10: =INDEX(Cronograma!$F$5:$F$16,MATCH(A10,Cronograma!$A$5:$A$16,0)) -> Carrossel | D10: =INDEX(Cronograma!$B$5:$B$16,MATCH(A10,Cronograma!$A$5:$A$16,0)) -> 46316 | E10: Slide 1 · capa | F10: Antes de chegar às empresas, nossa história começou em um hospital. 2009 → hoje | H10: Luz tiffany sobre verde-noite. O fio nasce num ponto embaixo, à esquerda. | I10: Etiqueta "Nossa história".
A11: P02 | B11: =INDEX(Cronograma!$G$5:$G$16,MATCH(A11,Cronograma!$A$5:$A$16,0)) -> Por que a FairHealth existe? | C11: =INDEX(Cronograma!$F$5:$F$16,MATCH(A11,Cronograma!$A$5:$A$16,0)) -> Carrossel | D11: =INDEX(Cronograma!$B$5:$B$16,MATCH(A11,Cronograma!$A$5:$A$16,0)) -> 46316 | E11: Slide 2 · o início | F11: 2009 Dentro de um hospital, surgiu o Escritório do Paciente. Um modelo de cuidado que colocava a escuta e as necessidades de cada pessoa no centro da atenção. | H11: Fundo Tiffany, "2009" grande em verde-escuro. Ponto no fio marcado "2009".
A12: P02 | B12: =INDEX(Cronograma!$G$5:$G$16,MATCH(A12,Cronograma!$A$5:$A$16,0)) -> Por que a FairHealth existe? | C12: =INDEX(Cronograma!$F$5:$F$16,MATCH(A12,Cronograma!$A$5:$A$16,0)) -> Carrossel | D12: =INDEX(Cronograma!$B$5:$B$16,MATCH(A12,Cronograma!$A$5:$A$16,0)) -> 46316 | E12: Slide 3 · a essência | F12: Por trás de cada atendimento, existe uma pessoa. Com a sua própria história, hábitos, necessidades e prioridades. Por isso, escutar sempre foi parte essencial da nossa maneira de cuidar. | H12: Fundo verde, palavra-chave em Tiffany.
A13: P02 | B13: =INDEX(Cronograma!$G$5:$G$16,MATCH(A13,Cronograma!$A$5:$A$16,0)) -> Por que a FairHealth existe? | C13: =INDEX(Cronograma!$F$5:$F$16,MATCH(A13,Cronograma!$A$5:$A$16,0)) -> Carrossel | D13: =INDEX(Cronograma!$B$5:$B$16,MATCH(A13,Cronograma!$A$5:$A$16,0)) -> 46316 | E13: Slide 4 · evolução | F13: Com o tempo, essa forma de cuidar evoluiu. E surgiu a possibilidade de aproximar o cuidado preventivo de um lugar que faz parte da rotina das pessoas: o trabalho. | H13: Fundo Tiffany. O fio sobe. | I13: "Milhões de pessoas" saiu: número sem fonte.
A14: P02 | B14: =INDEX(Cronograma!$G$5:$G$16,MATCH(A14,Cronograma!$A$5:$A$16,0)) -> Por que a FairHealth existe? | C14: =INDEX(Cronograma!$F$5:$F$16,MATCH(A14,Cronograma!$A$5:$A$16,0)) -> Carrossel | D14: =INDEX(Cronograma!$B$5:$B$16,MATCH(A14,Cronograma!$A$5:$A$16,0)) -> 46316 | E14: Slide 5 · hoje | F14: Hoje, essa filosofia está presente na fairhealth. Levamos cuidado individualizado, prevenção e acompanhamento para dentro das empresas, conectando profissionais de saúde, conhecimento e tecnologia. O Escritório do Paciente virou o Escritório do Cuidado. | H14: Fundo verde. Ponto no fio marcado "hoje".
A15: P02 | B15: =INDEX(Cronograma!$G$5:$G$16,MATCH(A15,Cronograma!$A$5:$A$16,0)) -> Por que a FairHealth existe? | C15: =INDEX(Cronograma!$F$5:$F$16,MATCH(A15,Cronograma!$A$5:$A$16,0)) -> Carrossel | D15: =INDEX(Cronograma!$B$5:$B$16,MATCH(A15,Cronograma!$A$5:$A$16,0)) -> 46316 | E15: Slide 6 · o propósito | F15: Os lugares mudaram. A essência do cuidado permanece. Da experiência hospitalar ao ambiente corporativo, seguimos com um mesmo princípio: o cuidado começa pela pessoa. | H15: Fundo Tiffany. O fio termina no logo.
A16: P03 | B16: =INDEX(Cronograma!$G$5:$G$16,MATCH(A16,Cronograma!$A$5:$A$16,0)) -> Cuidar da saúde não deveria começar quando algo vai mal | C16: =INDEX(Cronograma!$F$5:$F$16,MATCH(A16,Cronograma!$A$5:$A$16,0)) -> Carrossel | D16: =INDEX(Cronograma!$B$5:$B$16,MATCH(A16,Cronograma!$A$5:$A$16,0)) -> 46318 | E16: Slide 1 · capa | F16: Cuidar da saúde não deveria começar quando algo vai mal. Arraste e volte no tempo → | H16: Fundo Tiffany. O fio começa na borda direita.
A17: P03 | B17: =INDEX(Cronograma!$G$5:$G$16,MATCH(A17,Cronograma!$A$5:$A$16,0)) -> Cuidar da saúde não deveria começar quando algo vai mal | C17: =INDEX(Cronograma!$F$5:$F$16,MATCH(A17,Cronograma!$A$5:$A$16,0)) -> Carrossel | D17: =INDEX(Cronograma!$B$5:$B$16,MATCH(A17,Cronograma!$A$5:$A$16,0)) -> 46318 | E17: Slide 2 | F17: O afastamento. É aqui que, muitas vezes, o cuidado começa. | H17: Fundo verde. Primeiro ponto no fio: "afastamento".
A18: P03 | B18: =INDEX(Cronograma!$G$5:$G$16,MATCH(A18,Cronograma!$A$5:$A$16,0)) -> Cuidar da saúde não deveria começar quando algo vai mal | C18: =INDEX(Cronograma!$F$5:$F$16,MATCH(A18,Cronograma!$A$5:$A$16,0)) -> Carrossel | D18: =INDEX(Cronograma!$B$5:$B$16,MATCH(A18,Cronograma!$A$5:$A$16,0)) -> 46318 | E18: Slide 3 | F18: Antes dele, teve um atestado. | H18: Fundo Tiffany. Segundo ponto: "atestado".
A19: P03 | B19: =INDEX(Cronograma!$G$5:$G$16,MATCH(A19,Cronograma!$A$5:$A$16,0)) -> Cuidar da saúde não deveria começar quando algo vai mal | C19: =INDEX(Cronograma!$F$5:$F$16,MATCH(A19,Cronograma!$A$5:$A$16,0)) -> Carrossel | D19: =INDEX(Cronograma!$B$5:$B$16,MATCH(A19,Cronograma!$A$5:$A$16,0)) -> 46318 | E19: Slide 4 | F19: Antes do atestado, teve uma semana pesada. | H19: Fundo verde. Terceiro ponto: "semana pesada".
