Workbook

Sheet Cronograma
A1: Cronograma de posts · FAIR HEALTH · 90 dias
A2: Início (segunda da semana 1): | D2: 46300 | E2: Mude esta data e todas as datas se ajustam. Horário padrão: 7:30.
A4: ID | B4: Semana | C4: Dia | D4: Data | E4: Tema da semana | F4: Pauta | G4: Objetivo | H4: Formato | I4: Especificação | J4: Gancho (capa ou 2 s iniciais) | K4: Roteiro / conteúdo | L4: Legenda | M4: CTA | N4: Hashtags | O4: Quem aparece / fotos | P4: Status | Q4: Observações
A5: 1 | B5: 1 | C5: Segunda | D5: =$D$2+(B5-1)*7+MATCH(C5,Listas!$A$1:$A$5,0)-1 | E5: Quem somos | F5: Reel manifesto: Bem-vindos à FAIR HEALTH | G5: Propósito e posicionamento | H5: Reel | I5: 9:16 · 1080x1920 · 30–45 s · texto na tela desde o 1º quadro | J5: O afastamento não começa no atestado. | K5: 0–2 s · "O afastamento não começa no atestado." Imagem: porta do Escritório do Cuidado se abrindo. Tela: O AFASTAMENTO NÃO COMEÇA NO ATESTADO 2–7 s · "Começa antes: no sono ruim, no estresse que acumula, na dor que ninguém trata." Imagem: detalhes de mãos, caneca, relógio. Tela: COMEÇA NA ROTINA 7–15 s · "A FAIR HEALTH existe para cuidar antes. Médicos, psicólogos e assistentes sociais dentro da empresa, perto de quem precisa." Imagem: time no espaço. Tela: CUIDAR ANTES 15–22 s · "E tudo começa com uma pergunta: o que importa para você?" Imagem: cada integrante olha para a câmera. Tela: O QUE IMPORTA PARA VOCÊ? 22–30 s · "Conhecemos a rotina, os objetivos e o contexto de cada pessoa. E acompanhamos com ciência, tecnologia e dados." Imagem: smartband, bioimpedância, tela genérica 30–35 s · "Bem-vindos à FAIR HEALTH." Logo + assinatura "O cuidado: o que importa para você?" | L5: O afastamento não começa no atestado. Começa muito antes, na rotina: no sono que não descansa, no estresse que vai acumulando, na dor que ninguém teve tempo de tratar. A FAIR HEALTH nasceu para cuidar antes. Levamos médicos, psicólogos e assistentes sociais para dentro das empresas, com um plano de cuidado feito para cada pessoa, baseado na Medicina do Estilo de Vida. E tudo começa com uma pergunta: o que importa para você? Nos próximos dias, você vai conhecer quem cuida por aqui. #fairhealth #saudecorporativa #cuidadocentradonapessoa #medicinadoestilodevida #saudedotrabalhador | M5: Siga para conhecer o time | N5: #fairhealth #saudecorporativa #cuidadocentradonapessoa #medicinadoestilodevida #saudedotrabalhador | O5: Time todo (vozes e imagens); espaço; mãos com smartband | P5: Em produção | Q5: Fixar no perfil. Stories: repost + caixa de perguntas "O que importa para você?".
A6: 2 | B6: 1 | C6: Terça | D6: =$D$2+(B6-1)*7+MATCH(C6,Listas!$A$1:$A$5,0)-1 | E6: Quem somos | F6: Carrossel de apresentação: Bem-vindos à FAIR HEALTH | G6: Propósito e posicionamento | H6: Carrossel | I6: 4:5 · 1080x1350 · 8–10 slides · slide 2 entendível sozinho | J6: O afastamento não começa no atestado. (sub: Bem-vindos à FAIR HEALTH) | K6: 1 · CAPA · Verde-escuro. BEM-VINDOS À FAIR HEALTH pequeno no topo. O afastamento não começa no atestado. / Por que a FAIR HEALTH existe. Flecha. 2 · Quando vira atestado, o adoecimento já começou faz tempo. 3 · O RH costuma enxergar só o fim da história: atestado, afastamento e sinistro no plano de saúde. 4 · E o começo é pequeno: sono ruim, estresse acumulado, um hábito que escorrega, uma dor que ninguém trata. 5 · Por isso levamos o cuidado para dentro da empresa: médicos, psicólogos e assistentes sociais onde o time já está. 6 · E todo cuidado começa com uma pergunta: O que importa para você? Rotina, objetivos e contexto viram um plano de cuidado individual, baseado na Medicina do Estilo de Vida. 7 · E comprovamos com dados: o RH recebe relatórios anonimizados. Nenhum dado individual. 8 · RESUMO · Por que existimos: 1. O adoecimento começa antes do atestado. 2. O RH só vê o fim. 3. Cuidado precisa estar perto. 4. Cada pessoa tem um plano. 5. Comprovamos com dados. 9 · CTA · Siga @fairhealth.br e conheça quem cuida. | L6: E se o afastamento começar muito antes do atestado? Sono ruim, estresse acumulado, um hábito que escorrega, uma dor que ninguém trata. Nada disso aparece em relatório. Quando chega ao RH, já virou atestado, afastamento ou sinistro no plano de saúde. A FAIR HEALTH nasceu para mudar essa ordem na saúde corporativa: levar médicos, psicólogos e assistentes sociais para dentro da empresa e cuidar antes que o adoecimento vire afastamento. Cada cuidado começa com uma pergunta simples: o que importa para você? E, porque cuidado sem dado é só intenção, o RH acompanha tudo em relatórios anonimizados. #fairhealth #saudecorporativa #cuidadocentradonapessoa #medicinadoestilodevida #saudedotrabalhador | M6: Siga e conheça quem cuida | N6: #fairhealth #saudecorporativa #cuidadocentradonapessoa #medicinadoestilodevida #saudedotrabalhador | O6: Arte (fotos do espaço na capa e no slide 5) | P6: Em revisão | Q6: Arte pronta: instagram/posts/marca (9 slides, mesma capa do carrossel do time). Pronto para aprovação.
A7: 3 | B7: 1 | C7: Quarta | D7: =$D$2+(B7-1)*7+MATCH(C7,Listas!$A$1:$A$5,0)-1 | E7: Quem somos | F7: Carrossel: Nosso time (8 pessoas, sem cargos) | G7: Humanização e autoridade | H7: Carrossel | I7: 4:5 · 1080x1350 · 8–10 slides · slide 2 entendível sozinho | J7: Nosso time. (sub: Conheça quem cuida da saúde da sua empresa.) | K7: IDENTIDADE: fontes e cores da marca (Raleway, verde-escuro, verde-água). Da referência @conselhosdorh só a composição: retrato em tela cheia, nome no topo, bloco com linha vertical embaixo. Sem cargo. 1 · CAPA · Verde-escuro, sem foto. FAIR HEALTH pequeno no topo. "Nosso time." grande. Sub: Conheça quem cuida da saúde da sua empresa. Flecha para o lado. 2 · Marília · [FOTO em tela cheia] · nome grande no topo · bloco com linha verde-água: [pequena descrição] / O que é importante para você? [resposta] 3 · Nina · [FOTO em tela cheia] · nome grande no topo · bloco com linha verde-água: [pequena descrição] / O que é importante para você? [resposta] 4 · Ronald · [FOTO em tela cheia] · nome grande no topo · bloco com linha verde-água: [pequena descrição] / O que é importante para você? [resposta] 5 · Floriana · [FOTO em tela cheia] · nome grande no topo · bloco com linha verde-água: [pequena descrição] / O que é importante para você? [resposta] 6 · Renata · [FOTO em tela cheia] · nome grande no topo · bloco com linha verde-água: [pequena descrição] / O que é importante para você? [resposta] 7 · Liliane · [FOTO em tela cheia] · nome grande no topo · bloco com linha verde-água: [pequena descrição] / O que é importante para você? [resposta] 8 · Fernando · [FOTO em tela cheia] · nome grande no topo · bloco com linha verde-água: [pequena descrição] / O que é importante para você? [resposta] 9 · Charles · [FOTO em tela cheia] · nome grande no topo · bloco com linha verde-água: [pequena descrição] / O que é importante para você? [resposta] 10 · FECHAMENTO · Verde-escuro: Pessoas diferentes, um mesmo jeito de cuidar. E para você, o que é importante? Conta nos comentários. Logo. | L7: Por trás de todo cuidado, tem gente. Estas são as pessoas que fazem a FAIR HEALTH acontecer, cada uma com a sua história. Fizemos a todas a mesma pergunta que fazemos a quem cuidamos: o que é importante para você? As respostas estão no carrossel. E para você, o que é importante? #fairhealth #saudecorporativa #cuidadocentradonapessoa #medicinadoestilodevida #saudedotrabalhador | M7: Comente: e para você, o que é importante? | N7: #fairhealth #saudecorporativa #cuidadocentradonapessoa #medicinadoestilodevida #saudedotrabalhador | O7: 8 pessoas: Marília, Nina, Ronald, Floriana, Renata, Liliane, Fernando, Charles. Retrato individual vertical. | P7: Em revisão | Q7: Na aprovação, pedir a cada pessoa: 1) retrato vertical (luz natural, fundo real); 2) uma pequena descrição sobre si, sem cargo; 3) resposta curta a "O que é importante para você?". Confirmar CRM dos médicos com o Dr. Ronald. Arte: instagram/posts/time.
A8: 4 | B8: 1 | C8: Quinta | D8: =$D$2+(B8-1)*7+MATCH(C8,Listas!$A$1:$A$5,0)-1 | E8: Quem somos | F8: Por dentro: o time respondendo "O que importa para você?" em vídeo | G8: Pessoas, método, bastidores e prova | H8: Reel | I8: 9:16 · 1080x1920 · 30–45 s · texto na tela desde o 1º quadro | P8: A fazer
A9: 5 | B9: 1 | C9: Sexta | D9: =$D$2+(B9-1)*7+MATCH(C9,Listas!$A$1:$A$5,0)-1 | E9: Quem somos | F9: Como a FAIR HEALTH cuida: medir, cuidar, conscientizar, comprovar | G9: Explicar o modelo individualizado | H9: Carrossel | I9: 4:5 · 1080x1350 · 8–10 slides · slide 2 entendível sozinho | P9: A fazer | Q9: Base: arte pronta em instagram/posts/estreia (carrossel #3).
A10: 6 | B10: 2 | C10: Segunda | D10: =$D$2+(B10-1)*7+MATCH(C10,Listas!$A$1:$A$5,0)-1 | E10: Quem cuida | F10: O que importa para você? As respostas de quem nos segue (caixa de perguntas vira post) | G10: Marca, relacionamento e diferenciação | H10: Carrossel | I10: 4:5 · 1080x1350 · 8–10 slides · slide 2 entendível sozinho | P10: A fazer
A11: 7 | B11: 2 | C11: Terça | D11: =$D$2+(B11-1)*7+MATCH(C11,Listas!$A$1:$A$5,0)-1 | E11: Quem cuida | F11: 1 Minuto de Cuidado: como enxergamos o cuidado (com um profissional) | G11: Descoberta, educação e retenção | H11: Reel | I11: 9:16 · 1080x1920 · 30–45 s · texto na tela desde o 1º quadro | P11: A fazer
A12: 8 | B12: 2 | C12: Quarta | D12: =$D$2+(B12-1)*7+MATCH(C12,Listas!$A$1:$A$5,0)-1 | E12: Quem cuida | F12: Os pilares da saúde: os 7 pilares da Medicina do Estilo de Vida | G12: Apresentar MEV e iniciar série educativa | H12: Carrossel | I12: 4:5 · 1080x1350 · 8–10 slides · slide 2 entendível sozinho | P12: A fazer
A13: 9 | B13: 2 | C13: Quinta | D13: =$D$2+(B13-1)*7+MATCH(C13,Listas!$A$1:$A$5,0)-1 | E13: Quem cuida | F13: Por dentro da FAIR HEALTH: espaço, atendimento, tecnologia e acompanhamento | G13: Tangibilizar atendimento, tecnologia e acompanhamento | H13: Reel | I13: 9:16 · 1080x1920 · 30–45 s · texto na tela desde o 1º quadro | P13: A fazer
A14: 10 | B14: 2 | C14: Sexta | D14: =$D$2+(B14-1)*7+MATCH(C14,Listas!$A$1:$A$5,0)-1 | E14: Quem cuida | F14: O que o Escritório do Cuidado entrega à empresa | G14: Saúde corporativa, NR-1 e B2B | H14: Carrossel | I14: 4:5 · 1080x1350 · 8–10 slides · slide 2 entendível sozinho | P14: A fazer
A15: 11 | B15: 3 | C15: Segunda | D15: =$D$2+(B15-1)*7+MATCH(C15,Listas!$A$1:$A$5,0)-1 | E15: Como cuidamos | F15: Plano de cuidado individualizado: avaliação, metas e acompanhamento | G15: Marca, relacionamento e diferenciação | H15: Carrossel | I15: 4:5 · 1080x1350 · 8–10 slides · slide 2 entendível sozinho | P15: A fazer
A16: 12 | B16: 3 | C16: Terça | D16: =$D$2+(B16-1)*7+MATCH(C16,Listas!$A$1:$A$5,0)-1 | E16: Como cuidamos | F16: Medicina do Estilo de Vida em 1 minuto | G16: Descoberta, educação e retenção | H16: Reel | I16: 9:16 · 1080x1920 · 30–45 s · texto na tela desde o 1º quadro | P16: A fazer
A17: 13 | B17: 3 | C17: Quarta | D17: =$D$2+(B17-1)*7+MATCH(C17,Listas!$A$1:$A$5,0)-1 | E17: Como cuidamos | F17: Escritório do Cuidado: o que é e como funciona | G17: Autoridade, salvamento e compartilhamento | H17: Carrossel | I17: 4:5 · 1080x1350 · 8–10 slides · slide 2 entendível sozinho | P17: A fazer
A18: 14 | B18: 3 | C18: Quinta | D18: =$D$2+(B18-1)*7+MATCH(C18,Listas!$A$1:$A$5,0)-1 | E18: Como cuidamos | F18: Uma consulta por dentro: da anamnese ao plano | G18: Pessoas, método, bastidores e prova | H18: Reel | I18: 9:16 · 1080x1920 · 30–45 s · texto na tela desde o 1º quadro | P18: A fazer
A19: 15 | B19: 3 | C19: Sexta | D19: =$D$2+(B19-1)*7+MATCH(C19,Listas!$A$1:$A$5,0)-1 | E19: Como cuidamos | F19: O que o RH recebe: relatórios anonimizados e indicadores do grupo | G19: Saúde corporativa, NR-1 e B2B | H19: Carrossel | I19: 4:5 · 1080x1350 · 8–10 slides · slide 2 entendível sozinho | P19: A fazer
A20: 16 | B20: 4 | C20: Segunda | D20: =$D$2+(B20-1)*7+MATCH(C20,Listas!$A$1:$A$5,0)-1 | E20: Alimentação e hidratação | F20: O que atrapalha sua alimentação no trabalho? (enquete) | G20: Marca, relacionamento e diferenciação | H20: Carrossel | I20: 4:5 · 1080x1350 · 8–10 slides · slide 2 entendível sozinho | P20: A fazer
A21: 17 | B21: 4 | C21: Terça | D21: =$D$2+(B21-1)*7+MATCH(C21,Listas!$A$1:$A$5,0)-1 | E21: Alimentação e hidratação | F21: Hidratação no expediente | G21: Descoberta, educação e retenção | H21: Reel | I21: 9:16 · 1080x1920 · 30–45 s · texto na tela desde o 1º quadro | P21: A fazer
... A69: 65 | B69: 13 | C69: Sexta | D69: =$D$2+(B69-1)*7+MATCH(C69,Listas!$A$1:$A$5,0)-1 | E69: FAIR HEALTH para empresas | F69: Diagnóstico gratuito: comente CUIDADO | G69: Saúde corporativa, NR-1 e B2B | H69: Carrossel | I69: 4:5 · 1080x1350 · 8–10 slides · slide 2 entendível sozinho | P69: A fazer

Sheet Novembro
A1: Calendário de novembro 2026 · FAIR HEALTH
A2: Tema do mês: da intenção à evidência. Outubro mostrou quem somos e como cuidamos; novembro prova que funciona e abre a conversa com o RH (janela de orçamento 2027). Ritmo: até 5 posts por semana às 7:30, com 2 Reels por semana; feriados sem post.
A4: Data | B4: Dia | C4: Semana | D4: Tema da semana | E4: Origem (90 dias) | F4: Pauta | G4: Objetivo | H4: Formato | I4: Especificação | J4: Gancho (capa ou 2 s iniciais) | K4: Roteiro / conteúdo | L4: Legenda | M4: CTA | N4: Hashtags | O4: Quem aparece / fotos | P4: Status | Q4: Observações
A5: 46327 | B5: Domingo | C5: — | D5: Abertura do mês | E5: — | F5: Stories: Novembro Azul começa hoje | G5: Abrir o mês e anunciar o tema | H5: Stories | I5: 9:16 · 1080x1920 · sequência de 3 a 5 telas com figurinha | J5: Novembro é mês de falar de saúde do homem. | M5: Figurinha de pergunta: "O que te faz adiar uma consulta?" | N5: — | O5: Arte (logo coração) | P5: A fazer | Q5: Agendar na sexta 30/10. As respostas da caixa alimentam o Reel de 03/11.
A6: 46328 | B6: Segunda | C6: — | D6: Feriado: Finados | E6: — | F6: Sem publicação | G6: — | H6: — | I6: — | J6: — | M6: — | N6: — | O6: — | P6: — | Q6: Feriado nacional. Público de RH fora do ar.
A7: 46329 | B7: Terça | C7: 1 | D7: Novembro Azul e movimento | E7: NOVO | F7: 1 Minuto de Cuidado: por que o homem só vai ao médico quando dói | G7: Descoberta, educação e retenção | H7: Reel | I7: 9:16 · 1080x1920 · 30–45 s · texto na tela desde o 1º quadro | J7: Ele só vai ao médico quando dói. | M7: Mande para alguém que está adiando a consulta | N7: #fairhealth #novembroazul #saudedohomem #saudecorporativa #prevencao | O7: Dr. Ronald para a câmera | P7: A fazer | Q7: Abre a campanha. Sem números sem fonte e sem falar de exame específico como promessa. Revisão técnica do Dr. Ronald. Stories do dia: enquete de movimento (era o ID 21).
A8: 46330 | B8: Quarta | C8: 1 | D8: Novembro Azul e movimento | E8: ID 23 | F8: Pilar 2: Atividade física | G8: Autoridade, salvamento e compartilhamento | H8: Carrossel | I8: 4:5 · 1080x1350 · 8–10 slides · slide 2 entendível sozinho | J8: Movimento não precisa caber na academia. | M8: Salve para lembrar na próxima pausa | N8: #fairhealth #medicinadoestilodevida #saudedotrabalhador #prevencao #saudecorporativa | O8: Arte estilo pilares (duotone, cor do pilar) | P8: A fazer | Q8: Série 7 pilares.
A9: 46331 | B9: Quinta | C9: 1 | D9: Novembro Azul e movimento | E9: ID 24 | F9: Bioimpedância: o que ela mostra | G9: Pessoas, método, bastidores e prova | H9: Reel | I9: 9:16 · 1080x1920 · 30–45 s · texto na tela desde o 1º quadro | J9: A balança não conta a história toda. | M9: Siga para ver como cuidamos | N9: #fairhealth #medicinadoestilodevida #saudedotrabalhador #prevencao #saudecorporativa | O9: Profissional do time + aparelho no espaço (sem colaborador atendido) | P9: A fazer | Q9: Mostrar o aparelho e a leitura genérica. Nenhum dado real na tela.
A10: 46332 | B10: Sexta | C10: 1 | D10: Novembro Azul e movimento | E10: NOVO (no lugar do ID 25) | F10: Novembro Azul na empresa: o que vai além do laço azul | G10: Saúde corporativa, NR-1 e B2B | H10: Carrossel | I10: 4:5 · 1080x1350 · 8–10 slides · slide 2 entendível sozinho | J10: Novembro Azul não cabe em um mês. | M10: Mande para quem cuida das pessoas na sua empresa | N10: #fairhealth #novembroazul #saudedohomem #saudecorporativa #prevencao | O10: Arte institucional (fairedu) | P10: A fazer | Q10: Mensagem para o RH: campanha de um mês não muda adesão; cuidado perto do time, o ano inteiro, sim. Gancho para o Escritório do Cuidado.
A11: 46333 | B11: Sábado | C11: — | D11: — | E11: — | F11: — | G11: — | H11: — | I11: — | J11: — | M11: — | N11: — | O11: — | P11: — | Q11: Fim de semana.
A12: 46334 | B12: Domingo | C12: — | D12: — | E12: — | F12: — | G12: — | H12: — | I12: — | J12: — | M12: — | N12: — | O12: — | P12: — | Q12: Fim de semana.
A13: 46335 | B13: Segunda | C13: 2 | D13: Sono e prova: Chemitec | E13: ID 48 (antecipado de 09/12) | F13: Adesão e retorno: Chemitec, 1º semestre de 2026 | G13: Autoridade, salvamento e compartilhamento | H13: Carrossel | I13: 4:5 · 1080x1350 · 8–10 slides · slide 2 entendível sozinho | J13: 98% de adesão. Veja como. | M13: Comente CUIDADO para saber como funcionaria na sua empresa | N13: #fairhealth #saudecorporativa #gestaodepessoas #absenteismo #rh | O13: Arte institucional; logo círculo | P13: A fazer | Q13: Números liberados: 161 atendimentos, 48 colaboradores atendidos (98% de adesão), 81,3% voltaram para 2 ou mais atendimentos, 46 smartbands. Sempre agregado. Confirmar se a Chemitec topa coautoria (Collab). Stories: enquete "Como você dormiu esta semana?" (era o ID 26).
A14: 46336 | B14: Terça | C14: 2 | D14: Sono e prova: Chemitec | E14: ID 27 | F14: Higiene do sono em 3 passos | G14: Descoberta, educação e retenção | H14: Reel | I14: 9:16 · 1080x1920 · 30–45 s · texto na tela desde o 1º quadro | J14: Três ajustes para dormir melhor hoje. | M14: Mande para quem vive cansado | N14: #fairhealth #medicinadoestilodevida #saudedotrabalhador #prevencao #saudecorporativa | O14: Um profissional do time | P14: A fazer | Q14: Série 1 Minuto de Cuidado.
A15: 46337 | B15: Quarta | C15: 2 | D15: Sono e prova: Chemitec | E15: ID 28 | F15: Pilar 3: Sono reparador | G15: Autoridade, salvamento e compartilhamento | H15: Carrossel | I15: 4:5 · 1080x1350 · 8–10 slides · slide 2 entendível sozinho | J15: Sono não é tempo perdido. | M15: Salve este carrossel | N15: #fairhealth #medicinadoestilodevida #saudedotrabalhador #prevencao #saudecorporativa | O15: Arte estilo pilares | P15: A fazer | Q15: Série 7 pilares.
A16: 46338 | B16: Quinta | C16: 2 | D16: Sono e prova: Chemitec | E16: NOVO (no lugar do ID 29) | F16: Adesão baixa não é culpa do colaborador | G16: Pessoas, método, bastidores e prova | H16: Reel | I16: 9:16 · 1080x1920 · 30–45 s · texto na tela desde o 1º quadro | J16: Adesão baixa não é culpa do colaborador. | M16: Comente CUIDADO | N16: #fairhealth #saudecorporativa #gestaodepessoas #absenteismo #rh | O16: Narração + imagens do espaço; fecha com o depoimento A4 em card | P16: A fazer | Q16: Da estratégia (#15). Usa a Chemitec como prova e a posição 3 da voz: programa que ninguém usa é custo, não cuidado. O ID 29 (smartband e sono) vai para dezembro, junto do tema Tecnologia.
A17: 46339 | B17: Sexta | C17: 2 | D17: Sono e prova: Chemitec | E17: ID 30 | F17: Sono, produtividade e segurança: atenção aos turnos na indústria | G17: Saúde corporativa, NR-1 e B2B | H17: Carrossel | I17: 4:5 · 1080x1350 · 8–10 slides · slide 2 entendível sozinho | J17: Quem trabalha de noite dorme diferente. | M17: Mande para o seu SESMT | N17: #fairhealth #saudecorporativa #nr1 #riscospsicossociais #gestaodepessoas | O17: Arte institucional | P17: A fazer | Q17: Revisão técnica.
A18: 46340 | B18: Sábado | C18: — | D18: Dia Mundial do Diabetes | E18: — | F18: Stories: Dia Mundial do Diabetes e Medicina do Estilo de Vida | G18: Relacionamento | H18: Stories | I18: 9:16 · 1080x1920 · sequência de 3 a 5 telas com figurinha | J18: Hoje é o Dia Mundial do Diabetes. | M18: Figurinha de quiz sobre hábitos | N18: — | O18: Arte (logo coração) | P18: A fazer | Q18: Agendar na sexta. Educativo, sem promessa de resultado. Revisão técnica.
A19: 46341 | B19: Domingo | C19: — | D19: — | E19: — | F19: — | G19: — | H19: — | I19: — | J19: — | M19: — | N19: — | O19: — | P19: — | Q19: Domingo (Proclamação da República).
A20: 46342 | B20: Segunda | C20: 3 | D20: Saúde mental e NR-01 | E20: ID 33 (era 18/11) | F20: Pilar 4: Saúde mental e estresse (com CVV 188) | G20: Autoridade, salvamento e compartilhamento | H20: Carrossel | I20: 4:5 · 1080x1350 · 8–10 slides · slide 2 entendível sozinho | J20: Estresse não avisa quando passa do limite. | M20: Salve e mande para alguém | N20: #fairhealth #medicinadoestilodevida #saudedotrabalhador #prevencao #saudecorporativa | O20: Arte estilo pilares | P20: A fazer | Q20: Último slide com CVV 188. Stories: caixa "O que mais pesa na sua semana?" (era o ID 31).
A21: 46343 | B21: Terça | C21: 3 | D21: Saúde mental e NR-01 | E21: ID 32 | F21: Respiração para momentos de tensão | G21: Descoberta, educação e retenção | H21: Reel | I21: 9:16 · 1080x1920 · 30–45 s · texto na tela desde o 1º quadro | J21: Um minuto para baixar a tensão. | M21: Salve para usar antes da próxima reunião | N21: #fairhealth #medicinadoestilodevida #saudedotrabalhador #prevencao #saudecorporativa | O21: Profissional de psicologia para a câmera | P21: A fazer | Q21: Série 1 Minuto de Cuidado.
A22: 46344 | B22: Quarta | C22: 3 | D22: Saúde mental e NR-01 | E22: ID 35 (era 20/11, feriado) | F22: NR-01 e riscos psicossociais: o que muda para o RH + lançamento do guia | G22: Saúde corporativa, NR-1 e B2B | H22: Carrossel | I22: 4:5 · 1080x1350 · 8–10 slides · slide 2 entendível sozinho | J22: NR-01 não é só uma planilha. | M22: Comente CUIDADO e receba o guia de NR-01 para o RH | N22: #fairhealth #saudecorporativa #nr1 #riscospsicossociais #gestaodepessoas | O22: Arte institucional; logo círculo | P22: A fazer | Q22: POST MAIS IMPORTANTE DO MÊS. Depende de: guia de NR-01 pronto e validado pelo Dr. Ronald, e resposta automática da palavra CUIDADO funcionando até 13/11. Fixar no perfil. Versão em PDF no LinkedIn no mesmo dia.
A23: 46345 | B23: Quinta | C23: 3 | D23: Saúde mental e NR-01 | E23: ID 34 | F23: Como funciona o atendimento psicológico: o que fica só entre você e o profissional | G23: Pessoas, método, bastidores e prova | H23: Reel | I23: 9:16 · 1080x1920 · 30–45 s · texto na tela desde o 1º quadro | J23: O que você conta fica aqui. | M23: Siga para conhecer o Escritório do Cuidado | N23: #fairhealth #medicinadoestilodevida #saudedotrabalhador #prevencao #saudecorporativa | O23: Profissional de psicologia para a câmera | P23: A fazer | Q23: Explicar que o RH só recebe indicadores do grupo, anonimizados.
A24: 46346 | B24: Sexta | C24: — | D24: Feriado: Dia da Consciência Negra | E24: — | F24: Sem post no feed | G24: — | H24: — | I24: — | J24: — | M24: — | N24: — | O24: — | P24: — | Q24: Feriado nacional, emenda com o fim de semana.
A25: 46347 | B25: Sábado | C25: — | D25: — | E25: — | F25: — | G25: — | H25: — | I25: — | J25: — | M25: — | N25: — | O25: — | P25: — | Q25: Fim de semana.
A26: 46348 | B26: Domingo | C26: — | D26: — | E26: — | F26: — | G26: — | H26: — | I26: — | J26: — | M26: — | N26: — | O26: — | P26: — | Q26: Fim de semana.
A27: 46349 | B27: Segunda | C27: 4 | D27: Relações, propósito e conversão | E27: ID 53 (antecipado de 16/12) | F27: Case Hospital Dia Santo Amaro: de 34 para cerca de 20 reclamações por mês | G27: Autoridade, salvamento e compartilhamento | H27: Carrossel | I27: 4:5 · 1080x1350 · 8–10 slides · slide 2 entendível sozinho | J27: De 34 para cerca de 20. | M27: Comente CUIDADO | N27: #fairhealth #saudecorporativa #gestaodepessoas #absenteismo #rh | O27: Arte institucional; logo círculo | P27: A fazer | Q27: Dados liberados: redução de cerca de 40%, conformidade média de 98,2%, apresentado em congresso internacional. Stories: "Quem faz diferença no seu dia de trabalho?" (era o ID 36).
A28: 46350 | B28: Terça | C28: 4 | D28: Relações, propósito e conversão | E28: ID 37 | F28: Conexões no trabalho também são saúde | G28: Descoberta, educação e retenção | H28: Reel | I28: 9:16 · 1080x1920 · 30–45 s · texto na tela desde o 1º quadro | J28: Quem você procura num dia difícil? | M28: Mande para essa pessoa | N28: #fairhealth #medicinadoestilodevida #saudedotrabalhador #prevencao #saudecorporativa | O28: Dois integrantes do time em conversa | P28: A fazer | Q28: —
A29: 46351 | B29: Quarta | C29: 4 | D29: Relações, propósito e conversão | E29: ID 38 | F29: Pilares 6 e 7: Relações sociais e Propósito | G29: Autoridade, salvamento e compartilhamento | H29: Carrossel | I29: 4:5 · 1080x1350 · 8–10 slides · slide 2 entendível sozinho | J29: Relações e propósito também são saúde. | M29: Salve este carrossel | N29: #fairhealth #medicinadoestilodevida #saudedotrabalhador #prevencao #saudecorporativa | O29: Arte estilo pilares | P29: A fazer | Q29: Série 7 pilares.
A30: 46352 | B30: Quinta | C30: 4 | D30: Relações, propósito e conversão | E30: ID 59 (antecipado de 17/12) | F30: "Ela não gosta de gravar vídeo. Gravou um mesmo assim." (trechos em cards) | G30: Pessoas, método, bastidores e prova | H30: Reel | I30: 9:16 · 1080x1920 · 30–45 s · texto na tela desde o 1º quadro | J30: Ela não gosta de gravar vídeo. | M30: Comente CUIDADO | N30: #fairhealth #saudecorporativa #gestaodepessoas #absenteismo #rh | O30: Cards de texto com os trechos A6, A4 e A5 (logo coração) | P30: A fazer | Q30: O vídeo original NÃO é postado. Só trechos em texto, sem nome, rosto ou empresa (ver depoimentos.md).
A31: 46353 | B31: Sexta | C31: 4 | D31: Relações, propósito e conversão | E31: ID 63 + ID 65 (antecipados de dezembro) | F31: Como começar: diagnóstico gratuito, proposta e implementação | G31: Saúde corporativa, NR-1 e B2B | H31: Carrossel | I31: 4:5 · 1080x1350 · 8–10 slides · slide 2 entendível sozinho | J31: Como levar o cuidado para sua empresa. | M31: Comente CUIDADO e agende o diagnóstico gratuito | N31: #fairhealth #saudecorporativa #nr1 #riscospsicossociais #gestaodepessoas | O31: Arte institucional; logo círculo | P31: A fazer | Q31: Janela de orçamento 2027 do RH. É Black Friday: nada de linguagem de promoção ("só hoje", "aproveite"). Se preferir, trocar com o post de 26/11.
A32: 46354 | B32: Sábado | C32: — | D32: — | E32: — | F32: — | G32: — | H32: — | I32: — | J32: — | M32: — | N32: — | O32: — | P32: — | Q32: Fim de semana.
A33: 46355 | B33: Domingo | C33: — | D33: — | E33: — | F33: — | G33: — | H33: — | I33: — | J33: — | M33: — | N33: — | O33: — | P33: — | Q33: Fim de semana.
A34: 46356 | B34: Segunda | C34: 5 | D34: Fechamento do mês | E34: ID 58 (antecipado de 16/12) | F34: Depoimentos em texto: o cuidado na voz de quem é atendido | G34: Marca, relacionamento e diferenciação | H34: Carrossel | I34: 4:5 · 1080x1350 · 8–10 slides · slide 2 entendível sozinho | J34: O processo não precisa ser perfeito. | M34: Comente CUIDADO | N34: #fairhealth #saudecorporativa #gestaodepessoas #absenteismo #rh | O34: Cards de texto (logo coração) | P34: A fazer | Q34: Trechos B1, B2, B3, A1, A2 e A3 ("É mudança de cultura"). Assinatura: "Colaboradora atendida pelo Escritório do Cuidado". Fecha o mês de prova.
A36: Pendências para novembro funcionar
A37: Até 30/10 | D37: Marketing | F37: Roteiros dos Reels de 03 e 05/11 aprovados e gravados na diária de outubro.
A38: Até 06/11 | D38: Dr. Ronald | F38: Revisão técnica dos posts de Novembro Azul, sono, saúde mental e Dia do Diabetes.
A39: Até 06/11 | D39: Diretoria | F39: Confirmar com Chemitec e Hospital Dia Santo Amaro o uso do nome e, se possível, post em coautoria (Collab).
A40: Até 13/11 | D40: Marketing + Dr. Ronald | F40: Guia de NR-01 para o RH pronto e validado.
A41: Até 13/11 | D41: Marketing + Comercial | F41: Resposta automática da palavra CUIDADO no direct e página do diagnóstico gratuito no ar, com UTM.
A42: Até 13/11 | D42: Comercial | F42: Meta de diagnósticos de novembro e quem responde os leads em até 24 h.
...

Sheet Novembro (calendário)
A1: Novembro 2026 · FAIR HEALTH · Instagram
A2: Tema do mês: da intenção à evidência. Posts no feed às 7:30.
A4: Domingo | B4: Segunda | C4: Terça | D4: Quarta | E4: Quinta | F4: Sexta | G4: Sábado
A5: 1 STORIES Novembro Azul começa hoje | B5: 2 Feriado: Finados | C5: 3 REEL 1 Minuto de Cuidado: por que o homem só vai ao médico quando dói | D5: 4 CARROSSEL Pilar 2: Atividade física | E5: 5 REEL Bioimpedância: o que ela mostra | F5: 6 CARROSSEL Novembro Azul na empresa: o que vai além do laço azul | G5: 7
A6: 8 | B6: 9 CARROSSEL Adesão e retorno: Chemitec, 1º semestre de 2026 | C6: 10 REEL Higiene do sono em 3 passos | D6: 11 CARROSSEL Pilar 3: Sono reparador | E6: 12 REEL Adesão baixa não é culpa do colaborador | F6: 13 CARROSSEL Sono, produtividade e segurança: atenção aos turnos na indústria | G6: 14 STORIES Dia Mundial do Diabetes e Medicina do Estilo de Vida
A7: 15 | B7: 16 CARROSSEL Pilar 4: Saúde mental e estresse (com CVV 188) | C7: 17 REEL Respiração para momentos de tensão | D7: 18 CARROSSEL NR-01 e riscos psicossociais: o que muda para o RH + lançamento do guia | E7: 19 REEL Como funciona o atendimento psicológico: o que fica só entre você e o profissional | F7: 20 Feriado: Dia da Consciência Negra | G7: 21
A8: 22 | B8: 23 CARROSSEL Case Hospital Dia Santo Amaro: de 34 para cerca de 20 reclamações por mês | C8: 24 REEL Conexões no trabalho também são saúde | D8: 25 CARROSSEL Pilares 6 e 7: Relações sociais e Propósito | E8: 26 REEL "Ela não gosta de gravar vídeo. Gravou um mesmo assim." (trechos em cards) | F8: 27 CARROSSEL Como começar: diagnóstico gratuito, proposta e implementação | G8: 28
A9: 29 | B9: 30 CARROSSEL Depoimentos em texto: o cuidado na voz de quem é atendido
A11: Legenda das cores: verde = Reel · cinza-claro = Carrossel · amarelo = Stories. Detalhes de cada post na aba Novembro.

Sheet Listas
A1: Segunda | B1: 1 | C1: A fazer | D1: Reel
A2: Terça | B2: 2 | C2: Em produção | D2: Carrossel
A3: Quarta | B3: 3 | C3: Em revisão | D3: Foto única
A4: Quinta | B4: 4 | C4: Aprovado | D4: Stories
A5: Sexta | B5: 5 | C5: Publicado
